File: Modulus_Al_4.csv
Time,Displacement,Force,Strain 1
(s),(mm),(kN),(%)
0.00000,0.00000,0.00020,-0.00010
0.04000,0.00020,0.00010,-0.00010
0.08000,0.00070,0.00070,-0.00010
0.12000,0.00180,0.00170,0.00010
0.16000,0.00270,0.00280,0.00020
0.20000,0.00340,0.00400,0.00040
0.24000,0.00390,0.00520,0.00050
0.28000,0.00450,0.00620,0.00070
0.32000,0.00520,0.00730,0.00080
0.36000,0.00610,0.00860,0.00110
0.40000,0.00690,0.01010,0.00130
0.44000,0.00760,0.01140,0.00150
0.48000,0.00810,0.01260,0.00170
0.52000,0.00870,0.01330,0.00180
0.56000,0.00920,0.01410,0.00190
0.60000,0.00980,0.01490,0.00200
0.64000,0.01060,0.01640,0.00220
0.68000,0.01150,0.01800,0.00240
0.72000,0.01220,0.01970,0.00260
0.76000,0.01290,0.02110,0.00280
0.80000,0.01350,0.02240,0.00290
0.84000,0.01400,0.02350,0.00300
0.88000,0.01450,0.02470,0.00310
0.92000,0.01520,0.02570,0.00320
0.96000,0.01600,0.02730,0.00340
1.00000,0.01680,0.02920,0.00350
1.04000,0.01760,0.03100,0.00360
1.08000,0.01820,0.03260,0.00380
1.12000,0.01870,0.03370,0.00390
1.16000,0.01920,0.03500,0.00390
1.20000,0.01980,0.03610,0.00400
1.24000,0.02060,0.03760,0.00400
1.28000,0.02150,0.03980,0.00420
1.32000,0.02220,0.04160,0.00430
1.36000,0.02290,0.04310,0.00430
1.40000,0.02350,0.04450,0.00440
1.44000,0.02410,0.04560,0.00450
1.48000,0.02460,0.04680,0.00450
1.52000,0.02510,0.04810,0.00460
1.56000,0.02590,0.04930,0.00470
1.60000,0.02680,0.05110,0.00490
1.64000,0.02750,0.05320,0.00500
1.68000,0.02820,0.05460,0.00510
1.72000,0.02880,0.05560,0.00520
1.76000,0.02930,0.05690,0.00530
1.80000,0.02980,0.05790,0.00540
1.84000,0.03050,0.05930,0.00550
1.88000,0.03140,0.06100,0.00570
1.92000,0.03220,0.06290,0.00580
1.96000,0.03290,0.06450,0.00600
2.00000,0.03350,0.06590,0.00610
2.04000,0.03410,0.06700,0.00620
2.08000,0.03460,0.06810,0.00620
2.12000,0.03510,0.06920,0.00630
2.16000,0.03580,0.07070,0.00640
2.20000,0.03670,0.07260,0.00650
2.24000,0.03760,0.07450,0.00660
2.28000,0.03820,0.07600,0.00670
2.32000,0.03880,0.07690,0.00680
2.36000,0.03940,0.07780,0.00680
2.40000,0.03990,0.07860,0.00690
2.44000,0.04060,0.07980,0.00700
2.48000,0.04140,0.08140,0.00720
2.52000,0.04220,0.08310,0.00730
2.56000,0.04290,0.08490,0.00750
2.60000,0.04360,0.08610,0.00760
2.64000,0.04410,0.08730,0.00770
2.68000,0.04460,0.08850,0.00770
2.72000,0.04520,0.08940,0.00780
2.76000,0.04580,0.09070,0.00790
2.80000,0.04670,0.09220,0.00800
2.84000,0.04750,0.09430,0.00820
2.88000,0.04830,0.09590,0.00840
2.92000,0.04890,0.09740,0.00850
2.96000,0.04940,0.09850,0.00860
3.00000,0.04990,0.09940,0.00870
3.04000,0.05050,0.10050,0.00880
3.08000,0.05130,0.10190,0.00890
3.12000,0.05220,0.10380,0.00900
3.16000,0.05290,0.10590,0.00920
3.20000,0.05350,0.10710,0.00930
3.24000,0.05410,0.10850,0.00940
3.28000,0.05470,0.10960,0.00950
3.32000,0.05520,0.11070,0.00960
3.36000,0.05580,0.11220,0.00980
3.40000,0.05660,0.11400,0.01000
3.44000,0.05750,0.11600,0.01020
3.48000,0.05830,0.11810,0.01050
3.52000,0.05890,0.11970,0.01070
3.56000,0.05950,0.12080,0.01080
3.60000,0.06000,0.12190,0.01100
3.64000,0.06050,0.12290,0.01110
3.68000,0.06120,0.12400,0.01120
3.72000,0.06210,0.12610,0.01150
3.76000,0.06280,0.12820,0.01170
3.80000,0.06350,0.12950,0.01180
3.84000,0.06420,0.13070,0.01200
3.88000,0.06470,0.13190,0.01210
3.92000,0.06520,0.13290,0.01220
3.96000,0.06580,0.13400,0.01240
4.00000,0.06650,0.13530,0.01250
4.04000,0.06740,0.13730,0.01270
4.08000,0.06820,0.13920,0.01290
4.12000,0.06890,0.14070,0.01310
4.16000,0.06950,0.14160,0.01320
4.20000,0.07000,0.14250,0.01330
4.24000,0.07050,0.14340,0.01340
4.28000,0.07110,0.14450,0.01350
4.32000,0.07200,0.14620,0.01370
4.36000,0.07290,0.14820,0.01390
4.40000,0.07360,0.14970,0.01400
4.44000,0.07420,0.15080,0.01410
4.48000,0.07470,0.15170,0.01430
4.52000,0.07530,0.15260,0.01430
4.56000,0.07590,0.15350,0.01440
4.60000,0.07650,0.15460,0.01450
4.64000,0.07740,0.15640,0.01470
4.68000,0.07820,0.15830,0.01490
4.72000,0.07890,0.15990,0.01500
4.76000,0.07950,0.16060,0.01520
4.80000,0.08000,0.16130,0.01520
4.84000,0.08050,0.16230,0.01530
4.88000,0.08120,0.16320,0.01540
4.92000,0.08190,0.16460,0.01550
4.96000,0.08280,0.16650,0.01570
5.00000,0.08360,0.16860,0.01590
5.04000,0.08420,0.16990,0.01610
5.08000,0.08480,0.17120,0.01620
5.12000,0.08540,0.17190,0.01630
5.16000,0.08590,0.17300,0.01640
5.20000,0.08650,0.17400,0.01650
5.24000,0.08730,0.17590,0.01660
5.28000,0.08820,0.17820,0.01680
5.32000,0.08890,0.18030,0.01700
5.36000,0.08950,0.18180,0.01720
5.40000,0.09010,0.18280,0.01720
5.44000,0.09060,0.18400,0.01740
5.48000,0.09120,0.18530,0.01750
5.52000,0.09190,0.18690,0.01760
5.56000,0.09280,0.18900,0.01790
5.60000,0.09360,0.19170,0.01810
5.64000,0.09430,0.19360,0.01820
5.68000,0.09490,0.19510,0.01840
5.72000,0.09540,0.19640,0.01850
5.76000,0.09590,0.19740,0.01860
5.80000,0.09650,0.19860,0.01870
5.84000,0.09720,0.20040,0.01890
5.88000,0.09810,0.20270,0.01910
5.92000,0.09890,0.20520,0.01930
5.96000,0.09950,0.20710,0.01950
6.00000,0.10010,0.20860,0.01960
6.04000,0.10070,0.20970,0.01970
6.08000,0.10120,0.21100,0.01990
6.12000,0.10180,0.21240,0.02000
6.16000,0.10270,0.21480,0.02010
6.20000,0.10360,0.21760,0.02040
6.24000,0.10420,0.21960,0.02060
6.28000,0.10490,0.22130,0.02070
6.32000,0.10540,0.22260,0.02080
6.36000,0.10600,0.22360,0.02090
6.40000,0.10650,0.22490,0.02100
6.44000,0.10720,0.22640,0.02110
6.48000,0.10810,0.22890,0.02130
6.52000,0.10890,0.23160,0.02150
6.56000,0.10960,0.23390,0.02170
6.60000,0.11010,0.23550,0.02190
6.64000,0.11070,0.23660,0.02200
6.68000,0.11120,0.23780,0.02210
6.72000,0.11190,0.23900,0.02210
6.76000,0.11270,0.24100,0.02230
6.80000,0.11350,0.24410,0.02250
6.84000,0.11420,0.24640,0.02270
6.88000,0.11490,0.24790,0.02280
6.92000,0.11540,0.24930,0.02290
6.96000,0.11600,0.25060,0.02300
7.00000,0.11650,0.25180,0.02310
7.04000,0.11720,0.25310,0.02320
7.08000,0.11800,0.25530,0.02340
7.12000,0.11880,0.25810,0.02360
7.16000,0.11960,0.26060,0.02380
7.20000,0.12020,0.26230,0.02400
7.24000,0.12070,0.26360,0.02400
7.28000,0.12130,0.26490,0.02420
7.32000,0.12190,0.26600,0.02420
7.36000,0.12260,0.26790,0.02440
7.40000,0.12350,0.27060,0.02460
7.44000,0.12420,0.27300,0.02480
7.48000,0.12490,0.27480,0.02490
7.52000,0.12550,0.27650,0.02500
7.56000,0.12600,0.27790,0.02510
7.60000,0.12650,0.27910,0.02520
7.64000,0.12710,0.28030,0.02530
7.68000,0.12790,0.28230,0.02550
7.72000,0.12880,0.28520,0.02570
7.76000,0.12960,0.28790,0.02590
7.80000,0.13020,0.28990,0.02600
7.84000,0.13080,0.29140,0.02620
7.88000,0.13130,0.29250,0.02630
7.92000,0.13180,0.29380,0.02640
7.96000,0.13250,0.29570,0.02650
8.00000,0.13340,0.29810,0.02660
8.04000,0.13420,0.30120,0.02690
8.08000,0.13490,0.30350,0.02710
8.12000,0.13550,0.30530,0.02720
8.16000,0.13610,0.30670,0.02730
8.20000,0.13660,0.30830,0.02750
8.24000,0.13720,0.30990,0.02760
8.28000,0.13790,0.31160,0.02770
8.32000,0.13880,0.31450,0.02790
8.36000,0.13960,0.31760,0.02820
8.40000,0.14030,0.32010,0.02840
8.44000,0.14080,0.32170,0.02860
8.48000,0.14140,0.32300,0.02860
8.52000,0.14190,0.32430,0.02870
8.56000,0.14250,0.32560,0.02880
8.60000,0.14330,0.32820,0.02900
8.64000,0.14420,0.33140,0.02930
8.68000,0.14490,0.33400,0.02950
8.72000,0.14560,0.33610,0.02970
8.76000,0.14610,0.33770,0.02980
8.80000,0.14670,0.33900,0.02990
8.84000,0.14720,0.34070,0.03000
8.88000,0.14790,0.34220,0.03020
8.92000,0.14870,0.34490,0.03040
8.96000,0.14960,0.34800,0.03070
9.00000,0.15030,0.35080,0.03090
9.04000,0.15090,0.35260,0.03100
9.08000,0.15130,0.35370,0.03110
9.12000,0.15190,0.35530,0.03120
9.16000,0.15250,0.35670,0.03140
9.20000,0.15330,0.35890,0.03150
9.24000,0.15410,0.36210,0.03180
9.28000,0.15490,0.36530,0.03200
9.32000,0.15560,0.36740,0.03220
9.36000,0.15620,0.36910,0.03240
9.40000,0.15670,0.37070,0.03250
9.44000,0.15720,0.37210,0.03260
9.48000,0.15790,0.37380,0.03270
9.52000,0.15860,0.37610,0.03290
9.56000,0.15940,0.37940,0.03320
9.60000,0.16020,0.38220,0.03340
9.64000,0.16080,0.38440,0.03360
9.68000,0.16140,0.38580,0.03370
9.72000,0.16190,0.38740,0.03380
9.76000,0.16250,0.38890,0.03390
9.80000,0.16320,0.39080,0.03410
9.84000,0.16400,0.39360,0.03430
9.88000,0.16490,0.39710,0.03460
9.92000,0.16560,0.39970,0.03480
9.96000,0.16620,0.40160,0.03490
10.00000,0.16680,0.40320,0.03510
10.04000,0.16720,0.40480,0.03520
10.08000,0.16780,0.40610,0.03530
10.12000,0.16850,0.40830,0.03550
10.16000,0.16940,0.41120,0.03570
10.20000,0.17020,0.41460,0.03600
10.24000,0.17080,0.41730,0.03620
10.28000,0.17140,0.41910,0.03630
10.32000,0.17200,0.42090,0.03650
10.36000,0.17250,0.42270,0.03660
10.40000,0.17320,0.42460,0.03680
10.44000,0.17410,0.42740,0.03700
10.48000,0.17490,0.43100,0.03730
10.52000,0.17560,0.43410,0.03750
10.56000,0.17620,0.43640,0.03770
10.60000,0.17670,0.43800,0.03780
10.64000,0.17730,0.43980,0.03800
10.68000,0.17790,0.44140,0.03810
10.72000,0.17850,0.44370,0.03830
10.76000,0.17940,0.44680,0.03850
10.80000,0.18020,0.45040,0.03880
10.84000,0.18090,0.45350,0.03910
10.88000,0.18150,0.45590,0.03930
10.92000,0.18200,0.45760,0.03940
10.96000,0.18260,0.45920,0.03950
11.00000,0.18320,0.46100,0.03970
11.04000,0.18400,0.46370,0.03990
11.08000,0.18490,0.46730,0.04020
11.12000,0.18560,0.47080,0.04040
11.16000,0.18620,0.47310,0.04060
11.20000,0.18680,0.47510,0.04080
11.24000,0.18730,0.47700,0.04090
11.28000,0.18790,0.47870,0.04110
11.32000,0.18850,0.48080,0.04130
11.36000,0.18930,0.48360,0.04150
11.40000,0.19020,0.48730,0.04180
11.44000,0.19090,0.49110,0.04200
11.48000,0.19160,0.49370,0.04220
11.52000,0.19210,0.49590,0.04230
11.56000,0.19260,0.49800,0.04240
11.60000,0.19320,0.50000,0.04260
11.64000,0.19390,0.50260,0.04280
11.68000,0.19480,0.50620,0.04300
11.72000,0.19550,0.51030,0.04330
11.76000,0.19620,0.51350,0.04350
11.80000,0.19680,0.51610,0.04360
11.84000,0.19740,0.51850,0.04380
11.88000,0.19790,0.52060,0.04390
11.92000,0.19850,0.52290,0.04410
11.96000,0.19920,0.52580,0.04420
12.00000,0.20010,0.52960,0.04450
12.04000,0.20090,0.53370,0.04480
12.08000,0.20160,0.53720,0.04500
12.12000,0.20220,0.53970,0.04520
12.16000,0.20270,0.54190,0.04530
12.20000,0.20320,0.54390,0.04540
12.24000,0.20380,0.54620,0.04550
12.28000,0.20460,0.54960,0.04580
12.32000,0.20550,0.55400,0.04610
12.36000,0.20620,0.55790,0.04630
12.40000,0.20680,0.56090,0.04650
12.44000,0.20740,0.56350,0.04660
12.48000,0.20800,0.56570,0.04680
12.52000,0.20850,0.56800,0.04690
12.56000,0.20920,0.57070,0.04710
12.60000,0.21010,0.57430,0.04730
12.64000,0.21090,0.57860,0.04760
12.68000,0.21160,0.58240,0.04790
12.72000,0.21220,0.58540,0.04810
12.76000,0.21270,0.58750,0.04820
12.80000,0.21320,0.58960,0.04830
12.84000,0.21380,0.59190,0.04850
12.88000,0.21460,0.59520,0.04870
12.92000,0.21550,0.59950,0.04900
12.96000,0.21620,0.60390,0.04920
13.00000,0.21690,0.60710,0.04950
13.04000,0.21750,0.61000,0.04970
13.08000,0.21800,0.61240,0.04980
13.12000,0.21860,0.61460,0.05000
13.16000,0.21920,0.61730,0.05020
13.20000,0.22000,0.62090,0.05040
13.24000,0.22090,0.62550,0.05070
13.28000,0.22160,0.62970,0.05100
13.32000,0.22220,0.63280,0.05120
13.36000,0.22270,0.63540,0.05140
13.40000,0.22330,0.63770,0.05150
13.44000,0.22380,0.64010,0.05170
13.48000,0.22460,0.64310,0.05190
13.52000,0.22540,0.64740,0.05220
13.56000,0.22620,0.65230,0.05250
13.60000,0.22690,0.65580,0.05280
13.64000,0.22760,0.65900,0.05300
13.68000,0.22810,0.66160,0.05320
13.72000,0.22860,0.66400,0.05330
13.76000,0.22920,0.66650,0.05350
13.80000,0.22990,0.66960,0.05370
13.84000,0.23080,0.67400,0.05400
13.88000,0.23150,0.67860,0.05430
13.92000,0.23220,0.68220,0.05460
13.96000,0.23280,0.68560,0.05480
14.00000,0.23330,0.68810,0.05490
14.04000,0.23380,0.69050,0.05510
14.08000,0.23450,0.69320,0.05530
14.12000,0.23540,0.69720,0.05550
14.16000,0.23620,0.70210,0.05590
14.20000,0.23690,0.70620,0.05620
14.24000,0.23760,0.70950,0.05650
14.28000,0.23810,0.71240,0.05660
14.32000,0.23860,0.71480,0.05680
14.36000,0.23910,0.71710,0.05690
14.40000,0.23980,0.71990,0.05710
14.44000,0.24070,0.72390,0.05740
14.48000,0.24150,0.72880,0.05780
14.52000,0.24220,0.73320,0.05810
14.56000,0.24280,0.73650,0.05830
14.60000,0.24340,0.73910,0.05840
14.64000,0.24390,0.74150,0.05860
14.68000,0.24450,0.74430,0.05880
14.72000,0.24530,0.74800,0.05910
14.76000,0.24620,0.75280,0.05940
14.80000,0.24690,0.75760,0.05970
14.84000,0.24760,0.76120,0.05990
14.88000,0.24810,0.76400,0.06020
14.92000,0.24860,0.76650,0.06040
14.96000,0.24920,0.76870,0.06050
15.00000,0.24980,0.77160,0.06060
15.04000,0.25060,0.77540,0.06090
15.08000,0.25150,0.78000,0.06130
15.12000,0.25220,0.78470,0.06160
15.16000,0.25290,0.78850,0.06190
15.20000,0.25340,0.79130,0.06210
15.24000,0.25390,0.79380,0.06220
15.28000,0.25450,0.79630,0.06240
15.32000,0.25530,0.79970,0.06260
15.36000,0.25620,0.80440,0.06300
15.40000,0.25690,0.80940,0.06330
15.44000,0.25750,0.81300,0.06350
15.48000,0.25820,0.81620,0.06380
15.52000,0.25870,0.81870,0.06400
15.56000,0.25920,0.82150,0.06410
15.60000,0.25980,0.82430,0.06430
15.64000,0.26060,0.82760,0.06460
15.68000,0.26140,0.83240,0.06490
15.72000,0.26230,0.83760,0.06530
15.76000,0.26290,0.84180,0.06560
15.80000,0.26350,0.84480,0.06570
15.84000,0.26400,0.84730,0.06590
15.88000,0.26450,0.84990,0.06610
15.92000,0.26520,0.85300,0.06630
15.96000,0.26610,0.85730,0.06660
16.00000,0.26690,0.86250,0.06700
16.04000,0.26750,0.86660,0.06720
16.08000,0.26820,0.87000,0.06750
16.12000,0.26870,0.87320,0.06770
16.16000,0.26920,0.87620,0.06790
16.20000,0.26980,0.87880,0.06810
16.24000,0.27050,0.88180,0.06830
16.28000,0.27140,0.88640,0.06860
16.32000,0.27220,0.89190,0.06900
16.36000,0.27290,0.89640,0.06930
16.40000,0.27350,0.89960,0.06950
16.44000,0.27410,0.90250,0.06970
16.48000,0.27460,0.90500,0.07000
16.52000,0.27520,0.90780,0.07010
16.56000,0.27590,0.91170,0.07030
16.60000,0.27690,0.91670,0.07070
16.64000,0.27760,0.92140,0.07110
16.68000,0.27820,0.92540,0.07130
16.72000,0.27880,0.92880,0.07160
16.76000,0.27930,0.93170,0.07180
16.80000,0.27990,0.93460,0.07190
16.84000,0.28050,0.93770,0.07220
16.88000,0.28140,0.94180,0.07240
16.92000,0.28230,0.94730,0.07290
16.96000,0.28300,0.95240,0.07320
17.00000,0.28350,0.95590,0.07350
17.04000,0.28400,0.95860,0.07360
17.08000,0.28460,0.96120,0.07380
17.12000,0.28520,0.96410,0.07400
17.16000,0.28590,0.96770,0.07430
17.20000,0.28680,0.97270,0.07460
17.24000,0.28760,0.97790,0.07500
17.28000,0.28820,0.98220,0.07530
17.32000,0.28880,0.98570,0.07560
17.36000,0.28940,0.98880,0.07580
17.40000,0.28990,0.99170,0.07600
17.44000,0.29050,0.99450,0.07620
17.48000,0.29130,0.99850,0.07640
17.52000,0.29220,1.00380,0.07680
17.56000,0.29290,1.00900,0.07720
17.60000,0.29350,1.01290,0.07740
17.64000,0.29410,1.01600,0.07770
17.68000,0.29460,1.01890,0.07780
17.72000,0.29510,1.02180,0.07810
17.76000,0.29590,1.02500,0.07830
17.80000,0.29670,1.02970,0.07870
17.84000,0.29750,1.03510,0.07900
17.88000,0.29820,1.03980,0.07940
17.92000,0.29890,1.04350,0.07960
17.96000,0.29940,1.04690,0.07990
18.00000,0.29990,1.04970,0.08000
18.04000,0.30050,1.05260,0.08030
18.08000,0.30120,1.05620,0.08050
18.12000,0.30210,1.06090,0.08090
18.16000,0.30290,1.06650,0.08130
18.20000,0.30350,1.07100,0.08160
18.24000,0.30410,1.07440,0.08180
18.28000,0.30470,1.07760,0.08200
18.32000,0.30520,1.08050,0.08220
18.36000,0.30580,1.08360,0.08240
18.40000,0.30670,1.08820,0.08270
18.44000,0.30760,1.09340,0.08310
18.48000,0.30820,1.09850,0.08350
18.52000,0.30890,1.10280,0.08380
18.56000,0.30950,1.10610,0.08400
18.60000,0.31000,1.10900,0.08420
18.64000,0.31050,1.11180,0.08440
18.68000,0.31120,1.11510,0.08470
18.72000,0.31200,1.11940,0.08500
18.76000,0.31290,1.12490,0.08540
18.80000,0.31360,1.13000,0.08570
18.84000,0.31420,1.13410,0.08610
18.88000,0.31470,1.13730,0.08630
18.92000,0.31530,1.14030,0.08650
18.96000,0.31590,1.14330,0.08670
19.00000,0.31670,1.14740,0.08700
19.04000,0.31750,1.15260,0.08740
19.08000,0.31830,1.15810,0.08780
19.12000,0.31890,1.16260,0.08810
19.16000,0.31950,1.16630,0.08830
19.20000,0.32000,1.16930,0.08860
19.24000,0.32060,1.17230,0.08880
19.28000,0.32120,1.17550,0.08900
19.32000,0.32200,1.17960,0.08930
19.36000,0.32280,1.18520,0.08970
19.40000,0.32360,1.19090,0.09010
19.44000,0.32420,1.19490,0.09040
19.48000,0.32470,1.19860,0.09070
19.52000,0.32530,1.20140,0.09090
19.56000,0.32590,1.20430,0.09110
19.60000,0.32660,1.20810,0.09140
19.64000,0.32750,1.21320,0.09170
19.68000,0.32820,1.21890,0.09220
19.72000,0.32890,1.22320,0.09240
19.76000,0.32950,1.22700,0.09270
19.80000,0.33000,1.23040,0.09300
19.84000,0.33050,1.23360,0.09310
19.88000,0.33110,1.23650,0.09340
19.92000,0.33190,1.24040,0.09370
19.96000,0.33270,1.24600,0.09410
20.00000,0.33350,1.25190,0.09450
20.04000,0.33420,1.25660,0.09480
20.08000,0.33480,1.26010,0.09510
20.12000,0.33540,1.26350,0.09530
20.16000,0.33590,1.26630,0.09560
20.20000,0.33650,1.26960,0.09580
20.24000,0.33740,1.27430,0.09610
20.28000,0.33820,1.28000,0.09650
20.32000,0.33890,1.28490,0.09690
20.36000,0.33950,1.28900,0.09720
20.40000,0.34010,1.29260,0.09740
20.44000,0.34060,1.29580,0.09770
20.48000,0.34110,1.29900,0.09790
20.52000,0.34180,1.30250,0.09810
20.56000,0.34270,1.30740,0.09850
20.60000,0.34360,1.31330,0.09890
20.64000,0.34420,1.31840,0.09930
20.68000,0.34490,1.32270,0.09960
20.72000,0.34540,1.32600,0.09980
20.76000,0.34590,1.32880,0.10000
20.80000,0.34650,1.33200,0.10030
20.84000,0.34720,1.33590,0.10060
20.88000,0.34820,1.34170,0.10100
20.92000,0.34890,1.34710,0.10140
20.96000,0.34960,1.35190,0.10170
21.00000,0.35010,1.35560,0.10200
21.04000,0.35070,1.35880,0.10220
21.08000,0.35120,1.36230,0.10250
21.12000,0.35190,1.36570,0.10270
21.16000,0.35270,1.37020,0.10300
21.20000,0.35350,1.37620,0.10340
21.24000,0.35430,1.38190,0.10390
21.28000,0.35490,1.38630,0.10420
21.32000,0.35540,1.38960,0.10440
21.36000,0.35590,1.39270,0.10460
21.40000,0.35650,1.39590,0.10480
21.44000,0.35720,1.39980,0.10510
21.48000,0.35810,1.40520,0.10550
21.52000,0.35890,1.41110,0.10600
21.56000,0.35960,1.41600,0.10630
21.60000,0.36020,1.42010,0.10650
21.64000,0.36070,1.42370,0.10690
21.68000,0.36130,1.42720,0.10710
21.72000,0.36190,1.43050,0.10730
21.76000,0.36260,1.43460,0.10770
21.80000,0.36350,1.44030,0.10810
21.84000,0.36430,1.44600,0.10850
21.88000,0.36490,1.45070,0.10880
21.92000,0.36550,1.45440,0.10910
21.96000,0.36590,1.45770,0.10930
22.00000,0.36650,1.46090,0.10950
22.04000,0.36720,1.46470,0.10980
22.08000,0.36800,1.46960,0.11020
22.12000,0.36890,1.47580,0.11060
22.16000,0.36960,1.48110,0.11100
22.20000,0.37020,1.48530,0.11130
22.24000,0.37080,1.48920,0.11160
22.28000,0.37130,1.49260,0.11180
22.32000,0.37180,1.49590,0.11200
22.36000,0.37260,1.50000,0.11230
22.40000,0.37340,1.50520,0.11270
22.44000,0.37420,1.51070,0.11310
22.48000,0.37490,1.51600,0.11350
22.52000,0.37550,1.52000,0.11380
22.56000,0.37600,1.52370,0.11410
22.60000,0.37660,1.52690,0.11430
22.64000,0.37710,1.53000,0.11450
22.68000,0.37800,1.53480,0.11490
22.72000,0.37890,1.54100,0.11530
22.76000,0.37960,1.54660,0.11570
22.80000,0.38020,1.55140,0.11610
22.84000,0.38080,1.55520,0.11630
22.88000,0.38130,1.55880,0.11660
22.92000,0.38190,1.56190,0.11680
22.96000,0.38250,1.56540,0.11710
23.00000,0.38330,1.57020,0.11740
23.04000,0.38420,1.57600,0.11780
23.08000,0.38490,1.58160,0.11820
23.12000,0.38540,1.58590,0.11860
23.16000,0.38600,1.58960,0.11880
23.20000,0.38660,1.59300,0.11910
23.24000,0.38720,1.59640,0.11930
23.28000,0.38790,1.60070,0.11960
23.32000,0.38880,1.60650,0.12010
23.36000,0.38960,1.61280,0.12050
23.40000,0.39030,1.61750,0.12080
23.44000,0.39080,1.62130,0.12110
23.48000,0.39130,1.62480,0.12130
23.52000,0.39190,1.62800,0.12160
23.56000,0.39250,1.63150,0.12180
23.60000,0.39330,1.63590,0.12220
23.64000,0.39410,1.64170,0.12260
23.68000,0.39490,1.64730,0.12300
23.72000,0.39550,1.65240,0.12330
23.76000,0.39610,1.65620,0.12360
23.80000,0.39660,1.65960,0.12390
23.84000,0.39720,1.66280,0.12410
23.88000,0.39790,1.66680,0.12440
23.92000,0.39880,1.67230,0.12480
23.96000,0.39960,1.67860,0.12530
24.00000,0.40020,1.68380,0.12560
24.04000,0.40080,1.68780,0.12590
24.08000,0.40140,1.69150,0.12610
24.12000,0.40190,1.69510,0.12640
24.16000,0.40250,1.69850,0.12670
24.20000,0.40320,1.70280,0.12690
24.24000,0.40410,1.70830,0.12730
24.28000,0.40490,1.71410,0.12780
24.32000,0.40560,1.71970,0.12820
24.36000,0.40620,1.72370,0.12850
24.40000,0.40670,1.72700,0.12870
24.44000,0.40720,1.73040,0.12900
24.48000,0.40790,1.73420,0.12920
24.52000,0.40870,1.73900,0.12960
24.56000,0.40950,1.74490,0.13000
24.60000,0.41020,1.75040,0.13040
24.64000,0.41080,1.75490,0.13070
24.68000,0.41140,1.75900,0.13100
24.72000,0.41200,1.76280,0.13120
24.76000,0.41260,1.76590,0.13150
24.80000,0.41320,1.76970,0.13170
24.84000,0.41410,1.77460,0.13210
24.88000,0.41490,1.78070,0.13260
24.92000,0.41560,1.78660,0.13300
24.96000,0.41620,1.79110,0.13330
25.00000,0.41670,1.79470,0.13350
25.04000,0.41720,1.79760,0.13380
25.08000,0.41780,1.80090,0.13400
25.12000,0.41860,1.80520,0.13430
25.16000,0.41950,1.81100,0.13470
25.20000,0.42020,1.81720,0.13510
25.24000,0.42090,1.82190,0.13550
25.28000,0.42150,1.82620,0.13580
25.32000,0.42200,1.82990,0.13610
25.36000,0.42260,1.83300,0.13630
25.40000,0.42320,1.83660,0.13660
25.44000,0.42400,1.84130,0.13690
25.48000,0.42480,1.84720,0.13730
25.52000,0.42560,1.85300,0.13780
25.56000,0.42620,1.85790,0.13810
25.60000,0.42670,1.86170,0.13840
25.64000,0.42730,1.86520,0.13860
25.68000,0.42780,1.86810,0.13880
25.72000,0.42850,1.87220,0.13910
25.76000,0.42940,1.87740,0.13950
25.80000,0.43020,1.88360,0.14000
25.84000,0.43090,1.88880,0.14030
25.88000,0.43150,1.89330,0.14070
25.92000,0.43210,1.89720,0.14090
25.96000,0.43260,1.90040,0.14120
26.00000,0.43320,1.90390,0.14140
26.04000,0.43390,1.90810,0.14170
26.08000,0.43480,1.91390,0.14220
26.12000,0.43550,1.91980,0.14260
26.16000,0.43620,1.92470,0.14290
26.20000,0.43680,1.92880,0.14320
26.24000,0.43730,1.93240,0.14350
26.28000,0.43780,1.93590,0.14370
26.32000,0.43850,1.93940,0.14400
26.36000,0.43930,1.94430,0.14430
26.40000,0.44020,1.95040,0.14480
26.44000,0.44090,1.95620,0.14520
26.48000,0.44160,1.96090,0.14550
26.52000,0.44210,1.96490,0.14590
26.56000,0.44270,1.96840,0.14610
26.60000,0.44320,1.97140,0.14630
26.64000,0.44390,1.97530,0.14660
26.68000,0.44470,1.98050,0.14700
26.72000,0.44550,1.98640,0.14740
26.76000,0.44620,1.99220,0.14780
26.80000,0.44680,1.99680,0.14810
26.84000,0.44740,2.00070,0.14850
26.88000,0.44790,2.00410,0.14860
26.92000,0.44850,2.00750,0.14890
26.96000,0.44930,2.01200,0.14920
27.00000,0.45020,2.01800,0.14970
27.04000,0.45100,2.02430,0.15010
27.08000,0.45160,2.02900,0.15050
27.12000,0.45220,2.03330,0.15070
27.16000,0.45270,2.03700,0.15100
27.20000,0.45320,2.04010,0.15130
27.24000,0.45390,2.04340,0.15150
27.28000,0.45460,2.04800,0.15190
27.32000,0.45550,2.05410,0.15230
27.36000,0.45620,2.06030,0.15270
27.40000,0.45690,2.06530,0.15310
27.44000,0.45740,2.06940,0.15340
27.48000,0.45790,2.07300,0.15360
27.52000,0.45850,2.07630,0.15390
27.56000,0.45930,2.08020,0.15420
27.60000,0.46010,2.08600,0.15450
27.64000,0.46090,2.09230,0.15500
27.68000,0.46160,2.09780,0.15540
27.72000,0.46220,2.10180,0.15570
27.76000,0.46270,2.10560,0.15600
27.80000,0.46320,2.10880,0.15620
27.84000,0.46380,2.11200,0.15650
27.88000,0.46450,2.11650,0.15680
27.92000,0.46540,2.12240,0.15720
27.96000,0.46620,2.12870,0.15760
28.00000,0.46690,2.13400,0.15800
28.04000,0.46750,2.13810,0.15830
28.08000,0.46800,2.14190,0.15860
28.12000,0.46850,2.14520,0.15890
28.16000,0.46920,2.14890,0.15910
28.20000,0.47010,2.15400,0.15950
28.24000,0.47090,2.16040,0.16000
28.28000,0.47150,2.16580,0.16030
28.32000,0.47220,2.17030,0.16060
28.36000,0.47270,2.17430,0.16090
28.40000,0.47320,2.17780,0.16120
28.44000,0.47380,2.18140,0.16140
28.48000,0.47450,2.18520,0.16170
28.52000,0.47530,2.19050,0.16210
28.56000,0.47620,2.19700,0.16260
28.60000,0.47690,2.20270,0.16300
28.64000,0.47750,2.20750,0.16330
28.68000,0.47810,2.21120,0.16360
28.72000,0.47860,2.21430,0.16390
28.76000,0.47920,2.21780,0.16410
28.80000,0.48000,2.22250,0.16440
28.84000,0.48080,2.22850,0.16490
28.88000,0.48160,2.23460,0.16530
28.92000,0.48220,2.23940,0.16560
28.96000,0.48270,2.24370,0.16590
29.00000,0.48330,2.24760,0.16620
29.04000,0.48390,2.25110,0.16650
29.08000,0.48450,2.25480,0.16670
29.12000,0.48530,2.25960,0.16710
29.16000,0.48620,2.26570,0.16750
29.20000,0.48700,2.27200,0.16800
29.24000,0.48760,2.27690,0.16830
29.28000,0.48810,2.28090,0.16860
29.32000,0.48860,2.28430,0.16890
29.36000,0.48920,2.28750,0.16910
29.40000,0.48990,2.29150,0.16940
29.44000,0.49080,2.29750,0.16980
29.48000,0.49150,2.30400,0.17030
29.52000,0.49220,2.30920,0.17070
29.56000,0.49280,2.31380,0.17100
29.60000,0.49330,2.31780,0.17130
29.64000,0.49390,2.32130,0.17150
29.68000,0.49450,2.32480,0.17170
29.72000,0.49530,2.32950,0.17210
29.76000,0.49620,2.33560,0.17260
29.80000,0.49700,2.34210,0.17300
29.84000,0.49760,2.34720,0.17340
29.88000,0.49810,2.35100,0.17370
29.92000,0.49860,2.35440,0.17390
29.96000,0.49920,2.35800,0.17420
30.00000,0.49990,2.36170,0.17450
30.04000,0.50070,2.36720,0.17490
30.08000,0.50150,2.37390,0.17530
30.12000,0.50220,2.37960,0.17570
30.16000,0.50290,2.38430,0.17610
30.20000,0.50350,2.38850,0.17640
30.24000,0.50390,2.39200,0.17670
30.28000,0.50450,2.39550,0.17690
30.32000,0.50520,2.39930,0.17720
30.36000,0.50610,2.40510,0.17760
30.40000,0.50690,2.41160,0.17800
30.44000,0.50750,2.41690,0.17850
30.48000,0.50810,2.42110,0.17880
30.52000,0.50870,2.42490,0.17900
30.56000,0.50920,2.42850,0.17930
30.60000,0.50980,2.43200,0.17960
30.64000,0.51060,2.43700,0.17990
30.68000,0.51150,2.44340,0.18040
30.72000,0.51220,2.44950,0.18080
30.76000,0.51290,2.45440,0.18110
30.80000,0.51340,2.45850,0.18140
30.84000,0.51400,2.46200,0.18170
30.88000,0.51460,2.46570,0.18200
30.92000,0.51520,2.46930,0.18230
30.96000,0.51600,2.47430,0.18260
31.00000,0.51690,2.48070,0.18300
31.04000,0.51760,2.48680,0.18350
31.08000,0.51810,2.49150,0.18380
31.12000,0.51870,2.49530,0.18410
31.16000,0.51920,2.49900,0.18430
31.20000,0.51980,2.50260,0.18460
31.24000,0.52060,2.50670,0.18490
31.28000,0.52140,2.51280,0.18530
31.32000,0.52220,2.51910,0.18580
31.36000,0.52290,2.52410,0.18620
31.40000,0.52350,2.52880,0.18650
31.44000,0.52400,2.53270,0.18680
31.48000,0.52460,2.53580,0.18700
31.52000,0.52520,2.53950,0.18730
31.56000,0.52590,2.54390,0.18760
31.60000,0.52680,2.55000,0.18810
31.64000,0.52750,2.55630,0.18850
31.68000,0.52820,2.56170,0.18890
31.72000,0.52870,2.56600,0.18920
31.76000,0.52930,2.56950,0.18950
31.80000,0.52990,2.57300,0.18970
31.84000,0.53050,2.57700,0.19000
31.88000,0.53140,2.58240,0.19040
31.92000,0.53220,2.58890,0.19090
31.96000,0.53290,2.59470,0.19130
32.00000,0.53350,2.59910,0.19160
32.04000,0.53410,2.60310,0.19190
32.08000,0.53460,2.60650,0.19220
32.12000,0.53520,2.61020,0.19240
32.16000,0.53590,2.61450,0.19270
32.20000,0.53670,2.62030,0.19310
32.24000,0.53750,2.62670,0.19360
32.28000,0.53820,2.63270,0.19400
32.32000,0.53880,2.63710,0.19430
32.36000,0.53940,2.64110,0.19460
32.40000,0.53990,2.64450,0.19490
32.44000,0.54050,2.64830,0.19520
32.48000,0.54140,2.65340,0.19550
32.52000,0.54220,2.66000,0.19600
32.56000,0.54290,2.66580,0.19640
32.60000,0.54350,2.67040,0.19680
32.64000,0.54410,2.67440,0.19710
32.68000,0.54470,2.67840,0.19730
32.72000,0.54520,2.68210,0.19760
32.76000,0.54580,2.68610,0.19790
32.80000,0.54670,2.69170,0.19830
32.84000,0.54750,2.69820,0.19870
32.88000,0.54820,2.70440,0.19920
32.92000,0.54890,2.70950,0.19960
32.96000,0.54940,2.71330,0.19980
33.00000,0.55000,2.71680,0.20010
33.04000,0.55060,2.72050,0.20040
33.08000,0.55130,2.72510,0.20070
33.12000,0.55220,2.73110,0.20120
33.16000,0.55290,2.73760,0.20160
33.20000,0.55360,2.74280,0.20200
33.24000,0.55410,2.74760,0.20230
33.28000,0.55470,2.75150,0.20250
33.32000,0.55520,2.75510,0.20290
33.36000,0.55580,2.75890,0.20310
33.40000,0.55660,2.76370,0.20350
33.44000,0.55750,2.77020,0.20390
33.48000,0.55830,2.77650,0.20440
33.52000,0.55890,2.78180,0.20480
33.56000,0.55940,2.78590,0.20510
33.60000,0.55990,2.78950,0.20530
33.64000,0.56050,2.79290,0.20560
33.68000,0.56120,2.79690,0.20590
33.72000,0.56210,2.80270,0.20630
33.76000,0.56290,2.80940,0.20680
33.80000,0.56350,2.81520,0.20720
33.84000,0.56420,2.81980,0.20750
33.88000,0.56470,2.82410,0.20780
33.92000,0.56520,2.82760,0.20810
33.96000,0.56580,2.83150,0.20840
34.00000,0.56660,2.83590,0.20870
34.04000,0.56740,2.84190,0.20910
34.08000,0.56830,2.84870,0.20960
34.12000,0.56890,2.85430,0.21000
34.16000,0.56950,2.85850,0.21030
34.20000,0.57000,2.86210,0.21060
34.24000,0.57050,2.86570,0.21080
34.28000,0.57120,2.86970,0.21110
34.32000,0.57200,2.87490,0.21150
34.36000,0.57280,2.88170,0.21200
34.40000,0.57350,2.88780,0.21240
34.44000,0.57420,2.89270,0.21280
34.48000,0.57480,2.89690,0.21310
34.52000,0.57530,2.90070,0.21340
34.56000,0.57590,2.90460,0.21360
34.60000,0.57660,2.90870,0.21400
34.64000,0.57740,2.91440,0.21440
34.68000,0.57820,2.92090,0.21480
34.72000,0.57890,2.92680,0.21520
34.76000,0.57950,2.93140,0.21560
34.80000,0.58000,2.93560,0.21590
34.84000,0.58060,2.93940,0.21620
34.88000,0.58110,2.94320,0.21640
34.92000,0.58190,2.94810,0.21680
34.96000,0.58290,2.95450,0.21720
35.00000,0.58360,2.96090,0.21770
35.04000,0.58420,2.96620,0.21810
35.08000,0.58480,2.97090,0.21840
35.12000,0.58540,2.97470,0.21870
35.16000,0.58590,2.97840,0.21900
35.20000,0.58660,2.98220,0.21920
35.24000,0.58740,2.98760,0.21960
35.28000,0.58820,2.99410,0.22010
35.32000,0.58890,3.00020,0.22050
35.36000,0.58950,3.00540,0.22090
35.40000,0.59010,3.00970,0.22120
35.44000,0.59060,3.01340,0.22150
35.48000,0.59120,3.01710,0.22180
35.52000,0.59190,3.02150,0.22210
35.56000,0.59280,3.02750,0.22250
35.60000,0.59360,3.03440,0.22300
35.64000,0.59430,3.04020,0.22340
35.68000,0.59490,3.04490,0.22380
35.72000,0.59540,3.04890,0.22400
35.76000,0.59590,3.05240,0.22430
35.80000,0.59650,3.05610,0.22460
35.84000,0.59730,3.06110,0.22490
35.88000,0.59810,3.06700,0.22540
35.92000,0.59890,3.07360,0.22580
35.96000,0.59950,3.07920,0.22630
36.00000,0.60010,3.08360,0.22660
36.04000,0.60060,3.08750,0.22690
36.08000,0.60120,3.09100,0.22710
36.12000,0.60190,3.09520,0.22740
36.16000,0.60270,3.10110,0.22780
36.20000,0.60360,3.10820,0.22830
36.24000,0.60430,3.11400,0.22870
36.28000,0.60490,3.11880,0.22910
36.32000,0.60540,3.12260,0.22940
36.36000,0.60590,3.12640,0.22960
36.40000,0.60650,3.13010,0.22990
36.44000,0.60720,3.13450,0.23020
36.48000,0.60800,3.14020,0.23060
36.52000,0.60880,3.14690,0.23110
36.56000,0.60950,3.15270,0.23160
36.60000,0.61010,3.15770,0.23190
36.64000,0.61070,3.16170,0.23220
36.68000,0.61120,3.16530,0.23240
36.72000,0.61180,3.16920,0.23270
36.76000,0.61270,3.17420,0.23310
36.80000,0.61360,3.18120,0.23360
36.84000,0.61420,3.18740,0.23400
36.88000,0.61480,3.19240,0.23440
36.92000,0.61540,3.19660,0.23470
36.96000,0.61600,3.20050,0.23500
37.00000,0.61650,3.20420,0.23530
37.04000,0.61720,3.20850,0.23560
37.08000,0.61800,3.21380,0.23600
37.12000,0.61880,3.22040,0.23640
37.16000,0.61960,3.22670,0.23690
37.20000,0.62020,3.23190,0.23730
37.24000,0.62080,3.23610,0.23760
37.28000,0.62130,3.23990,0.23780
37.32000,0.62190,3.24380,0.23810
37.36000,0.62260,3.24850,0.23840
37.40000,0.62350,3.25470,0.23890
37.44000,0.62420,3.26100,0.23940
37.48000,0.62490,3.26670,0.23970
37.52000,0.62550,3.27120,0.24010
37.56000,0.62600,3.27530,0.24040
37.60000,0.62660,3.27910,0.24070
37.64000,0.62720,3.28300,0.24100
37.68000,0.62800,3.28800,0.24130
37.72000,0.62880,3.29430,0.24180
37.76000,0.62960,3.30100,0.24230
37.80000,0.63030,3.30690,0.24270
37.84000,0.63080,3.31130,0.24300
37.88000,0.63130,3.31520,0.24320
37.92000,0.63190,3.31860,0.24350
37.96000,0.63250,3.32280,0.24380
38.00000,0.63340,3.32830,0.24420
38.04000,0.63420,3.33480,0.24470
38.08000,0.63490,3.34110,0.24510
38.12000,0.63550,3.34610,0.24550
38.16000,0.63610,3.35030,0.24580
38.20000,0.63660,3.35420,0.24610
38.24000,0.63720,3.35790,0.24640
38.28000,0.63790,3.36230,0.24670
38.32000,0.63880,3.36860,0.24710
38.36000,0.63960,3.37530,0.24760
38.40000,0.64030,3.38150,0.24810
38.44000,0.64080,3.38610,0.24840
38.48000,0.64140,3.38980,0.24870
38.52000,0.64190,3.39330,0.24890
38.56000,0.64250,3.39720,0.24920
38.60000,0.64330,3.40250,0.24960
38.64000,0.64410,3.40920,0.25010
38.68000,0.64490,3.41570,0.25050
38.72000,0.64550,3.42080,0.25090
38.76000,0.64610,3.42540,0.25120
38.80000,0.64670,3.42930,0.25150
38.84000,0.64720,3.43320,0.25180
38.88000,0.64780,3.43720,0.25210
38.92000,0.64870,3.44290,0.25250
38.96000,0.64950,3.44950,0.25300
39.00000,0.65020,3.45560,0.25340
39.04000,0.65080,3.46040,0.25380
39.08000,0.65140,3.46470,0.25400
39.12000,0.65190,3.46850,0.25430
39.16000,0.65240,3.47230,0.25460
39.20000,0.65320,3.47690,0.25490
39.24000,0.65410,3.48320,0.25540
39.28000,0.65490,3.49040,0.25590
39.32000,0.65560,3.49600,0.25630
39.35200,0.65610,3.50010,0.25660