File: Modulus_Steel_3.csv
Time,Displacement,Force,Strain 1
(s),(mm),(kN),(%)
0.0000,0.0000,0.0006,-0.0089
0.0200,0.0000,0.0006,-0.0089
0.0400,0.0001,0.0005,-0.0089
0.0600,0.0003,0.0006,-0.0089
0.0800,0.0005,0.0007,-0.0089
0.1000,0.0009,0.0006,-0.0089
0.1200,0.0013,0.0007,-0.0088
0.1400,0.0018,0.0008,-0.0089
0.1600,0.0022,0.0010,-0.0089
0.1800,0.0027,0.0012,-0.0089
0.2000,0.0033,0.0017,-0.0088
0.2200,0.0037,0.0022,-0.0088
0.2400,0.0041,0.0031,-0.0087
0.2600,0.0044,0.0042,-0.0087
0.2800,0.0048,0.0052,-0.0087
0.3000,0.0051,0.0059,-0.0087
0.3200,0.0054,0.0067,-0.0087
0.3400,0.0056,0.0073,-0.0086
0.3600,0.0059,0.0079,-0.0086
0.3800,0.0062,0.0086,-0.0086
0.4000,0.0064,0.0092,-0.0086
0.4200,0.0067,0.0099,-0.0085
0.4400,0.0071,0.0108,-0.0085
0.4600,0.0075,0.0117,-0.0084
0.4800,0.0079,0.0126,-0.0084
0.5000,0.0084,0.0137,-0.0083
0.5200,0.0088,0.0149,-0.0083
0.5400,0.0092,0.0162,-0.0082
0.5600,0.0095,0.0175,-0.0082
0.5800,0.0098,0.0185,-0.0081
0.6000,0.0101,0.0196,-0.0081
0.6200,0.0104,0.0206,-0.0080
0.6400,0.0107,0.0215,-0.0080
0.6600,0.0109,0.0223,-0.0079
0.6800,0.0112,0.0231,-0.0079
0.7000,0.0115,0.0238,-0.0078
0.7200,0.0118,0.0247,-0.0078
0.7400,0.0122,0.0259,-0.0078
0.7600,0.0126,0.0270,-0.0077
0.7800,0.0130,0.0283,-0.0077
0.8000,0.0134,0.0298,-0.0076
0.8200,0.0138,0.0312,-0.0076
0.8400,0.0142,0.0325,-0.0075
0.8600,0.0145,0.0336,-0.0075
0.8800,0.0148,0.0346,-0.0074
0.9000,0.0151,0.0356,-0.0074
0.9200,0.0154,0.0366,-0.0074
0.9400,0.0157,0.0374,-0.0073
0.9600,0.0160,0.0381,-0.0073
0.9800,0.0162,0.0389,-0.0073
1.0000,0.0165,0.0399,-0.0073
1.0200,0.0168,0.0408,-0.0072
1.0400,0.0171,0.0417,-0.0072
1.0600,0.0175,0.0427,-0.0071
1.0800,0.0179,0.0438,-0.0071
1.1000,0.0183,0.0452,-0.0071
1.1200,0.0187,0.0469,-0.0070
1.1400,0.0192,0.0483,-0.0069
1.1600,0.0196,0.0493,-0.0068
1.1800,0.0199,0.0505,-0.0069
1.2000,0.0201,0.0516,-0.0068
1.2200,0.0205,0.0527,-0.0067
1.2400,0.0207,0.0535,-0.0067
1.2600,0.0209,0.0543,-0.0068
1.2800,0.0212,0.0551,-0.0068
1.3000,0.0215,0.0559,-0.0066
1.3200,0.0218,0.0567,-0.0066
1.3400,0.0221,0.0577,-0.0066
1.3600,0.0225,0.0589,-0.0064
1.3800,0.0229,0.0601,-0.0063
1.4000,0.0234,0.0618,-0.0065
1.4200,0.0238,0.0635,-0.0065
1.4400,0.0242,0.0653,-0.0062
1.4600,0.0245,0.0670,-0.0059
1.4800,0.0249,0.0680,-0.0062
1.5000,0.0251,0.0690,-0.0064
1.5200,0.0254,0.0701,-0.0061
1.5400,0.0257,0.0714,-0.0060
1.5600,0.0260,0.0728,-0.0062
1.5800,0.0262,0.0738,-0.0060
1.6000,0.0265,0.0746,-0.0058
1.6200,0.0268,0.0755,-0.0061
1.6400,0.0271,0.0767,-0.0062
1.6600,0.0275,0.0782,-0.0057
1.6800,0.0279,0.0797,-0.0056
1.7000,0.0283,0.0814,-0.0059
1.7200,0.0287,0.0833,-0.0059
1.7400,0.0291,0.0853,-0.0056
1.7600,0.0296,0.0874,-0.0057
1.7800,0.0299,0.0894,-0.0057
1.8000,0.0302,0.0910,-0.0054
1.8200,0.0305,0.0921,-0.0054
1.8400,0.0307,0.0932,-0.0057
1.8600,0.0310,0.0946,-0.0056
1.8800,0.0312,0.0962,-0.0053
1.9000,0.0315,0.0976,-0.0053
1.9200,0.0318,0.0989,-0.0055
1.9400,0.0321,0.1002,-0.0054
1.9600,0.0325,0.1019,-0.0052
1.9800,0.0328,0.1039,-0.0053
2.0000,0.0333,0.1063,-0.0053
2.0200,0.0337,0.1086,-0.0050
2.0400,0.0341,0.1108,-0.0050
2.0600,0.0345,0.1129,-0.0052
2.0800,0.0348,0.1149,-0.0051
2.1000,0.0351,0.1167,-0.0048
2.1200,0.0355,0.1183,-0.0049
2.1400,0.0357,0.1197,-0.0050
2.1600,0.0361,0.1212,-0.0049
2.1800,0.0363,0.1228,-0.0048
2.2000,0.0366,0.1244,-0.0049
2.2200,0.0369,0.1258,-0.0048
2.2400,0.0371,0.1274,-0.0047
2.2600,0.0374,0.1290,-0.0047
2.2800,0.0378,0.1306,-0.0048
2.3000,0.0382,0.1326,-0.0046
2.3200,0.0387,0.1351,-0.0044
2.3400,0.0391,0.1376,-0.0045
2.3600,0.0395,0.1400,-0.0045
2.3800,0.0399,0.1422,-0.0044
2.4000,0.0402,0.1443,-0.0043
2.4200,0.0405,0.1462,-0.0043
2.4400,0.0408,0.1477,-0.0042
2.4600,0.0410,0.1492,-0.0042
2.4800,0.0413,0.1507,-0.0042
2.5000,0.0415,0.1521,-0.0042
2.5200,0.0418,0.1536,-0.0041
2.5400,0.0421,0.1552,-0.0040
2.5600,0.0424,0.1569,-0.0040
2.5800,0.0428,0.1587,-0.0040
2.6000,0.0432,0.1607,-0.0039
2.6200,0.0437,0.1632,-0.0038
2.6400,0.0441,0.1660,-0.0039
2.6600,0.0445,0.1687,-0.0038
2.6800,0.0448,0.1710,-0.0037
2.7000,0.0452,0.1732,-0.0037
2.7200,0.0455,0.1752,-0.0037
2.7400,0.0458,0.1770,-0.0035
2.7600,0.0461,0.1790,-0.0035
2.7800,0.0463,0.1806,-0.0036
2.8000,0.0466,0.1821,-0.0035
2.8200,0.0469,0.1839,-0.0034
2.8400,0.0471,0.1856,-0.0034
2.8600,0.0475,0.1871,-0.0034
2.8800,0.0478,0.1889,-0.0033
2.9000,0.0482,0.1911,-0.0033
2.9200,0.0486,0.1936,-0.0033
2.9400,0.0490,0.1965,-0.0032
2.9600,0.0494,0.1993,-0.0031
2.9800,0.0498,0.2020,-0.0030
3.0000,0.0501,0.2046,-0.0030
3.0200,0.0505,0.2068,-0.0030
3.0400,0.0508,0.2086,-0.0029
3.0600,0.0511,0.2105,-0.0029
3.0800,0.0513,0.2124,-0.0029
3.1000,0.0516,0.2142,-0.0028
3.1200,0.0519,0.2159,-0.0028
3.1400,0.0521,0.2176,-0.0028
3.1600,0.0524,0.2193,-0.0027
3.1800,0.0528,0.2213,-0.0026
3.2000,0.0531,0.2238,-0.0026
3.2200,0.0536,0.2264,-0.0026
3.2400,0.0541,0.2293,-0.0025
3.2600,0.0545,0.2325,-0.0024
3.2800,0.0549,0.2354,-0.0024
3.3000,0.0552,0.2380,-0.0023
3.3200,0.0555,0.2403,-0.0022
3.3400,0.0558,0.2423,-0.0022
3.3600,0.0561,0.2442,-0.0022
3.3800,0.0564,0.2461,-0.0021
3.4000,0.0567,0.2482,-0.0021
3.4200,0.0569,0.2499,-0.0021
3.4400,0.0572,0.2517,-0.0021
3.4600,0.0575,0.2533,-0.0020
3.4800,0.0577,0.2552,-0.0020
3.5000,0.0581,0.2573,-0.0020
3.5200,0.0585,0.2596,-0.0019
3.5400,0.0589,0.2625,-0.0018
3.5600,0.0594,0.2655,-0.0017
3.5800,0.0598,0.2684,-0.0017
3.6000,0.0602,0.2713,-0.0016
3.6200,0.0605,0.2739,-0.0015
3.6400,0.0607,0.2762,-0.0016
3.6600,0.0611,0.2782,-0.0015
3.6800,0.0613,0.2802,-0.0014
3.7000,0.0616,0.2820,-0.0014
3.7200,0.0619,0.2838,-0.0013
3.7400,0.0621,0.2856,-0.0013
3.7600,0.0625,0.2875,-0.0012
3.7800,0.0628,0.2894,-0.0013
3.8000,0.0631,0.2914,-0.0012
3.8200,0.0635,0.2941,-0.0011
3.8400,0.0640,0.2971,-0.0010
3.8600,0.0645,0.3005,-0.0010
3.8800,0.0649,0.3040,-0.0009
3.9000,0.0652,0.3068,-0.0008
3.9200,0.0655,0.3093,-0.0008
3.9400,0.0658,0.3116,-0.0007
3.9600,0.0662,0.3138,-0.0007
3.9800,0.0664,0.3158,-0.0006
4.0000,0.0667,0.3177,-0.0006
4.0200,0.0670,0.3195,-0.0006
4.0400,0.0672,0.3215,-0.0005
4.0600,0.0674,0.3233,-0.0005
4.0800,0.0678,0.3253,-0.0005
4.1000,0.0681,0.3274,-0.0004
4.1200,0.0685,0.3297,-0.0004
4.1400,0.0689,0.3324,-0.0003
4.1600,0.0693,0.3354,-0.0002
4.1800,0.0697,0.3387,-0.0001
4.2000,0.0702,0.3420,-0.0001
4.2200,0.0705,0.3450,0.0000
4.2400,0.0708,0.3476,0.0000
4.2600,0.0711,0.3499,0.0001
4.2800,0.0714,0.3520,0.0002
4.3000,0.0717,0.3540,0.0002
4.3200,0.0719,0.3560,0.0002
4.3400,0.0722,0.3579,0.0003
4.3600,0.0725,0.3596,0.0003
4.3800,0.0728,0.3615,0.0004
4.4000,0.0731,0.3637,0.0004
4.4200,0.0735,0.3661,0.0004
4.4400,0.0740,0.3689,0.0005
4.4600,0.0744,0.3723,0.0006
4.4800,0.0748,0.3759,0.0007
4.5000,0.0752,0.3793,0.0008
4.5200,0.0755,0.3821,0.0008
4.5400,0.0759,0.3845,0.0009
4.5600,0.0761,0.3867,0.0009
4.5800,0.0764,0.3888,0.0010
4.6000,0.0767,0.3909,0.0010
4.6200,0.0770,0.3929,0.0011
4.6400,0.0772,0.3948,0.0011
4.6600,0.0775,0.3969,0.0011
4.6800,0.0778,0.3989,0.0012
4.7000,0.0781,0.4009,0.0012
4.7200,0.0784,0.4031,0.0013
4.7400,0.0788,0.4057,0.0013
4.7600,0.0793,0.4087,0.0014
4.7800,0.0797,0.4121,0.0014
4.8000,0.0801,0.4155,0.0015
4.8200,0.0805,0.4188,0.0016
4.8400,0.0809,0.4216,0.0017
4.8600,0.0812,0.4242,0.0017
4.8800,0.0815,0.4265,0.0018
4.9000,0.0817,0.4286,0.0018
4.9200,0.0820,0.4306,0.0018
4.9400,0.0823,0.4327,0.0019
4.9600,0.0826,0.4347,0.0020
4.9800,0.0828,0.4365,0.0020
5.0000,0.0831,0.4384,0.0020
5.0200,0.0835,0.4407,0.0021
5.0400,0.0839,0.4435,0.0022
5.0600,0.0843,0.4466,0.0022
5.0800,0.0847,0.4501,0.0023
5.1000,0.0852,0.4538,0.0024
5.1200,0.0855,0.4572,0.0024
5.1400,0.0858,0.4598,0.0025
5.1600,0.0861,0.4623,0.0026
5.1800,0.0865,0.4646,0.0026
5.2000,0.0867,0.4668,0.0027
5.2200,0.0870,0.4689,0.0027
5.2400,0.0873,0.4709,0.0028
5.2600,0.0875,0.4730,0.0028
5.2800,0.0879,0.4750,0.0029
5.3000,0.0881,0.4772,0.0029
5.3200,0.0884,0.4791,0.0030
5.3400,0.0888,0.4817,0.0030
5.3600,0.0892,0.4845,0.0031
5.3800,0.0896,0.4878,0.0031
5.4000,0.0901,0.4913,0.0033
5.4200,0.0905,0.4948,0.0033
5.4400,0.0909,0.4979,0.0034
5.4600,0.0912,0.5009,0.0034
5.4800,0.0915,0.5035,0.0035
5.5000,0.0918,0.5057,0.0036
5.5200,0.0920,0.5079,0.0036
5.5400,0.0923,0.5099,0.0037
5.5600,0.0926,0.5118,0.0037
5.5800,0.0928,0.5137,0.0037
5.6000,0.0931,0.5155,0.0038
5.6200,0.0934,0.5176,0.0039
5.6400,0.0938,0.5199,0.0039
5.6600,0.0942,0.5227,0.0039
5.6800,0.0946,0.5261,0.0040
5.7000,0.0950,0.5297,0.0041
5.7200,0.0955,0.5332,0.0042
5.7400,0.0958,0.5365,0.0043
5.7600,0.0961,0.5395,0.0043
5.7800,0.0964,0.5421,0.0044
5.8000,0.0967,0.5446,0.0044
5.8200,0.0971,0.5470,0.0045
5.8400,0.0973,0.5491,0.0045
5.8600,0.0976,0.5512,0.0046
5.8800,0.0979,0.5533,0.0047
5.9000,0.0981,0.5554,0.0047
5.9200,0.0984,0.5576,0.0048
5.9400,0.0988,0.5597,0.0048
5.9600,0.0992,0.5622,0.0049
5.9800,0.0996,0.5653,0.0049
6.0000,0.1000,0.5689,0.0050
6.0200,0.1004,0.5724,0.0051
6.0400,0.1008,0.5759,0.0052
6.0600,0.1012,0.5792,0.0052
6.0800,0.1015,0.5821,0.0053
6.1000,0.1018,0.5846,0.0054
6.1200,0.1021,0.5869,0.0054
6.1400,0.1024,0.5890,0.0055
6.1600,0.1026,0.5911,0.0055
6.1800,0.1029,0.5930,0.0056
6.2000,0.1031,0.5949,0.0056
6.2200,0.1034,0.5967,0.0057
6.2400,0.1038,0.5989,0.0057
6.2600,0.1041,0.6017,0.0058
6.2800,0.1046,0.6049,0.0059
6.3000,0.1050,0.6085,0.0059
6.3200,0.1054,0.6122,0.0060
6.3400,0.1058,0.6159,0.0061
6.3600,0.1061,0.6192,0.0062
6.3800,0.1065,0.6220,0.0062
6.4000,0.1068,0.6245,0.0063
6.4200,0.1071,0.6271,0.0063
6.4400,0.1074,0.6292,0.0064
6.4600,0.1077,0.6315,0.0065
6.4800,0.1079,0.6336,0.0066
6.5000,0.1082,0.6357,0.0066
6.5200,0.1085,0.6377,0.0067
6.5400,0.1088,0.6400,0.0067
6.5600,0.1091,0.6425,0.0067
6.5800,0.1096,0.6454,0.0068
6.6000,0.1100,0.6489,0.0069
6.6200,0.1104,0.6525,0.0070
6.6400,0.1108,0.6564,0.0071
6.6600,0.1112,0.6599,0.0071
6.6800,0.1115,0.6630,0.0072
6.7000,0.1118,0.6656,0.0073
6.7200,0.1121,0.6678,0.0073
6.7400,0.1124,0.6702,0.0074
6.7600,0.1126,0.6723,0.0074
6.7800,0.1129,0.6744,0.0075
6.8000,0.1132,0.6765,0.0075
6.8200,0.1135,0.6785,0.0076
6.8400,0.1137,0.6808,0.0077
6.8600,0.1141,0.6834,0.0077
6.8800,0.1145,0.6863,0.0078
6.9000,0.1150,0.6897,0.0079
6.9200,0.1154,0.6935,0.0080
6.9400,0.1158,0.6973,0.0081
6.9600,0.1162,0.7009,0.0081
6.9800,0.1165,0.7041,0.0082
7.0000,0.1168,0.7069,0.0083
7.0200,0.1172,0.7095,0.0083
7.0400,0.1175,0.7121,0.0084
7.0600,0.1177,0.7143,0.0084
7.0800,0.1180,0.7164,0.0085
7.1000,0.1182,0.7183,0.0085
7.1200,0.1185,0.7203,0.0086
7.1400,0.1188,0.7224,0.0086
7.1600,0.1191,0.7247,0.0087
7.1800,0.1195,0.7276,0.0088
7.2000,0.1199,0.7308,0.0089
7.2200,0.1203,0.7342,0.0089
7.2400,0.1207,0.7380,0.0090
7.2600,0.1211,0.7417,0.0091
7.2800,0.1215,0.7453,0.0092
7.3000,0.1218,0.7483,0.0093
7.3200,0.1221,0.7510,0.0093
7.3400,0.1224,0.7534,0.0094
7.3600,0.1227,0.7558,0.0095
7.3800,0.1229,0.7580,0.0095
7.4000,0.1232,0.7602,0.0096
7.4200,0.1235,0.7624,0.0096
7.4400,0.1238,0.7645,0.0097
7.4600,0.1241,0.7669,0.0097
7.4800,0.1244,0.7696,0.0098
7.5000,0.1249,0.7728,0.0098
7.5200,0.1254,0.7765,0.0099
7.5400,0.1258,0.7805,0.0100
7.5600,0.1262,0.7844,0.0101
7.5800,0.1265,0.7880,0.0102
7.6000,0.1269,0.7910,0.0103
7.6200,0.1272,0.7937,0.0103
7.6400,0.1275,0.7963,0.0104
7.6600,0.1278,0.7989,0.0105
7.6800,0.1280,0.8012,0.0105
7.7000,0.1283,0.8032,0.0106
7.7200,0.1286,0.8051,0.0107
7.7400,0.1288,0.8072,0.0107
7.7600,0.1291,0.8095,0.0108
7.7800,0.1294,0.8118,0.0108
7.8000,0.1298,0.8147,0.0109
7.8200,0.1302,0.8179,0.0109
7.8400,0.1307,0.8216,0.0110
7.8600,0.1311,0.8255,0.0111
7.8800,0.1315,0.8292,0.0112
7.9000,0.1318,0.8327,0.0113
7.9200,0.1322,0.8359,0.0114
7.9400,0.1325,0.8388,0.0115
7.9600,0.1327,0.8412,0.0116
7.9800,0.1330,0.8434,0.0116
8.0000,0.1333,0.8457,0.0117
8.0200,0.1336,0.8479,0.0117
8.0400,0.1338,0.8501,0.0118
8.0600,0.1341,0.8523,0.0118
8.0800,0.1345,0.8549,0.0119
8.1000,0.1348,0.8579,0.0120
8.1200,0.1353,0.8613,0.0120
8.1400,0.1357,0.8652,0.0121
8.1600,0.1362,0.8695,0.0123
8.1800,0.1366,0.8734,0.0124
8.2000,0.1369,0.8768,0.0124
8.2200,0.1372,0.8795,0.0125
8.2400,0.1375,0.8822,0.0125
8.2600,0.1378,0.8847,0.0126
8.2800,0.1381,0.8871,0.0127
8.3000,0.1383,0.8895,0.0127
8.3200,0.1385,0.8916,0.0128
8.3400,0.1388,0.8936,0.0128
8.3600,0.1391,0.8956,0.0129
8.3800,0.1394,0.8979,0.0130
8.4000,0.1398,0.9006,0.0131
8.4200,0.1401,0.9037,0.0131
8.4400,0.1406,0.9072,0.0132
8.4600,0.1410,0.9111,0.0133
8.4800,0.1414,0.9150,0.0134
8.5000,0.1418,0.9188,0.0135
8.5200,0.1422,0.9223,0.0136
8.5400,0.1425,0.9255,0.0136
8.5600,0.1428,0.9281,0.0137
8.5800,0.1430,0.9307,0.0138
8.6000,0.1433,0.9332,0.0138
8.6200,0.1436,0.9354,0.0139
8.6400,0.1438,0.9375,0.0139
8.6600,0.1441,0.9395,0.0140
8.6800,0.1444,0.9418,0.0141
8.7000,0.1448,0.9445,0.0141
8.7200,0.1452,0.9478,0.0142
8.7400,0.1457,0.9516,0.0143
8.7600,0.1461,0.9558,0.0144
8.7800,0.1465,0.9599,0.0145
8.8000,0.1468,0.9636,0.0146
8.8200,0.1472,0.9666,0.0147
8.8400,0.1475,0.9694,0.0147
8.8600,0.1478,0.9721,0.0148
8.8800,0.1481,0.9746,0.0149
8.9000,0.1483,0.9769,0.0150
8.9200,0.1486,0.9790,0.0150
8.9400,0.1488,0.9813,0.0151
8.9600,0.1491,0.9835,0.0151
8.9800,0.1494,0.9859,0.0152
9.0000,0.1497,0.9883,0.0152
9.0200,0.1501,0.9913,0.0153
9.0400,0.1505,0.9949,0.0154
9.0600,0.1510,0.9988,0.0155
9.0800,0.1514,1.0029,0.0156
9.1000,0.1518,1.0070,0.0157
9.1200,0.1522,1.0109,0.0158
9.1400,0.1525,1.0143,0.0159
9.1600,0.1528,1.0174,0.0159
9.1800,0.1531,1.0200,0.0160
9.2000,0.1534,1.0223,0.0161
9.2200,0.1536,1.0247,0.0162
9.2400,0.1539,1.0268,0.0162
9.2600,0.1542,1.0289,0.0163
9.2800,0.1544,1.0312,0.0163
9.3000,0.1548,1.0336,0.0164
9.3200,0.1552,1.0365,0.0165
9.3400,0.1556,1.0401,0.0165
9.3600,0.1561,1.0442,0.0167
9.3800,0.1565,1.0483,0.0168
9.4000,0.1568,1.0522,0.0168
9.4200,0.1572,1.0558,0.0169
9.4400,0.1575,1.0589,0.0170
9.4600,0.1578,1.0616,0.0171
9.4800,0.1581,1.0644,0.0172
9.5000,0.1584,1.0670,0.0172
9.5200,0.1586,1.0697,0.0172
9.5400,0.1589,1.0721,0.0173
9.5600,0.1592,1.0743,0.0174
9.5800,0.1594,1.0768,0.0175
9.6000,0.1597,1.0793,0.0175
9.6200,0.1601,1.0820,0.0176
9.6400,0.1605,1.0851,0.0177
9.6600,0.1609,1.0886,0.0178
9.6800,0.1614,1.0928,0.0179
9.7000,0.1618,1.0973,0.0180
9.7200,0.1622,1.1016,0.0181
9.7400,0.1625,1.1053,0.0182
9.7600,0.1629,1.1083,0.0183
9.7800,0.1632,1.1111,0.0183
9.8000,0.1634,1.1136,0.0184
9.8200,0.1637,1.1160,0.0184
9.8400,0.1639,1.1184,0.0185
9.8600,0.1642,1.1206,0.0186
9.8800,0.1645,1.1229,0.0186
9.9000,0.1648,1.1251,0.0187
9.9200,0.1652,1.1277,0.0188
9.9400,0.1655,1.1309,0.0188
9.9600,0.1660,1.1347,0.0189
9.9800,0.1664,1.1390,0.0190
10.0000,0.1668,1.1434,0.0191
10.0200,0.1671,1.1472,0.0192
10.0400,0.1675,1.1506,0.0193
10.0600,0.1678,1.1537,0.0194
10.0800,0.1681,1.1566,0.0195
10.1000,0.1684,1.1596,0.0195
10.1200,0.1687,1.1623,0.0196
10.1400,0.1690,1.1648,0.0197
10.1600,0.1692,1.1670,0.0197
10.1800,0.1695,1.1693,0.0198
10.2000,0.1698,1.1718,0.0199
10.2200,0.1701,1.1745,0.0199
10.2400,0.1705,1.1775,0.0200
10.2600,0.1709,1.1809,0.0201
10.2800,0.1713,1.1850,0.0202
10.3000,0.1718,1.1893,0.0203
10.3200,0.1722,1.1936,0.0204
10.3400,0.1726,1.1976,0.0205
10.3600,0.1729,1.2011,0.0206
10.3800,0.1732,1.2042,0.0207
10.4000,0.1735,1.2069,0.0207
10.4200,0.1737,1.2094,0.0208
10.4400,0.1739,1.2117,0.0209
10.4600,0.1742,1.2138,0.0209
10.4800,0.1745,1.2160,0.0210
10.5000,0.1747,1.2184,0.0210
10.5200,0.1751,1.2209,0.0211
10.5400,0.1754,1.2239,0.0212
10.5600,0.1759,1.2275,0.0213
10.5800,0.1764,1.2316,0.0214
10.6000,0.1768,1.2362,0.0215
10.6200,0.1772,1.2405,0.0216
10.6400,0.1775,1.2443,0.0217
10.6600,0.1778,1.2477,0.0218
10.6800,0.1781,1.2507,0.0218
10.7000,0.1784,1.2537,0.0219
10.7200,0.1787,1.2563,0.0220
10.7400,0.1790,1.2589,0.0220
10.7600,0.1793,1.2614,0.0221
10.7800,0.1795,1.2639,0.0222
10.8000,0.1798,1.2662,0.0222
10.8200,0.1801,1.2686,0.0223
10.8400,0.1805,1.2712,0.0224
10.8600,0.1809,1.2744,0.0224
10.8800,0.1813,1.2783,0.0226
10.9000,0.1817,1.2826,0.0227
10.9200,0.1821,1.2871,0.0228
10.9400,0.1825,1.2913,0.0229
10.9600,0.1829,1.2951,0.0230
10.9800,0.1832,1.2984,0.0230
11.0000,0.1834,1.3011,0.0231
11.0200,0.1837,1.3035,0.0232
11.0400,0.1840,1.3060,0.0232
11.0600,0.1842,1.3085,0.0233
11.0800,0.1845,1.3108,0.0234
11.1000,0.1848,1.3133,0.0235
11.1200,0.1851,1.3158,0.0235
11.1400,0.1854,1.3186,0.0236
11.1600,0.1858,1.3218,0.0236
11.1800,0.1863,1.3256,0.0237
11.2000,0.1867,1.3300,0.0238
11.2200,0.1871,1.3344,0.0240
11.2400,0.1875,1.3386,0.0241
11.2600,0.1878,1.3424,0.0242
11.2800,0.1882,1.3458,0.0242
11.3000,0.1885,1.3487,0.0243
11.3200,0.1888,1.3517,0.0244
11.3400,0.1891,1.3543,0.0245
11.3600,0.1893,1.3566,0.0245
11.3800,0.1896,1.3591,0.0246
11.4000,0.1899,1.3616,0.0247
11.4200,0.1901,1.3641,0.0247
11.4400,0.1904,1.3667,0.0248
11.4600,0.1908,1.3697,0.0249
11.4800,0.1912,1.3732,0.0250
11.5000,0.1916,1.3770,0.0251
11.5200,0.1921,1.3816,0.0251
11.5400,0.1925,1.3862,0.0253
11.5600,0.1929,1.3902,0.0254
11.5800,0.1931,1.3938,0.0254
11.6000,0.1934,1.3967,0.0255
11.6200,0.1938,1.3995,0.0256
11.6400,0.1940,1.4022,0.0257
11.6600,0.1943,1.4047,0.0257
11.6800,0.1946,1.4074,0.0258
11.7000,0.1948,1.4099,0.0259
11.7200,0.1951,1.4122,0.0259
11.7400,0.1954,1.4147,0.0260
11.7600,0.1958,1.4179,0.0261
11.7800,0.1962,1.4213,0.0261
11.8000,0.1967,1.4254,0.0262
11.8200,0.1971,1.4299,0.0264
11.8400,0.1975,1.4344,0.0265
11.8600,0.1979,1.4386,0.0266
11.8800,0.1982,1.4424,0.0267
11.9000,0.1985,1.4458,0.0268
11.9200,0.1988,1.4489,0.0268
11.9400,0.1991,1.4516,0.0269
11.9600,0.1994,1.4542,0.0270
11.9800,0.1997,1.4567,0.0270
12.0000,0.1999,1.4592,0.0271
12.0200,0.2002,1.4616,0.0272
12.0400,0.2005,1.4642,0.0272
12.0600,0.2008,1.4667,0.0273
12.0800,0.2012,1.4698,0.0274
12.1000,0.2015,1.4733,0.0274
12.1200,0.2020,1.4776,0.0275
12.1400,0.2024,1.4821,0.0277
12.1600,0.2028,1.4866,0.0278
12.1800,0.2031,1.4906,0.0279
12.2000,0.2035,1.4941,0.0280
12.2200,0.2038,1.4972,0.0280
12.2400,0.2041,1.5003,0.0281
12.2600,0.2044,1.5031,0.0282
12.2800,0.2046,1.5056,0.0283
12.3000,0.2049,1.5082,0.0283
12.3200,0.2052,1.5106,0.0284
12.3400,0.2054,1.5130,0.0285
12.3600,0.2058,1.5159,0.0285
12.3800,0.2061,1.5193,0.0286
12.4000,0.2066,1.5231,0.0287
12.4200,0.2071,1.5274,0.0288
12.4400,0.2075,1.5319,0.0289
12.4600,0.2079,1.5363,0.0291
12.4800,0.2082,1.5404,0.0292
12.5000,0.2086,1.5441,0.0292
12.5200,0.2089,1.5472,0.0293
12.5400,0.2091,1.5502,0.0294
12.5600,0.2094,1.5531,0.0295
12.5800,0.2097,1.5556,0.0295
12.6000,0.2099,1.5579,0.0296
12.6200,0.2102,1.5603,0.0296
12.6400,0.2105,1.5628,0.0297
12.6600,0.2107,1.5655,0.0298
12.6800,0.2111,1.5683,0.0299
12.7000,0.2115,1.5717,0.0299
12.7200,0.2119,1.5756,0.0300
12.7400,0.2124,1.5802,0.0302
12.7600,0.2128,1.5848,0.0303
12.7800,0.2132,1.5891,0.0304
12.8000,0.2135,1.5931,0.0305
12.8200,0.2138,1.5965,0.0305
12.8400,0.2141,1.5996,0.0306
12.8600,0.2144,1.6026,0.0307
12.8800,0.2147,1.6054,0.0308
12.9000,0.2150,1.6079,0.0308
12.9200,0.2152,1.6104,0.0309
12.9400,0.2155,1.6129,0.0309
12.9600,0.2158,1.6156,0.0310
12.9800,0.2162,1.6185,0.0311
13.0000,0.2165,1.6219,0.0312
13.0200,0.2170,1.6260,0.0313
13.0400,0.2174,1.6309,0.0314
13.0600,0.2178,1.6355,0.0315
13.0800,0.2182,1.6398,0.0316
13.1000,0.2185,1.6436,0.0317
13.1200,0.2188,1.6467,0.0318
13.1400,0.2191,1.6496,0.0319
13.1600,0.2194,1.6525,0.0320
13.1800,0.2197,1.6552,0.0320
13.2000,0.2199,1.6576,0.0321
13.2200,0.2202,1.6601,0.0322
13.2400,0.2205,1.6626,0.0322
13.2600,0.2208,1.6651,0.0323
13.2800,0.2211,1.6677,0.0324
13.3000,0.2215,1.6710,0.0325
13.3200,0.2218,1.6748,0.0325
13.3400,0.2223,1.6789,0.0326
13.3600,0.2227,1.6834,0.0328
13.3800,0.2231,1.6882,0.0329
13.4000,0.2235,1.6926,0.0330
13.4200,0.2238,1.6965,0.0331
13.4400,0.2241,1.7000,0.0332
13.4600,0.2245,1.7031,0.0333
13.4800,0.2247,1.7059,0.0333
13.5000,0.2250,1.7085,0.0334
13.5200,0.2253,1.7109,0.0335
13.5400,0.2255,1.7132,0.0335
13.5600,0.2258,1.7157,0.0336
13.5800,0.2261,1.7184,0.0336
13.6000,0.2265,1.7216,0.0337
13.6200,0.2269,1.7252,0.0338
13.6400,0.2274,1.7296,0.0339
13.6600,0.2278,1.7344,0.0341
13.6800,0.2282,1.7388,0.0342
13.7000,0.2285,1.7428,0.0343
13.7200,0.2288,1.7463,0.0343
13.7400,0.2291,1.7494,0.0344
13.7600,0.2294,1.7524,0.0345
13.7800,0.2297,1.7552,0.0346
13.8000,0.2300,1.7580,0.0347
13.8200,0.2302,1.7605,0.0347
13.8400,0.2305,1.7630,0.0348
13.8600,0.2308,1.7658,0.0349
13.8800,0.2311,1.7687,0.0349
13.9000,0.2314,1.7714,0.0350
13.9200,0.2318,1.7745,0.0351
13.9400,0.2322,1.7784,0.0352
13.9600,0.2327,1.7830,0.0353
13.9800,0.2331,1.7878,0.0354
14.0000,0.2335,1.7925,0.0355
14.0200,0.2338,1.7967,0.0357
14.0400,0.2342,1.8005,0.0358
14.0600,0.2345,1.8036,0.0358
14.0800,0.2347,1.8064,0.0359
14.1000,0.2350,1.8090,0.0359
14.1200,0.2353,1.8116,0.0360
14.1400,0.2356,1.8141,0.0361
14.1600,0.2358,1.8165,0.0362
14.1800,0.2361,1.8190,0.0363
14.2000,0.2365,1.8217,0.0363
14.2200,0.2368,1.8251,0.0364
14.2400,0.2373,1.8290,0.0365
14.2600,0.2377,1.8335,0.0366
14.2800,0.2381,1.8382,0.0367
14.3000,0.2385,1.8428,0.0369
14.3200,0.2388,1.8468,0.0370
14.3400,0.2391,1.8504,0.0371
14.3600,0.2395,1.8535,0.0371
14.3800,0.2397,1.8566,0.0372
14.4000,0.2401,1.8595,0.0373
14.4200,0.2403,1.8622,0.0373
14.4400,0.2406,1.8648,0.0374
14.4600,0.2409,1.8675,0.0375
14.4800,0.2411,1.8701,0.0376
14.5000,0.2414,1.8727,0.0376
14.5200,0.2418,1.8759,0.0377
14.5400,0.2422,1.8797,0.0378
14.5600,0.2426,1.8840,0.0379
14.5800,0.2431,1.8886,0.0381
14.6000,0.2435,1.8932,0.0382
14.6200,0.2439,1.8977,0.0383
14.6400,0.2442,1.9018,0.0384
14.6600,0.2445,1.9052,0.0385
14.6800,0.2448,1.9083,0.0385
14.7000,0.2450,1.9111,0.0386
14.7200,0.2453,1.9136,0.0387
14.7400,0.2456,1.9160,0.0388
14.7600,0.2458,1.9184,0.0388
14.7800,0.2461,1.9209,0.0389
14.8000,0.2464,1.9236,0.0389
14.8200,0.2468,1.9268,0.0390
14.8400,0.2472,1.9305,0.0391
14.8600,0.2476,1.9348,0.0392
14.8800,0.2481,1.9395,0.0394
14.9000,0.2485,1.9444,0.0395
14.9200,0.2488,1.9488,0.0396
14.9400,0.2492,1.9526,0.0397
14.9600,0.2495,1.9560,0.0398
14.9800,0.2498,1.9591,0.0399
15.0000,0.2501,1.9621,0.0400
15.0200,0.2503,1.9650,0.0400
15.0400,0.2506,1.9677,0.0401
15.0600,0.2509,1.9704,0.0402
15.0800,0.2512,1.9730,0.0403
15.1000,0.2515,1.9756,0.0404
15.1200,0.2518,1.9785,0.0404
15.1400,0.2522,1.9820,0.0405
15.1600,0.2526,1.9860,0.0406
15.1800,0.2531,1.9906,0.0407
15.2000,0.2534,1.9955,0.0408
15.2200,0.2539,2.0002,0.0409
15.2400,0.2542,2.0045,0.0411
15.2600,0.2545,2.0082,0.0412
15.2800,0.2548,2.0113,0.0412
15.3000,0.2551,2.0141,0.0413
15.3200,0.2554,2.0167,0.0414
15.3400,0.2556,2.0193,0.0414
15.3600,0.2559,2.0219,0.0415
15.3800,0.2561,2.0244,0.0416
15.4000,0.2564,2.0269,0.0417
15.4200,0.2568,2.0298,0.0417
15.4400,0.2571,2.0333,0.0418
15.4600,0.2576,2.0373,0.0419
15.4800,0.2581,2.0420,0.0420
15.5000,0.2585,2.0472,0.0422
15.5200,0.2589,2.0519,0.0423
15.5400,0.2592,2.0560,0.0424
15.5600,0.2595,2.0595,0.0425
15.5800,0.2598,2.0628,0.0426
15.6000,0.2601,2.0659,0.0427
15.6200,0.2604,2.0688,0.0428
15.6400,0.2607,2.0714,0.0428
15.6600,0.2609,2.0742,0.0429
15.6800,0.2612,2.0767,0.0430
15.7000,0.2615,2.0794,0.0431
15.7200,0.2618,2.0822,0.0431
15.7400,0.2621,2.0852,0.0432
15.7600,0.2626,2.0888,0.0433
15.7800,0.2630,2.0931,0.0434
15.8000,0.2634,2.0978,0.0435
15.8200,0.2638,2.1024,0.0437
15.8400,0.2642,2.1069,0.0438
15.8600,0.2645,2.1110,0.0439
15.8800,0.2648,2.1144,0.0439
15.9000,0.2651,2.1174,0.0440
15.9200,0.2654,2.1203,0.0441
15.9400,0.2657,2.1229,0.0442
15.9600,0.2659,2.1257,0.0443
15.9800,0.2662,2.1283,0.0443
16.0000,0.2665,2.1308,0.0444
16.0200,0.2667,2.1335,0.0445
16.0400,0.2671,2.1366,0.0445
16.0600,0.2675,2.1401,0.0446
16.0800,0.2680,2.1445,0.0448
16.1000,0.2684,2.1493,0.0449
16.1200,0.2688,2.1545,0.0450
16.1400,0.2692,2.1592,0.0451
16.1600,0.2695,2.1632,0.0452
16.1800,0.2698,2.1666,0.0453
16.2000,0.2702,2.1695,0.0454
16.2200,0.2704,2.1725,0.0455
16.2400,0.2707,2.1755,0.0456
16.2600,0.2710,2.1782,0.0456
16.2800,0.2712,2.1808,0.0457
16.3000,0.2715,2.1834,0.0457
16.3200,0.2718,2.1860,0.0458
16.3400,0.2721,2.1888,0.0459
16.3600,0.2725,2.1920,0.0460
16.3800,0.2728,2.1957,0.0461
16.4000,0.2733,2.2001,0.0462
16.4200,0.2737,2.2048,0.0463
16.4400,0.2741,2.2096,0.0465
16.4600,0.2744,2.2138,0.0465
16.4800,0.2748,2.2177,0.0466
16.5000,0.2751,2.2211,0.0467
16.5200,0.2754,2.2241,0.0468
16.5400,0.2757,2.2270,0.0469
16.5600,0.2759,2.2300,0.0470
16.5800,0.2762,2.2329,0.0471
16.6000,0.2765,2.2354,0.0471
16.6200,0.2767,2.2382,0.0472
16.6400,0.2771,2.2410,0.0473
16.6600,0.2774,2.2443,0.0474
16.6800,0.2779,2.2483,0.0475
16.7000,0.2784,2.2529,0.0476
16.7200,0.2788,2.2579,0.0477
16.7400,0.2792,2.2629,0.0478
16.7600,0.2795,2.2673,0.0480
16.7800,0.2799,2.2709,0.0480
16.8000,0.2802,2.2738,0.0481
16.8200,0.2804,2.2768,0.0482
16.8400,0.2807,2.2797,0.0482
16.8600,0.2810,2.2824,0.0483
16.8800,0.2812,2.2850,0.0484
16.9000,0.2815,2.2876,0.0485
16.9200,0.2818,2.2902,0.0486
16.9400,0.2821,2.2929,0.0486
16.9600,0.2824,2.2958,0.0487
16.9800,0.2828,2.2992,0.0488
17.0000,0.2832,2.3034,0.0489
17.0200,0.2837,2.3084,0.0490
17.0400,0.2841,2.3134,0.0492
17.0600,0.2845,2.3182,0.0493
17.0800,0.2848,2.3226,0.0493
17.1000,0.2852,2.3266,0.0495
17.1200,0.2855,2.3299,0.0496
17.1400,0.2857,2.3330,0.0497
17.1600,0.2860,2.3359,0.0498
17.1800,0.2863,2.3384,0.0498
17.2000,0.2866,2.3408,0.0499
17.2200,0.2868,2.3433,0.0499
17.2400,0.2871,2.3460,0.0500
17.2600,0.2875,2.3490,0.0501
17.2800,0.2879,2.3528,0.0502
17.3000,0.2883,2.3570,0.0503
17.3200,0.2888,2.3619,0.0504
17.3400,0.2892,2.3671,0.0506
17.3600,0.2896,2.3719,0.0507
17.3800,0.2899,2.3758,0.0508
17.4000,0.2901,2.3792,0.0509
17.4200,0.2905,2.3824,0.0510
17.4400,0.2907,2.3854,0.0510
17.4600,0.2911,2.3882,0.0511
17.4800,0.2913,2.3910,0.0512
17.5000,0.2915,2.3938,0.0513
17.5200,0.2919,2.3966,0.0513
17.5400,0.2921,2.3994,0.0514
17.5600,0.2924,2.4022,0.0514
17.5800,0.2928,2.4053,0.0515
17.6000,0.2932,2.4089,0.0517
17.6200,0.2936,2.4135,0.0518
17.6400,0.2941,2.4185,0.0519
17.6600,0.2945,2.4236,0.0520
17.6800,0.2949,2.4283,0.0522
17.7000,0.2952,2.4325,0.0523
17.7200,0.2956,2.4361,0.0524
17.7400,0.2958,2.4393,0.0524
17.7600,0.2961,2.4423,0.0525
17.7800,0.2964,2.4452,0.0526
17.8000,0.2966,2.4479,0.0526
17.8200,0.2969,2.4504,0.0527
17.8400,0.2972,2.4530,0.0528
17.8600,0.2975,2.4557,0.0529
17.8800,0.2978,2.4589,0.0529
17.9000,0.2982,2.4628,0.0530
17.9200,0.2987,2.4674,0.0532
17.9400,0.2991,2.4723,0.0533
17.9600,0.2995,2.4772,0.0534
17.9800,0.2998,2.4815,0.0535
18.0000,0.3002,2.4855,0.0536
18.0200,0.3005,2.4890,0.0537
18.0400,0.3008,2.4923,0.0538
18.0600,0.3011,2.4955,0.0538
18.0800,0.3013,2.4985,0.0540
18.1000,0.3016,2.5012,0.0540
18.1200,0.3019,2.5040,0.0541
18.1400,0.3022,2.5069,0.0542
18.1600,0.3025,2.5096,0.0543
18.1800,0.3028,2.5126,0.0543
18.2000,0.3032,2.5160,0.0544
18.2200,0.3036,2.5202,0.0545
18.2400,0.3040,2.5248,0.0547
18.2600,0.3044,2.5298,0.0548
18.2800,0.3049,2.5347,0.0549
18.3000,0.3052,2.5393,0.0550
18.3200,0.3055,2.5433,0.0551
18.3400,0.3058,2.5469,0.0552
18.3600,0.3062,2.5502,0.0553
18.3800,0.3064,2.5531,0.0554
18.4000,0.3067,2.5557,0.0555
18.4200,0.3069,2.5582,0.0555
18.4400,0.3072,2.5605,0.0556
18.4600,0.3074,2.5630,0.0556
18.4800,0.3078,2.5660,0.0557
18.5000,0.3081,2.5693,0.0558
18.5200,0.3086,2.5733,0.0559
18.5400,0.3090,2.5779,0.0560
18.5600,0.3094,2.5828,0.0562
18.5800,0.3098,2.5879,0.0563
18.6000,0.3102,2.5924,0.0564
18.6200,0.3105,2.5963,0.0565
18.6400,0.3108,2.5997,0.0566
18.6600,0.3111,2.6030,0.0567
18.6800,0.3114,2.6061,0.0567
18.7000,0.3117,2.6089,0.0568
18.7200,0.3119,2.6119,0.0569
18.7400,0.3122,2.6147,0.0570
18.7600,0.3125,2.6175,0.0571
18.7800,0.3127,2.6203,0.0571
18.8000,0.3131,2.6233,0.0572
18.8200,0.3135,2.6270,0.0572
18.8400,0.3139,2.6313,0.0573
18.8600,0.3144,2.6360,0.0575
18.8800,0.3148,2.6411,0.0577
18.9000,0.3152,2.6460,0.0578
18.9200,0.3155,2.6504,0.0579
18.9400,0.3159,2.6542,0.0580
18.9600,0.3161,2.6576,0.0581
18.9800,0.3164,2.6605,0.0582
19.0000,0.3167,2.6632,0.0582
19.0200,0.3169,2.6658,0.0583
19.0400,0.3172,2.6683,0.0583
19.0600,0.3175,2.6707,0.0584
19.0800,0.3177,2.6733,0.0585
19.1000,0.3181,2.6763,0.0586
19.1200,0.3185,2.6800,0.0587
19.1400,0.3189,2.6843,0.0588
19.1600,0.3193,2.6892,0.0589
19.1800,0.3198,2.6945,0.0590
19.2000,0.3201,2.6995,0.0591
19.2200,0.3205,2.7036,0.0592
19.2400,0.3208,2.7073,0.0594
19.2600,0.3211,2.7108,0.0594
19.2800,0.3214,2.7143,0.0595
19.3000,0.3217,2.7176,0.0596
19.3200,0.3220,2.7206,0.0597
19.3400,0.3222,2.7231,0.0598
19.3600,0.3225,2.7258,0.0599
19.3800,0.3228,2.7285,0.0599
19.4000,0.3231,2.7315,0.0600
19.4200,0.3235,2.7347,0.0600
19.4400,0.3239,2.7384,0.0601
19.4600,0.3243,2.7430,0.0603
19.4800,0.3247,2.7480,0.0604
19.5000,0.3252,2.7531,0.0606
19.5200,0.3255,2.7579,0.0606
19.5400,0.3258,2.7620,0.0607
19.5600,0.3261,2.7653,0.0608
19.5800,0.3264,2.7684,0.0609
19.6000,0.3267,2.7715,0.0610
19.6200,0.3269,2.7742,0.0611
19.6400,0.3273,2.7771,0.0612
19.6600,0.3275,2.7797,0.0613
19.6800,0.3277,2.7825,0.0613
19.7000,0.3281,2.7853,0.0614
19.7200,0.3284,2.7885,0.0615
19.7400,0.3288,2.7924,0.0616
19.7600,0.3293,2.7973,0.0617
19.7800,0.3297,2.8025,0.0618
19.8000,0.3302,2.8076,0.0619
19.8200,0.3305,2.8122,0.0620
19.8400,0.3309,2.8163,0.0622
19.8600,0.3312,2.8199,0.0623
19.8800,0.3315,2.8233,0.0623
19.9000,0.3318,2.8267,0.0624
19.9200,0.3320,2.8299,0.0625
19.9400,0.3323,2.8326,0.0626
19.9600,0.3326,2.8352,0.0627
19.9800,0.3328,2.8377,0.0627
20.0000,0.3331,2.8404,0.0628
20.0200,0.3335,2.8435,0.0629
20.0400,0.3338,2.8471,0.0630
20.0600,0.3342,2.8513,0.0630
20.0800,0.3347,2.8560,0.0632
20.1000,0.3351,2.8609,0.0633
20.1200,0.3355,2.8658,0.0634
20.1400,0.3358,2.8702,0.0636
20.1600,0.3362,2.8742,0.0637
20.1800,0.3365,2.8778,0.0637
20.2000,0.3367,2.8811,0.0638
20.2200,0.3370,2.8842,0.0639
20.2400,0.3373,2.8870,0.0640
20.2600,0.3376,2.8896,0.0640
20.2800,0.3378,2.8922,0.0641
20.3000,0.3381,2.8949,0.0642
20.3200,0.3384,2.8980,0.0643
20.3400,0.3388,2.9015,0.0644
20.3600,0.3393,2.9057,0.0645
20.3800,0.3397,2.9107,0.0646
20.4000,0.3401,2.9161,0.0647
20.4200,0.3406,2.9213,0.0649
20.4400,0.3409,2.9260,0.0650
20.4600,0.3412,2.9300,0.0651
20.4800,0.3415,2.9336,0.0652
20.5000,0.3418,2.9369,0.0652
20.5200,0.3421,2.9401,0.0653
20.5400,0.3424,2.9430,0.0654
20.5600,0.3426,2.9455,0.0655
20.5800,0.3429,2.9482,0.0656
20.6000,0.3431,2.9509,0.0657
20.6200,0.3434,2.9537,0.0658
20.6400,0.3438,2.9568,0.0658
20.6600,0.3441,2.9603,0.0659
20.6800,0.3446,2.9645,0.0660
20.7000,0.3450,2.9695,0.0661
20.7200,0.3454,2.9746,0.0662
20.7400,0.3458,2.9794,0.0664
20.7600,0.3462,2.9840,0.0665
20.7800,0.3465,2.9880,0.0666
20.8000,0.3468,2.9916,0.0667
20.8200,0.3471,2.9947,0.0668
20.8400,0.3474,2.9976,0.0669
20.8600,0.3476,3.0004,0.0669
20.8800,0.3478,3.0033,0.0670
20.9000,0.3481,3.0061,0.0670
20.9200,0.3484,3.0090,0.0671
20.9400,0.3488,3.0121,0.0672
20.9600,0.3492,3.0160,0.0673
20.9800,0.3497,3.0204,0.0674
21.0000,0.3501,3.0257,0.0676
21.0200,0.3505,3.0310,0.0677
21.0400,0.3509,3.0359,0.0678
21.0600,0.3512,3.0402,0.0679
21.0800,0.3515,3.0439,0.0680
21.1000,0.3519,3.0472,0.0681
21.1200,0.3521,3.0505,0.0682
21.1400,0.3524,3.0535,0.0683
21.1600,0.3526,3.0562,0.0684
21.1800,0.3529,3.0586,0.0684
21.2000,0.3531,3.0612,0.0685
21.2200,0.3535,3.0640,0.0686
21.2400,0.3537,3.0670,0.0686
21.2600,0.3541,3.0703,0.0687
21.2800,0.3545,3.0741,0.0688
21.3000,0.3550,3.0786,0.0689
21.3200,0.3554,3.0839,0.0690
21.3400,0.3558,3.0893,0.0692
21.3600,0.3561,3.0941,0.0693
21.3800,0.3565,3.0984,0.0694
21.4000,0.3568,3.1022,0.0695
21.4200,0.3571,3.1056,0.0696
21.4400,0.3574,3.1086,0.0697
21.4600,0.3576,3.1115,0.0698
21.4800,0.3579,3.1144,0.0698
21.5000,0.3582,3.1169,0.0699
21.5200,0.3584,3.1194,0.0700
21.5400,0.3588,3.1222,0.0700
21.5600,0.3591,3.1257,0.0701
21.5800,0.3596,3.1299,0.0702
21.6000,0.3601,3.1347,0.0703
21.6200,0.3605,3.1399,0.0705
21.6400,0.3609,3.1451,0.0706
21.6600,0.3612,3.1499,0.0707
21.6800,0.3615,3.1539,0.0708
21.7000,0.3618,3.1573,0.0709
21.7200,0.3621,3.1605,0.0710
21.7400,0.3624,3.1637,0.0711
21.7600,0.3626,3.1667,0.0711
21.7800,0.3629,3.1694,0.0712
21.8000,0.3632,3.1721,0.0713
21.8200,0.3634,3.1749,0.0713
21.8400,0.3637,3.1777,0.0714
21.8600,0.3641,3.1807,0.0715
21.8800,0.3644,3.1843,0.0716
21.9000,0.3649,3.1885,0.0717
21.9200,0.3653,3.1931,0.0718
21.9400,0.3657,3.1984,0.0720
21.9600,0.3662,3.2038,0.0721
21.9800,0.3665,3.2086,0.0722
22.0000,0.3669,3.2129,0.0723
22.0200,0.3671,3.2166,0.0724
22.0400,0.3674,3.2197,0.0725
22.0600,0.3677,3.2225,0.0725
22.0800,0.3680,3.2255,0.0726
22.1000,0.3682,3.2282,0.0727
22.1200,0.3685,3.2307,0.0728
22.1400,0.3688,3.2335,0.0728
22.1600,0.3691,3.2366,0.0729
22.1800,0.3695,3.2404,0.0730
22.2000,0.3700,3.2448,0.0731
22.2200,0.3704,3.2499,0.0733
22.2400,0.3708,3.2552,0.0734
22.2600,0.3711,3.2600,0.0736
22.2800,0.3715,3.2642,0.0736
22.3000,0.3718,3.2678,0.0737
22.3200,0.3721,3.2712,0.0738
22.3400,0.3724,3.2746,0.0739
22.3600,0.3727,3.2777,0.0740
22.3800,0.3730,3.2806,0.0740
22.4000,0.3732,3.2834,0.0741
22.4200,0.3735,3.2863,0.0742
22.4400,0.3738,3.2891,0.0743
22.4600,0.3741,3.2922,0.0743
22.4800,0.3744,3.2953,0.0744
22.5000,0.3748,3.2991,0.0745
22.5200,0.3753,3.3037,0.0746
22.5400,0.3757,3.3090,0.0748
22.5600,0.3762,3.3145,0.0749
22.5800,0.3766,3.3195,0.0750
22.6000,0.3769,3.3240,0.0751
22.6200,0.3772,3.3280,0.0752
22.6400,0.3775,3.3313,0.0753
22.6600,0.3777,3.3345,0.0754
22.6800,0.3781,3.3375,0.0755
22.7000,0.3783,3.3402,0.0756
22.7200,0.3785,3.3429,0.0756
22.7400,0.3788,3.3455,0.0757
22.7600,0.3791,3.3483,0.0758
22.7800,0.3794,3.3515,0.0759
22.8000,0.3799,3.3554,0.0759
22.8200,0.3803,3.3601,0.0761
22.8400,0.3807,3.3651,0.0762
22.8600,0.3811,3.3705,0.0763
22.8800,0.3815,3.3753,0.0765
22.9000,0.3818,3.3795,0.0766
22.9200,0.3821,3.3832,0.0766
22.9400,0.3824,3.3867,0.0767
22.9600,0.3827,3.3901,0.0768
22.9800,0.3830,3.3932,0.0769
23.0000,0.3832,3.3961,0.0770
23.0200,0.3835,3.3988,0.0771
23.0400,0.3838,3.4017,0.0771
23.0600,0.3841,3.4046,0.0772
23.0800,0.3844,3.4076,0.0773
23.1000,0.3848,3.4113,0.0774
23.1200,0.3852,3.4155,0.0775
23.1400,0.3857,3.4204,0.0776
23.1600,0.3861,3.4257,0.0777
23.1800,0.3866,3.4311,0.0779
23.2000,0.3869,3.4362,0.0780
23.2200,0.3872,3.4403,0.0781
23.2400,0.3875,3.4437,0.0782
23.2600,0.3877,3.4468,0.0783
23.2800,0.3880,3.4497,0.0783
23.3000,0.3883,3.4524,0.0784
23.3200,0.3886,3.4551,0.0784
23.3400,0.3888,3.4580,0.0786
23.3600,0.3891,3.4608,0.0786
23.3800,0.3894,3.4638,0.0787
23.4000,0.3898,3.4673,0.0788
23.4200,0.3902,3.4715,0.0789
23.4400,0.3907,3.4767,0.0790
23.4600,0.3911,3.4823,0.0792
23.4800,0.3915,3.4877,0.0793
23.5000,0.3918,3.4923,0.0794
23.5200,0.3922,3.4962,0.0795
23.5400,0.3925,3.4997,0.0796
23.5420,0.3925,3.5001,0.0796