File: Modulus_Steel_4.csv
Time,Displacement,Force,Strain 1
(s),(mm),(kN),(%)
0.00000,0.00010,0.00020,0.00000
0.04000,0.00020,0.00030,0.00000
0.08000,0.00070,0.00010,0.00000
0.12000,0.00170,0.00010,0.00000
0.16000,0.00260,0.00010,-0.00010
0.20000,0.00320,0.00030,0.00000
0.24000,0.00380,0.00020,0.00000
0.28000,0.00460,0.00020,0.00000
0.32000,0.00550,0.00010,0.00000
0.36000,0.00630,0.00020,0.00000
0.40000,0.00690,0.00040,-0.00010
0.44000,0.00760,0.00030,0.00000
0.48000,0.00810,0.00040,0.00000
0.52000,0.00860,0.00040,-0.00010
0.56000,0.00920,0.00030,0.00000
0.60000,0.01000,0.00030,0.00000
0.64000,0.01080,0.00030,-0.00010
0.68000,0.01160,0.00030,0.00000
0.72000,0.01220,0.00030,0.00000
0.76000,0.01280,0.00040,0.00000
0.80000,0.01330,0.00030,0.00000
0.84000,0.01390,0.00030,0.00000
0.88000,0.01460,0.00030,0.00000
0.92000,0.01540,0.00020,0.00000
0.96000,0.01630,0.00030,0.00000
1.00000,0.01690,0.00020,0.00000
1.04000,0.01760,0.00030,0.00000
1.08000,0.01810,0.00030,0.00000
1.12000,0.01860,0.00040,0.00000
1.16000,0.01920,0.00050,0.00000
1.20000,0.01990,0.00030,0.00000
1.24000,0.02080,0.00030,-0.00010
1.28000,0.02150,0.00030,0.00000
1.32000,0.02220,0.00040,0.00010
1.36000,0.02280,0.00020,-0.00010
1.40000,0.02340,0.00030,0.00000
1.44000,0.02390,0.00020,0.00000
1.48000,0.02450,0.00030,-0.00010
1.52000,0.02540,0.00040,0.00000
1.56000,0.02620,0.00040,0.00000
1.60000,0.02690,0.00040,0.00000
1.64000,0.02750,0.00030,0.00000
1.68000,0.02810,0.00040,0.00000
1.72000,0.02870,0.00030,-0.00010
1.76000,0.02920,0.00020,0.00000
1.80000,0.02980,0.00030,0.00000
1.84000,0.03070,0.00020,-0.00010
1.88000,0.03160,0.00020,0.00000
1.92000,0.03220,0.00040,0.00010
1.96000,0.03290,0.00040,0.00000
2.00000,0.03340,0.00030,0.00000
2.04000,0.03400,0.00030,0.00010
2.08000,0.03460,0.00040,0.00000
2.12000,0.03530,0.00020,0.00000
2.16000,0.03620,0.00040,0.00000
2.20000,0.03690,0.00050,0.00000
2.24000,0.03760,0.00040,0.00000
2.28000,0.03820,0.00040,0.00000
2.32000,0.03870,0.00040,0.00000
2.36000,0.03920,0.00020,0.00000
2.40000,0.03990,0.00020,0.00000
2.44000,0.04070,0.00020,0.00000
2.48000,0.04150,0.00020,0.00000
2.52000,0.04230,0.00030,0.00000
2.56000,0.04290,0.00050,0.00000
2.60000,0.04350,0.00040,0.00000
2.64000,0.04400,0.00040,0.00000
2.68000,0.04460,0.00030,0.00000
2.72000,0.04530,0.00030,0.00000
2.76000,0.04610,0.00050,0.00000
2.80000,0.04690,0.00040,0.00000
2.84000,0.04760,0.00040,0.00000
2.88000,0.04820,0.00060,0.00000
2.92000,0.04870,0.00050,0.00000
2.96000,0.04930,0.00050,0.00000
3.00000,0.04990,0.00040,0.00010
3.04000,0.05060,0.00060,0.00000
3.08000,0.05150,0.00070,0.00000
3.12000,0.05230,0.00050,0.00000
3.16000,0.05290,0.00060,0.00000
3.20000,0.05350,0.00070,0.00000
3.24000,0.05400,0.00070,0.00010
3.28000,0.05460,0.00060,0.00000
3.32000,0.05520,0.00070,0.00000
3.36000,0.05610,0.00080,0.00010
3.40000,0.05690,0.00080,0.00000
3.44000,0.05760,0.00060,0.00000
3.48000,0.05820,0.00060,0.00010
3.52000,0.05880,0.00060,0.00000
3.56000,0.05940,0.00080,0.00000
3.60000,0.05990,0.00080,0.00010
3.64000,0.06060,0.00070,0.00000
3.68000,0.06140,0.00080,0.00000
3.72000,0.06220,0.00090,0.00000
3.76000,0.06290,0.00080,0.00000
3.80000,0.06350,0.00080,0.00000
3.84000,0.06410,0.00070,0.00000
3.88000,0.06460,0.00090,-0.00010
3.92000,0.06520,0.00080,0.00000
3.96000,0.06590,0.00070,0.00000
4.00000,0.06690,0.00090,0.00000
4.04000,0.06760,0.00080,-0.00010
4.08000,0.06820,0.00080,0.00000
4.12000,0.06880,0.00080,-0.00010
4.16000,0.06940,0.00090,-0.00010
4.20000,0.06990,0.00090,-0.00010
4.24000,0.07060,0.00100,-0.00010
4.28000,0.07140,0.00080,0.00000
4.32000,0.07220,0.00100,0.00000
4.36000,0.07290,0.00090,-0.00010
4.40000,0.07360,0.00080,-0.00010
4.44000,0.07410,0.00080,0.00000
4.48000,0.07460,0.00080,-0.00010
4.52000,0.07520,0.00100,-0.00010
4.56000,0.07590,0.00090,0.00000
4.60000,0.07680,0.00090,0.00000
4.64000,0.07760,0.00100,0.00000
4.68000,0.07830,0.00100,-0.00010
4.72000,0.07890,0.00130,-0.00010
4.76000,0.07940,0.00130,-0.00010
4.80000,0.07990,0.00110,0.00000
4.84000,0.08050,0.00110,-0.00010
4.88000,0.08130,0.00090,-0.00010
4.92000,0.08220,0.00120,-0.00010
4.96000,0.08290,0.00130,-0.00010
5.00000,0.08350,0.00130,-0.00010
5.04000,0.08410,0.00120,-0.00010
5.08000,0.08460,0.00130,-0.00010
5.12000,0.08520,0.00150,-0.00010
5.16000,0.08590,0.00160,-0.00010
5.20000,0.08680,0.00190,-0.00010
5.24000,0.08760,0.00260,-0.00010
5.28000,0.08830,0.00290,0.00000
5.32000,0.08890,0.00340,0.00000
5.36000,0.08950,0.00370,0.00000
5.40000,0.08990,0.00410,0.00000
5.44000,0.09050,0.00430,0.00000
5.48000,0.09120,0.00470,0.00000
5.52000,0.09210,0.00520,0.00000
5.56000,0.09290,0.00560,0.00000
5.60000,0.09360,0.00620,0.00000
5.64000,0.09420,0.00670,0.00000
5.68000,0.09470,0.00700,0.00000
5.72000,0.09520,0.00740,0.00000
5.76000,0.09590,0.00780,0.00010
5.80000,0.09670,0.00840,0.00000
5.84000,0.09760,0.00910,0.00000
5.88000,0.09830,0.00970,0.00000
5.92000,0.09890,0.01030,0.00000
5.96000,0.09950,0.01110,0.00010
6.00000,0.10000,0.01180,0.00010
6.04000,0.10060,0.01250,0.00010
6.08000,0.10120,0.01330,0.00010
6.12000,0.10210,0.01460,0.00010
6.16000,0.10290,0.01620,0.00010
6.20000,0.10360,0.01760,0.00010
6.24000,0.10420,0.01890,0.00010
6.28000,0.10480,0.02020,0.00010
6.32000,0.10530,0.02120,0.00010
6.36000,0.10590,0.02260,0.00020
6.40000,0.10670,0.02440,0.00010
6.44000,0.10750,0.02670,0.00010
6.48000,0.10830,0.02880,0.00020
6.52000,0.10890,0.03070,0.00010
6.56000,0.10950,0.03220,0.00010
6.60000,0.11010,0.03370,0.00010
6.64000,0.11060,0.03510,0.00010
6.68000,0.11120,0.03660,0.00010
6.72000,0.11200,0.03870,0.00020
6.76000,0.11280,0.04120,0.00020
6.80000,0.11360,0.04420,0.00020
6.84000,0.11430,0.04630,0.00030
6.88000,0.11480,0.04800,0.00030
6.92000,0.11530,0.04960,0.00030
6.96000,0.11590,0.05100,0.00040
7.00000,0.11660,0.05290,0.00040
7.04000,0.11740,0.05540,0.00040
7.08000,0.11820,0.05830,0.00050
7.12000,0.11890,0.06040,0.00050
7.16000,0.11950,0.06220,0.00050
7.20000,0.12010,0.06400,0.00060
7.24000,0.12060,0.06570,0.00070
7.28000,0.12120,0.06740,0.00070
7.32000,0.12190,0.06950,0.00080
7.36000,0.12280,0.07220,0.00080
7.40000,0.12360,0.07500,0.00080
7.44000,0.12430,0.07750,0.00090
7.48000,0.12490,0.07940,0.00100
7.52000,0.12540,0.08090,0.00100
7.56000,0.12590,0.08260,0.00100
7.60000,0.12650,0.08450,0.00110
7.64000,0.12730,0.08720,0.00110
7.68000,0.12820,0.09030,0.00120
7.72000,0.12890,0.09320,0.00120
7.76000,0.12950,0.09600,0.00130
7.80000,0.13010,0.09860,0.00140
7.84000,0.13070,0.10100,0.00140
7.88000,0.13120,0.10320,0.00140
7.92000,0.13190,0.10590,0.00150
7.96000,0.13270,0.10940,0.00160
8.00000,0.13360,0.11360,0.00170
8.04000,0.13420,0.11720,0.00180
8.08000,0.13490,0.12000,0.00180
8.12000,0.13540,0.12250,0.00180
8.16000,0.13590,0.12500,0.00190
8.20000,0.13650,0.12740,0.00190
8.24000,0.13720,0.13040,0.00200
8.28000,0.13820,0.13490,0.00210
8.32000,0.13890,0.13920,0.00220
8.36000,0.13960,0.14260,0.00220
8.40000,0.14020,0.14550,0.00230
8.44000,0.14070,0.14830,0.00230
8.48000,0.14130,0.15080,0.00240
8.52000,0.14190,0.15350,0.00250
8.56000,0.14270,0.15690,0.00250
8.60000,0.14350,0.16130,0.00260
8.64000,0.14430,0.16540,0.00270
8.68000,0.14490,0.16920,0.00280
8.72000,0.14540,0.17220,0.00280
8.76000,0.14600,0.17480,0.00280
8.80000,0.14650,0.17730,0.00290
8.84000,0.14720,0.18040,0.00290
8.88000,0.14810,0.18460,0.00310
8.92000,0.14890,0.18970,0.00320
8.96000,0.14960,0.19360,0.00320
9.00000,0.15020,0.19700,0.00330
9.04000,0.15080,0.20020,0.00330
9.08000,0.15130,0.20270,0.00340
9.12000,0.15190,0.20550,0.00350
9.16000,0.15260,0.20910,0.00350
9.20000,0.15340,0.21370,0.00360
9.24000,0.15420,0.21860,0.00370
9.28000,0.15490,0.22290,0.00380
9.32000,0.15550,0.22630,0.00380
9.36000,0.15610,0.22940,0.00390
9.40000,0.15650,0.23210,0.00390
9.44000,0.15720,0.23530,0.00400
9.48000,0.15800,0.23980,0.00410
9.52000,0.15890,0.24530,0.00420
9.56000,0.15960,0.25030,0.00430
9.60000,0.16020,0.25370,0.00440
9.64000,0.16080,0.25720,0.00440
9.68000,0.16130,0.26010,0.00440
9.72000,0.16180,0.26290,0.00450
9.76000,0.16250,0.26640,0.00460
9.80000,0.16330,0.27090,0.00470
9.84000,0.16420,0.27640,0.00480
9.88000,0.16490,0.28100,0.00480
9.92000,0.16550,0.28480,0.00490
9.96000,0.16610,0.28810,0.00500
10.00000,0.16660,0.29110,0.00510
10.04000,0.16720,0.29380,0.00510
10.08000,0.16800,0.29840,0.00520
10.12000,0.16890,0.30380,0.00530
10.16000,0.16960,0.30900,0.00540
10.20000,0.17020,0.31300,0.00550
10.24000,0.17080,0.31670,0.00550
10.28000,0.17140,0.32020,0.00560
10.32000,0.17190,0.32350,0.00560
10.36000,0.17250,0.32660,0.00570
10.40000,0.17330,0.33080,0.00580
10.44000,0.17420,0.33660,0.00590
10.48000,0.17500,0.34200,0.00600
10.52000,0.17560,0.34630,0.00610
10.56000,0.17610,0.34970,0.00620
10.60000,0.17670,0.35300,0.00620
10.64000,0.17720,0.35590,0.00630
10.68000,0.17800,0.36000,0.00630
10.72000,0.17880,0.36550,0.00650
10.76000,0.17960,0.37130,0.00660
10.80000,0.18020,0.37580,0.00660
10.84000,0.18090,0.37990,0.00670
10.88000,0.18140,0.38340,0.00680
10.92000,0.18190,0.38670,0.00680
10.96000,0.18250,0.38990,0.00690
11.00000,0.18330,0.39420,0.00700
11.04000,0.18410,0.39990,0.00710
11.08000,0.18490,0.40580,0.00720
11.12000,0.18560,0.41060,0.00730
11.16000,0.18620,0.41430,0.00740
11.20000,0.18670,0.41780,0.00750
11.24000,0.18720,0.42100,0.00750
11.28000,0.18790,0.42460,0.00760
11.32000,0.18870,0.42980,0.00770
11.36000,0.18950,0.43600,0.00780
11.40000,0.19020,0.44120,0.00790
11.44000,0.19090,0.44540,0.00800
11.48000,0.19140,0.44930,0.00810
11.52000,0.19200,0.45290,0.00810
11.56000,0.19250,0.45650,0.00820
11.60000,0.19320,0.46050,0.00830
11.64000,0.19410,0.46590,0.00840
11.68000,0.19490,0.47250,0.00850
11.72000,0.19560,0.47790,0.00860
11.76000,0.19620,0.48180,0.00870
11.80000,0.19670,0.48510,0.00880
11.84000,0.19720,0.48830,0.00880
11.88000,0.19780,0.49180,0.00890
11.92000,0.19860,0.49680,0.00900
11.96000,0.19960,0.50330,0.00910
12.00000,0.20020,0.50920,0.00930
12.04000,0.20090,0.51380,0.00930
12.08000,0.20150,0.51780,0.00940
12.12000,0.20200,0.52150,0.00950
12.16000,0.20260,0.52510,0.00960
12.20000,0.20320,0.52870,0.00960
12.24000,0.20400,0.53400,0.00980
12.28000,0.20490,0.54050,0.00990
12.32000,0.20560,0.54660,0.01000
12.36000,0.20620,0.55090,0.01010
12.40000,0.20670,0.55480,0.01010
12.44000,0.20730,0.55840,0.01030
12.48000,0.20780,0.56200,0.01030
12.52000,0.20860,0.56650,0.01040
12.56000,0.20950,0.57280,0.01050
12.60000,0.21030,0.57920,0.01070
12.64000,0.21090,0.58450,0.01080
12.68000,0.21150,0.58870,0.01090
12.72000,0.21210,0.59270,0.01100
12.76000,0.21260,0.59630,0.01100
12.80000,0.21320,0.60010,0.01110
12.84000,0.21400,0.60470,0.01120
12.88000,0.21480,0.61120,0.01140
12.92000,0.21560,0.61760,0.01150
12.96000,0.21620,0.62270,0.01160
13.00000,0.21680,0.62700,0.01170
13.04000,0.21730,0.63090,0.01170
13.08000,0.21790,0.63460,0.01180
13.12000,0.21860,0.63880,0.01190
13.16000,0.21940,0.64480,0.01200
13.20000,0.22020,0.65160,0.01220
13.24000,0.22090,0.65760,0.01230
13.28000,0.22160,0.66210,0.01240
13.32000,0.22220,0.66630,0.01250
13.36000,0.22270,0.67010,0.01250
13.40000,0.22320,0.67390,0.01260
13.44000,0.22390,0.67840,0.01270
13.48000,0.22470,0.68430,0.01290
13.52000,0.22550,0.69120,0.01300
13.56000,0.22620,0.69730,0.01310
13.60000,0.22690,0.70190,0.01320
13.64000,0.22740,0.70590,0.01330
13.68000,0.22790,0.70960,0.01340
13.72000,0.22850,0.71370,0.01350
13.76000,0.22930,0.71910,0.01360
13.80000,0.23020,0.72620,0.01380
13.84000,0.23090,0.73260,0.01390
13.88000,0.23160,0.73800,0.01400
13.92000,0.23220,0.74220,0.01410
13.96000,0.23270,0.74600,0.01410
14.00000,0.23320,0.75000,0.01430
14.04000,0.23380,0.75420,0.01430
14.08000,0.23470,0.76010,0.01450
14.12000,0.23550,0.76730,0.01460
14.16000,0.23620,0.77370,0.01470
14.20000,0.23690,0.77880,0.01490
14.24000,0.23740,0.78340,0.01490
14.28000,0.23800,0.78680,0.01510
14.32000,0.23860,0.79100,0.01510
14.36000,0.23930,0.79600,0.01520
14.40000,0.24020,0.80300,0.01540
14.44000,0.24100,0.81050,0.01560
14.48000,0.24160,0.81560,0.01560
14.52000,0.24210,0.82010,0.01580
14.56000,0.24270,0.82440,0.01580
14.60000,0.24330,0.82820,0.01590
14.64000,0.24390,0.83240,0.01600
14.68000,0.24460,0.83770,0.01610
14.72000,0.24550,0.84470,0.01620
14.76000,0.24630,0.85170,0.01640
14.80000,0.24690,0.85760,0.01650
14.84000,0.24750,0.86210,0.01660
14.88000,0.24800,0.86620,0.01670
14.92000,0.24860,0.87010,0.01680
14.96000,0.24930,0.87500,0.01690
15.00000,0.25010,0.88140,0.01710
15.04000,0.25090,0.88870,0.01720
15.08000,0.25160,0.89470,0.01730
15.12000,0.25220,0.89960,0.01740
15.16000,0.25270,0.90410,0.01750
15.20000,0.25330,0.90810,0.01760
15.24000,0.25380,0.91210,0.01770
15.28000,0.25460,0.91680,0.01780
15.32000,0.25540,0.92370,0.01790
15.36000,0.25620,0.93120,0.01810
15.40000,0.25690,0.93760,0.01820
15.44000,0.25750,0.94280,0.01830
15.48000,0.25810,0.94690,0.01840
15.52000,0.25860,0.95080,0.01850
15.56000,0.25920,0.95490,0.01860
15.60000,0.26000,0.96050,0.01870
15.64000,0.26080,0.96800,0.01880
15.68000,0.26160,0.97460,0.01900
15.72000,0.26220,0.98010,0.01920
15.76000,0.26280,0.98490,0.01930
15.80000,0.26340,0.98920,0.01930
15.84000,0.26390,0.99350,0.01950
15.88000,0.26460,0.99820,0.01950
15.92000,0.26540,1.00480,0.01970
15.96000,0.26620,1.01230,0.01990
16.00000,0.26700,1.01900,0.02000
16.04000,0.26750,1.02430,0.02010
16.08000,0.26810,1.02830,0.02020
16.12000,0.26860,1.03220,0.02030
16.16000,0.26920,1.03620,0.02040
16.20000,0.26990,1.04180,0.02050
16.24000,0.27090,1.04930,0.02070
16.28000,0.27160,1.05680,0.02080
16.32000,0.27220,1.06270,0.02090
16.36000,0.27280,1.06800,0.02100
16.40000,0.27340,1.07250,0.02110
16.44000,0.27400,1.07660,0.02120
16.48000,0.27460,1.08100,0.02130
16.52000,0.27540,1.08710,0.02140
16.56000,0.27620,1.09500,0.02160
16.60000,0.27700,1.10180,0.02180
16.64000,0.27760,1.10740,0.02200
16.68000,0.27810,1.11200,0.02200
16.72000,0.27860,1.11630,0.02210
16.76000,0.27920,1.12050,0.02220
16.80000,0.27990,1.12570,0.02230
16.84000,0.28080,1.13300,0.02240
16.88000,0.28160,1.14150,0.02260
16.92000,0.28230,1.14830,0.02280
16.96000,0.28290,1.15380,0.02290
17.00000,0.28340,1.15920,0.02310
17.04000,0.28400,1.16390,0.02310
17.08000,0.28460,1.16860,0.02320
17.12000,0.28530,1.17460,0.02340
17.16000,0.28610,1.18240,0.02350
17.20000,0.28690,1.19050,0.02370
17.24000,0.28760,1.19750,0.02390
17.28000,0.28820,1.20300,0.02400
17.32000,0.28870,1.20770,0.02400
17.36000,0.28920,1.21230,0.02420
17.40000,0.28990,1.21730,0.02430
17.44000,0.29070,1.22450,0.02440
17.48000,0.29160,1.23350,0.02460
17.52000,0.29230,1.24090,0.02480
17.56000,0.29290,1.24720,0.02490
17.60000,0.29350,1.25270,0.02500
17.64000,0.29400,1.25740,0.02510
17.68000,0.29450,1.26230,0.02520
17.72000,0.29520,1.26740,0.02530
17.76000,0.29600,1.27450,0.02550
17.80000,0.29680,1.28300,0.02570
17.84000,0.29750,1.29050,0.02580
17.88000,0.29820,1.29660,0.02590
17.92000,0.29870,1.30180,0.02610
17.96000,0.29920,1.30680,0.02620
18.00000,0.29980,1.31170,0.02620
18.04000,0.30060,1.31820,0.02640
18.08000,0.30160,1.32710,0.02650
18.12000,0.30230,1.33530,0.02680
18.16000,0.30290,1.34120,0.02680
18.20000,0.30350,1.34640,0.02700
18.24000,0.30400,1.35130,0.02710
18.28000,0.30460,1.35620,0.02720
18.32000,0.30520,1.36130,0.02730
18.36000,0.30600,1.36850,0.02740
18.40000,0.30690,1.37720,0.02760
18.44000,0.30760,1.38520,0.02780
18.48000,0.30820,1.39180,0.02790
18.52000,0.30880,1.39710,0.02800
18.56000,0.30930,1.40210,0.02810
18.60000,0.30990,1.40670,0.02820
18.64000,0.31060,1.41260,0.02840
18.68000,0.31150,1.42110,0.02850
18.72000,0.31230,1.43000,0.02870
18.76000,0.31290,1.43630,0.02880
18.80000,0.31350,1.44210,0.02900
18.84000,0.31400,1.44750,0.02910
18.88000,0.31460,1.45250,0.02910
18.92000,0.31520,1.45750,0.02930
18.96000,0.31600,1.46410,0.02940
19.00000,0.31680,1.47260,0.02960
19.04000,0.31760,1.48090,0.02980
19.08000,0.31830,1.48840,0.02990
19.12000,0.31890,1.49430,0.03010
19.16000,0.31940,1.49920,0.03010
19.20000,0.31990,1.50410,0.03020
19.24000,0.32060,1.50950,0.03040
19.28000,0.32140,1.51670,0.03050
19.32000,0.32220,1.52570,0.03070
19.36000,0.32290,1.53330,0.03090
19.40000,0.32350,1.53950,0.03100
19.44000,0.32410,1.54520,0.03110
19.48000,0.32460,1.55070,0.03130
19.52000,0.32520,1.55580,0.03130
19.56000,0.32590,1.56160,0.03150
19.60000,0.32680,1.56960,0.03170
19.64000,0.32760,1.57850,0.03190
19.68000,0.32830,1.58620,0.03200
19.72000,0.32890,1.59240,0.03210
19.76000,0.32940,1.59750,0.03230
19.80000,0.32990,1.60210,0.03230
19.84000,0.33050,1.60690,0.03240
19.88000,0.33130,1.61390,0.03260
19.92000,0.33220,1.62300,0.03280
19.96000,0.33290,1.63160,0.03300
20.00000,0.33350,1.63820,0.03310
20.04000,0.33420,1.64420,0.03330
20.08000,0.33470,1.64970,0.03340
20.12000,0.33520,1.65470,0.03340
20.16000,0.33590,1.65980,0.03360
20.20000,0.33670,1.66690,0.03380
20.24000,0.33760,1.67620,0.03400
20.28000,0.33830,1.68470,0.03420
20.32000,0.33890,1.69160,0.03430
20.36000,0.33940,1.69690,0.03440
20.40000,0.33990,1.70180,0.03450
20.44000,0.34050,1.70660,0.03460
20.48000,0.34120,1.71260,0.03470
20.52000,0.34210,1.72120,0.03500
20.56000,0.34290,1.73010,0.03520
20.60000,0.34360,1.73750,0.03530
20.64000,0.34410,1.74370,0.03550
20.68000,0.34470,1.74970,0.03560
20.72000,0.34530,1.75500,0.03570
20.76000,0.34590,1.76000,0.03580
20.80000,0.34660,1.76670,0.03590
20.84000,0.34750,1.77570,0.03620
20.88000,0.34820,1.78410,0.03640
20.92000,0.34890,1.79080,0.03650
20.96000,0.34940,1.79700,0.03660
21.00000,0.35000,1.80240,0.03670
21.04000,0.35050,1.80760,0.03680
21.08000,0.35120,1.81320,0.03700
21.12000,0.35210,1.82100,0.03720
21.16000,0.35290,1.83070,0.03740
21.20000,0.35360,1.83880,0.03760
21.24000,0.35430,1.84510,0.03770
21.28000,0.35480,1.85110,0.03790
21.32000,0.35530,1.85650,0.03800
21.36000,0.35590,1.86170,0.03810
21.40000,0.35660,1.86780,0.03830
21.44000,0.35740,1.87580,0.03850
21.48000,0.35820,1.88520,0.03870
21.52000,0.35890,1.89300,0.03880
21.56000,0.35950,1.89970,0.03900
21.60000,0.36010,1.90530,0.03910
21.64000,0.36060,1.91030,0.03920
21.68000,0.36120,1.91570,0.03930
21.72000,0.36200,1.92320,0.03950
21.76000,0.36290,1.93310,0.03980
21.80000,0.36360,1.94190,0.04000
21.84000,0.36430,1.94880,0.04010
21.88000,0.36490,1.95520,0.04020
21.92000,0.36540,1.96050,0.04040
21.96000,0.36590,1.96520,0.04050
22.00000,0.36650,1.97090,0.04060
22.04000,0.36730,1.97840,0.04080
22.08000,0.36820,1.98770,0.04100
22.12000,0.36890,1.99670,0.04120
22.16000,0.36950,2.00430,0.04140
22.20000,0.37010,2.01020,0.04150
22.24000,0.37060,2.01550,0.04160
22.28000,0.37120,2.02060,0.04170
22.32000,0.37190,2.02730,0.04190
22.36000,0.37290,2.03640,0.04210
22.40000,0.37370,2.04610,0.04240
22.44000,0.37420,2.05340,0.04250
22.48000,0.37490,2.05920,0.04270
22.52000,0.37540,2.06540,0.04280
22.56000,0.37590,2.07040,0.04290
22.60000,0.37650,2.07600,0.04310
22.64000,0.37720,2.08290,0.04320
22.68000,0.37820,2.09220,0.04340
22.72000,0.37890,2.10150,0.04370
22.76000,0.37960,2.10890,0.04380
22.80000,0.38010,2.11560,0.04400
22.84000,0.38070,2.12120,0.04410
22.88000,0.38120,2.12600,0.04420
22.92000,0.38190,2.13220,0.04440
22.96000,0.38280,2.14100,0.04460
23.00000,0.38360,2.15070,0.04480
23.04000,0.38420,2.15840,0.04500
23.08000,0.38490,2.16440,0.04520
23.12000,0.38540,2.17070,0.04530
23.16000,0.38590,2.17620,0.04530
23.20000,0.38650,2.18170,0.04560
23.24000,0.38720,2.18840,0.04570
23.28000,0.38810,2.19690,0.04590
23.32000,0.38890,2.20670,0.04620
23.36000,0.38960,2.21490,0.04640
23.40000,0.39020,2.22180,0.04640
23.44000,0.39070,2.22760,0.04670
23.48000,0.39120,2.23260,0.04680
23.52000,0.39190,2.23800,0.04690
23.56000,0.39270,2.24630,0.04710
23.60000,0.39350,2.25610,0.04730
23.64000,0.39420,2.26450,0.04750
23.68000,0.39490,2.27120,0.04770
23.72000,0.39550,2.27750,0.04780
23.76000,0.39600,2.28330,0.04790
23.80000,0.39650,2.28890,0.04810
23.84000,0.39720,2.29480,0.04820
23.88000,0.39800,2.30290,0.04840
23.92000,0.39890,2.31350,0.04870
23.96000,0.39960,2.32230,0.04890
24.00000,0.40020,2.32940,0.04900
24.04000,0.40080,2.33550,0.04920
24.08000,0.40130,2.34060,0.04930
24.12000,0.40180,2.34580,0.04940
24.16000,0.40260,2.35250,0.04960
24.20000,0.40350,2.36200,0.04980
24.24000,0.40420,2.37200,0.05000
24.28000,0.40490,2.37940,0.05020
24.32000,0.40550,2.38600,0.05030
24.36000,0.40600,2.39210,0.05050
24.40000,0.40660,2.39780,0.05070
24.44000,0.40720,2.40340,0.05080
24.48000,0.40800,2.41090,0.05100
24.52000,0.40890,2.42090,0.05120
24.56000,0.40970,2.43090,0.05150
24.60000,0.41020,2.43800,0.05160
24.64000,0.41080,2.44390,0.05180
24.68000,0.41130,2.44930,0.05190
24.72000,0.41190,2.45460,0.05200
24.76000,0.41260,2.46140,0.05220
24.80000,0.41350,2.47040,0.05240
24.84000,0.41430,2.48050,0.05260
24.88000,0.41490,2.48860,0.05290
24.92000,0.41560,2.49550,0.05300
24.96000,0.41610,2.50190,0.05310
25.00000,0.41660,2.50740,0.05330
25.04000,0.41720,2.51320,0.05340
25.08000,0.41800,2.51990,0.05360
25.12000,0.41880,2.52900,0.05380
25.16000,0.41960,2.53910,0.05400
25.20000,0.42020,2.54670,0.05420
25.24000,0.42080,2.55310,0.05440
25.28000,0.42130,2.55910,0.05450
25.32000,0.42190,2.56450,0.05460
25.36000,0.42250,2.57040,0.05480
25.40000,0.42340,2.57880,0.05500
25.44000,0.42420,2.58900,0.05520
25.48000,0.42490,2.59760,0.05550
25.52000,0.42560,2.60480,0.05560
25.56000,0.42620,2.61100,0.05570
25.60000,0.42670,2.61690,0.05590
25.64000,0.42720,2.62280,0.05600
25.68000,0.42790,2.62890,0.05620
25.72000,0.42870,2.63720,0.05640
25.76000,0.42950,2.64720,0.05660
25.80000,0.43020,2.65610,0.05680
25.84000,0.43080,2.66260,0.05700
25.88000,0.43140,2.66870,0.05710
25.92000,0.43190,2.67430,0.05720
25.96000,0.43250,2.67990,0.05740
26.00000,0.43330,2.68720,0.05760
26.04000,0.43420,2.69740,0.05780
26.08000,0.43490,2.70750,0.05810
26.12000,0.43560,2.71530,0.05820
26.16000,0.43620,2.72170,0.05840
26.20000,0.43670,2.72750,0.05860
26.24000,0.43720,2.73300,0.05860
26.28000,0.43780,2.73870,0.05880
26.32000,0.43860,2.74630,0.05900
26.36000,0.43950,2.75630,0.05920
26.40000,0.44020,2.76630,0.05950
26.44000,0.44090,2.77370,0.05960
26.48000,0.44150,2.78020,0.05980
26.52000,0.44200,2.78600,0.05990
26.56000,0.44250,2.79140,0.06010
26.60000,0.44320,2.79810,0.06020
26.64000,0.44420,2.80770,0.06050
26.68000,0.44500,2.81830,0.06070
26.72000,0.44560,2.82640,0.06090
26.76000,0.44620,2.83310,0.06100
26.80000,0.44670,2.83890,0.06120
26.84000,0.44730,2.84460,0.06130
26.88000,0.44790,2.85040,0.06150
26.92000,0.44860,2.85770,0.06170
26.96000,0.44950,2.86730,0.06190
27.00000,0.45030,2.87740,0.06220
27.04000,0.45090,2.88580,0.06240
27.08000,0.45150,2.89260,0.06250
27.12000,0.45200,2.89840,0.06270
27.16000,0.45260,2.90390,0.06280
27.20000,0.45330,2.91010,0.06290
27.24000,0.45410,2.91910,0.06310
27.28000,0.45490,2.92990,0.06340
27.32000,0.45560,2.93860,0.06350
27.36000,0.45620,2.94550,0.06370
27.40000,0.45670,2.95190,0.06390
27.44000,0.45730,2.95770,0.06400
27.48000,0.45790,2.96350,0.06420
27.52000,0.45860,2.97000,0.06440
27.56000,0.45940,2.97910,0.06450
27.60000,0.46020,2.98970,0.06480
27.64000,0.46090,2.99880,0.06500
27.68000,0.46160,3.00590,0.06520
27.72000,0.46210,3.01210,0.06540
27.76000,0.46260,3.01790,0.06550
27.80000,0.46320,3.02400,0.06560
27.84000,0.46400,3.03140,0.06580
27.88000,0.46480,3.04140,0.06600
27.92000,0.46550,3.05050,0.06620
27.96000,0.46620,3.05840,0.06650
28.00000,0.46680,3.06580,0.06660
28.04000,0.46740,3.07200,0.06680
28.08000,0.46790,3.07760,0.06690
28.12000,0.46850,3.08370,0.06710
28.16000,0.46930,3.09180,0.06720
28.20000,0.47020,3.10230,0.06750
28.24000,0.47090,3.11170,0.06770
28.28000,0.47160,3.12010,0.06790
28.32000,0.47210,3.12640,0.06810
28.36000,0.47260,3.13180,0.06820
28.40000,0.47320,3.13730,0.06840
28.44000,0.47390,3.14400,0.06850
28.48000,0.47480,3.15380,0.06870
28.52000,0.47560,3.16390,0.06890
28.56000,0.47620,3.17200,0.06920
28.60000,0.47680,3.17920,0.06930
28.64000,0.47740,3.18580,0.06950
28.68000,0.47790,3.19190,0.06970
28.72000,0.47850,3.19810,0.06980
28.76000,0.47930,3.20540,0.07000
28.80000,0.48020,3.21550,0.07030
28.84000,0.48100,3.22540,0.07050
28.88000,0.48160,3.23360,0.07060
28.92000,0.48210,3.23980,0.07090
28.96000,0.48260,3.24580,0.07090
29.00000,0.48320,3.25160,0.07110
29.04000,0.48390,3.25790,0.07130
29.08000,0.48470,3.26690,0.07150
29.12000,0.48560,3.27770,0.07170
29.16000,0.48620,3.28630,0.07200
29.20000,0.48690,3.29350,0.07210
29.24000,0.48740,3.30030,0.07230
29.28000,0.48800,3.30630,0.07240
29.32000,0.48860,3.31270,0.07250
29.36000,0.48930,3.31940,0.07270
29.40000,0.49010,3.32930,0.07300
29.44000,0.49090,3.33880,0.07320
29.48000,0.49160,3.34710,0.07340
29.52000,0.49220,3.35430,0.07360
29.56000,0.49270,3.36050,0.07370
29.60000,0.49320,3.36640,0.07390
29.64000,0.49390,3.37260,0.07410
29.68000,0.49470,3.38080,0.07420
29.72000,0.49560,3.39160,0.07450
29.76000,0.49620,3.40120,0.07470
29.80000,0.49690,3.40850,0.07490
29.84000,0.49750,3.41520,0.07500
29.88000,0.49810,3.42150,0.07520
29.92000,0.49860,3.42760,0.07530
29.96000,0.49920,3.43380,0.07550
30.00000,0.50000,3.44240,0.07570
30.04000,0.50080,3.45270,0.07590
30.08000,0.50160,3.46200,0.07620
30.12000,0.50220,3.46950,0.07630
30.16000,0.50280,3.47610,0.07650
30.20000,0.50320,3.48150,0.07660
30.24000,0.50380,3.48720,0.07680
30.28000,0.50460,3.49490,0.07690
30.30200,0.50510,3.50040,0.07710