File: Modulus_Al_5.csv
Time,Displacement,Force,Strain 1
(s),(mm),(kN),(%)
0.000000,71.946700,0.001800,0.000000
0.040000,71.946800,0.001800,0.000100
0.080000,71.947200,0.002000,0.000100
0.120000,71.948000,0.002500,0.000200
0.160000,71.949100,0.003000,0.000300
0.200000,71.950000,0.003300,0.000400
0.240000,71.950800,0.003800,0.000400
0.280000,71.951300,0.004100,0.000500
0.320000,71.951900,0.004200,0.000500
0.360000,71.952500,0.004700,0.000500
0.400000,71.953300,0.005100,0.000600
0.440000,71.954100,0.005600,0.000700
0.480000,71.954900,0.006000,0.000700
0.520000,71.955500,0.006500,0.000700
0.560000,71.956100,0.006800,0.000800
0.600000,71.956600,0.007100,0.000800
0.640000,71.957200,0.007400,0.000900
0.680000,71.957900,0.007700,0.000900
0.720000,71.958800,0.008200,0.001000
0.760000,71.959600,0.008700,0.001100
0.800000,71.960300,0.008900,0.001100
0.840000,71.960900,0.009200,0.001100
0.880000,71.961400,0.009300,0.001200
0.920000,71.961900,0.009600,0.001200
0.960000,71.962500,0.009600,0.001200
1.000000,71.963200,0.010000,0.001200
1.040000,71.964100,0.010600,0.001300
1.080000,71.964800,0.011000,0.001300
1.120000,71.965500,0.011200,0.001300
1.160000,71.966100,0.011200,0.001200
1.200000,71.966700,0.011600,0.001300
1.240000,71.967200,0.012100,0.001400
1.280000,71.967900,0.012400,0.001400
1.320000,71.968800,0.013000,0.001500
1.360000,71.969600,0.013900,0.001600
1.400000,71.970300,0.014200,0.001600
1.440000,71.970800,0.014600,0.001700
1.480000,71.971400,0.015000,0.001800
1.520000,71.972000,0.015400,0.001800
1.560000,71.972600,0.015800,0.001900
1.600000,71.973200,0.016200,0.001900
1.640000,71.974100,0.017100,0.002000
1.680000,71.974900,0.018000,0.002200
1.720000,71.975600,0.018300,0.002200
1.760000,71.976200,0.018800,0.002300
1.800000,71.976700,0.019200,0.002300
1.840000,71.977300,0.019700,0.002400
1.880000,71.977900,0.020100,0.002500
1.920000,71.978700,0.020800,0.002500
1.960000,71.979600,0.021600,0.002600
2.000000,71.980200,0.022100,0.002700
2.040000,71.980900,0.022600,0.002800
2.080000,71.981500,0.022800,0.002800
2.120000,71.982000,0.023400,0.002800
2.160000,71.982600,0.023500,0.002900
2.200000,71.983200,0.023800,0.002900
2.240000,71.984000,0.024300,0.003000
2.280000,71.984900,0.025300,0.003100
2.320000,71.985600,0.025600,0.003100
2.360000,71.986300,0.025800,0.003200
2.400000,71.986900,0.025900,0.003200
2.440000,71.987300,0.025900,0.003100
2.480000,71.987900,0.026100,0.003200
2.520000,71.988600,0.026500,0.003200
2.560000,71.989500,0.027100,0.003300
2.600000,71.990200,0.027800,0.003400
2.640000,71.990900,0.028300,0.003400
2.680000,71.991500,0.028400,0.003400
2.720000,71.992100,0.028500,0.003400
2.760000,71.992600,0.028800,0.003400
2.800000,71.993200,0.028900,0.003500
2.840000,71.994000,0.029500,0.003500
2.880000,71.994900,0.030100,0.003600
2.920000,71.995600,0.030500,0.003600
2.960000,71.996300,0.030600,0.003600
3.000000,71.996800,0.030400,0.003600
3.040000,71.997400,0.030200,0.003600
3.080000,71.997900,0.030300,0.003600
3.120000,71.998500,0.030500,0.003600
3.160000,71.999400,0.030900,0.003600
3.200000,72.000300,0.031600,0.003700
3.240000,72.000900,0.031600,0.003800
3.280000,72.001500,0.031500,0.003700
3.320000,72.002100,0.031500,0.003700
3.360000,72.002700,0.031500,0.003700
3.400000,72.003300,0.031400,0.003700
3.440000,72.004000,0.031700,0.003700
3.480000,72.004900,0.032200,0.003800
3.520000,72.005600,0.032900,0.003900
3.560000,72.006300,0.033100,0.003900
3.600000,72.006800,0.032900,0.003900
3.640000,72.007400,0.033200,0.003900
3.680000,72.007900,0.033300,0.003900
3.720000,72.008500,0.033300,0.003900
3.760000,72.009300,0.033900,0.004000
3.800000,72.010200,0.034400,0.004100
3.840000,72.011000,0.034900,0.004100
3.880000,72.011600,0.035000,0.004100
3.920000,72.012100,0.035000,0.004100
3.960000,72.012700,0.034900,0.004100
4.000000,72.013300,0.035000,0.004100
4.040000,72.013900,0.035100,0.004100
4.080000,72.014800,0.035900,0.004200
4.120000,72.015600,0.036600,0.004300
4.160000,72.016200,0.036800,0.004300
4.200000,72.016900,0.036900,0.004300
4.240000,72.017500,0.036800,0.004300
4.280000,72.017900,0.037100,0.004300
4.320000,72.018500,0.037200,0.004300
4.360000,72.019300,0.037500,0.004400
4.400000,72.020200,0.038300,0.004400
4.440000,72.021000,0.038800,0.004600
4.480000,72.021600,0.038900,0.004500
4.520000,72.022200,0.039000,0.004500
4.560000,72.022800,0.039200,0.004600
4.600000,72.023300,0.039300,0.004600
4.640000,72.023900,0.039300,0.004600
4.680000,72.024600,0.039700,0.004700
4.720000,72.025500,0.040400,0.004700
4.760000,72.026200,0.040900,0.004800
4.800000,72.026900,0.040800,0.004800
4.840000,72.027500,0.040700,0.004800
4.880000,72.028000,0.040800,0.004800
4.920000,72.028500,0.040900,0.004800
4.960000,72.029300,0.041200,0.004800
5.000000,72.030200,0.041700,0.004900
5.040000,72.031000,0.042300,0.005000
5.080000,72.031600,0.042400,0.005000
5.120000,72.032200,0.042000,0.005000
5.160000,72.032800,0.042000,0.005000
5.200000,72.033300,0.041700,0.004900
5.240000,72.033800,0.041600,0.005000
5.280000,72.034600,0.042100,0.005000
5.320000,72.035500,0.042700,0.005100
5.360000,72.036300,0.043100,0.005100
5.400000,72.036900,0.043000,0.005100
5.440000,72.037500,0.042900,0.005100
5.480000,72.038100,0.042800,0.005100
5.520000,72.038600,0.042700,0.005000
5.560000,72.039300,0.042800,0.005100
5.600000,72.040100,0.043600,0.005200
5.640000,72.041000,0.044500,0.005300
5.680000,72.041600,0.044700,0.005300
5.720000,72.042200,0.044800,0.005300
5.760000,72.042800,0.044700,0.005300
5.800000,72.043300,0.044900,0.005300
5.840000,72.043900,0.044800,0.005300
5.880000,72.044600,0.045000,0.005300
5.920000,72.045400,0.045400,0.005400
5.960000,72.046300,0.046100,0.005500
6.000000,72.047000,0.046300,0.005500
6.040000,72.047600,0.046000,0.005500
6.080000,72.048100,0.045900,0.005500
6.120000,72.048600,0.045700,0.005500
6.160000,72.049200,0.045700,0.005500
6.200000,72.050000,0.046100,0.005500
6.240000,72.050900,0.046800,0.005600
6.280000,72.051600,0.047300,0.005700
6.320000,72.052200,0.047300,0.005700
6.360000,72.052800,0.047200,0.005700
6.400000,72.053400,0.047000,0.005700
6.440000,72.053900,0.046800,0.005600
6.480000,72.054500,0.046800,0.005600
6.520000,72.055300,0.047200,0.005700
6.560000,72.056200,0.048200,0.005800
6.600000,72.056900,0.048500,0.005800
6.640000,72.057600,0.048400,0.005800
6.680000,72.058200,0.048000,0.005800
6.720000,72.058700,0.047800,0.005800
6.760000,72.059200,0.047600,0.005700
6.800000,72.059900,0.048000,0.005800
6.840000,72.060800,0.048800,0.005900
6.880000,72.061600,0.049400,0.005900
6.920000,72.062200,0.049600,0.006000
6.960000,72.062900,0.049600,0.006000
7.000000,72.063500,0.049400,0.006000
7.040000,72.064000,0.049500,0.006000
7.080000,72.064500,0.049500,0.006000
7.120000,72.065300,0.049600,0.006000
7.160000,72.066200,0.050400,0.006100
7.200000,72.066900,0.050900,0.006200
7.240000,72.067600,0.050900,0.006200
7.280000,72.068200,0.050800,0.006200
7.320000,72.068700,0.050400,0.006100
7.360000,72.069200,0.050400,0.006100
7.400000,72.069800,0.050100,0.006100
7.440000,72.070700,0.050600,0.006200
7.480000,72.071600,0.051300,0.006200
7.520000,72.072300,0.051400,0.006200
7.560000,72.072900,0.051000,0.006200
7.600000,72.073500,0.050900,0.006200
7.640000,72.074100,0.050900,0.006200
7.680000,72.074600,0.050800,0.006200
7.720000,72.075300,0.050900,0.006200
7.760000,72.076100,0.051500,0.006300
7.800000,72.077000,0.052200,0.006300
7.840000,72.077600,0.052400,0.006400
7.880000,72.078200,0.052100,0.006400
7.920000,72.078700,0.052100,0.006300
7.960000,72.079300,0.052100,0.006300
8.000000,72.079900,0.052000,0.006300
8.040000,72.080600,0.052200,0.006400
8.080000,72.081500,0.053100,0.006500
8.120000,72.082300,0.053700,0.006500
8.160000,72.082900,0.053700,0.006500
8.200000,72.083600,0.053500,0.006500
8.240000,72.084100,0.053300,0.006500
8.280000,72.084600,0.053200,0.006500
8.320000,72.085200,0.053100,0.006500
8.360000,72.086000,0.053600,0.006600
8.400000,72.086900,0.054400,0.006700
8.440000,72.087600,0.054900,0.006700
8.480000,72.088200,0.054800,0.006700
8.520000,72.088800,0.054800,0.006700
8.560000,72.089300,0.054700,0.006700
8.600000,72.089900,0.054500,0.006700
8.640000,72.090600,0.054800,0.006800
8.680000,72.091500,0.055500,0.006800
8.720000,72.092300,0.056200,0.006900
8.760000,72.092900,0.056300,0.006900
8.800000,72.093600,0.056100,0.006900
8.840000,72.094100,0.056100,0.006900
8.880000,72.094700,0.055800,0.006900
8.920000,72.095200,0.055900,0.006900
8.960000,72.095900,0.056100,0.006900
9.000000,72.096800,0.056700,0.007000
9.040000,72.097500,0.057600,0.007100
9.080000,72.098200,0.057900,0.007100
9.120000,72.098800,0.057700,0.007100
9.160000,72.099400,0.057500,0.007100
9.200000,72.099900,0.057500,0.007100
9.240000,72.100500,0.057500,0.007100
9.280000,72.101400,0.058400,0.007200
9.320000,72.102300,0.060400,0.007200
9.360000,72.103000,0.062400,0.007200
9.400000,72.103600,0.064100,0.007200
9.440000,72.104100,0.065800,0.007200
9.480000,72.104700,0.067200,0.007200
9.520000,72.105200,0.068800,0.007300
9.560000,72.105800,0.070500,0.007400
9.600000,72.106700,0.073100,0.007500
9.640000,72.107600,0.076000,0.007600
9.680000,72.108300,0.078700,0.007800
9.720000,72.108900,0.080800,0.007800
9.760000,72.109400,0.082600,0.007900
9.800000,72.110000,0.084300,0.008000
9.840000,72.110600,0.085700,0.008000
9.880000,72.111400,0.087900,0.008200
9.920000,72.112300,0.091000,0.008300
9.960000,72.113000,0.093700,0.008400
10.000000,72.113600,0.095400,0.008500
10.040000,72.114200,0.097100,0.008600
10.080000,72.114700,0.098800,0.008600
10.120000,72.115200,0.100600,0.008700
10.160000,72.115900,0.102100,0.008900
10.200000,72.116700,0.104400,0.009000
10.240000,72.117600,0.107400,0.009200
10.280000,72.118300,0.110300,0.009300
10.320000,72.118900,0.112500,0.009500
10.360000,72.119500,0.114300,0.009600
10.400000,72.120000,0.115800,0.009700
10.440000,72.120600,0.117500,0.009800
10.480000,72.121300,0.119600,0.009900
10.520000,72.122200,0.122500,0.010100
10.560000,72.122900,0.125500,0.010300
10.600000,72.123600,0.127600,0.010500
10.640000,72.124200,0.129600,0.010600
10.680000,72.124800,0.131600,0.010700
10.720000,72.125300,0.133400,0.010800
10.760000,72.125900,0.135200,0.011000
10.800000,72.126600,0.137300,0.011100
10.840000,72.127500,0.140300,0.011300
10.880000,72.128300,0.143500,0.011500
10.920000,72.128900,0.145700,0.011700
10.960000,72.129500,0.147400,0.011800
11.000000,72.130100,0.149300,0.011900
11.040000,72.130600,0.151100,0.012000
11.080000,72.131200,0.152800,0.012100
11.120000,72.132100,0.155400,0.012300
11.160000,72.132900,0.158800,0.012600
11.200000,72.133600,0.161500,0.012700
11.240000,72.134200,0.163200,0.012900
11.280000,72.134800,0.165200,0.013100
11.320000,72.135300,0.167100,0.013200
11.360000,72.135800,0.169000,0.013300
11.400000,72.136500,0.170800,0.013400
11.440000,72.137500,0.173600,0.013600
11.480000,72.138300,0.177100,0.013900
11.520000,72.139000,0.179800,0.014100
11.560000,72.139500,0.181600,0.014200
11.600000,72.140100,0.183200,0.014300
11.640000,72.140600,0.184900,0.014500
11.680000,72.141200,0.186700,0.014600
11.720000,72.142000,0.189200,0.014800
11.760000,72.142900,0.192500,0.015000
11.800000,72.143600,0.195700,0.015300
11.840000,72.144300,0.197700,0.015500
11.880000,72.144800,0.199800,0.015500
11.920000,72.145300,0.201800,0.015700
11.960000,72.145900,0.203700,0.015800
12.000000,72.146600,0.205600,0.015900
12.040000,72.147400,0.208100,0.016200
12.080000,72.148300,0.211700,0.016400
12.120000,72.149000,0.214800,0.016600
12.160000,72.149500,0.216700,0.016800
12.200000,72.150100,0.218600,0.016900
12.240000,72.150600,0.220600,0.017100
12.280000,72.151200,0.222300,0.017200
12.320000,72.151900,0.224600,0.017400
12.360000,72.152900,0.228200,0.017600
12.400000,72.153600,0.231800,0.017900
12.440000,72.154300,0.234400,0.018100
12.480000,72.154900,0.236300,0.018200
12.520000,72.155500,0.238600,0.018400
12.560000,72.156000,0.240600,0.018500
12.600000,72.156600,0.242500,0.018700
12.640000,72.157300,0.244900,0.018900
12.680000,72.158200,0.248500,0.019100
12.720000,72.158900,0.252000,0.019300
12.760000,72.159500,0.254400,0.019500
12.800000,72.160100,0.256300,0.019700
12.840000,72.160600,0.258400,0.019800
12.880000,72.161200,0.260400,0.019900
12.920000,72.161900,0.262500,0.020100
12.960000,72.162800,0.265600,0.020400
13.000000,72.163700,0.269600,0.020600
13.040000,72.164300,0.272500,0.020800
13.080000,72.164900,0.274600,0.021000
13.120000,72.165500,0.276800,0.021200
13.160000,72.166000,0.278700,0.021300
13.200000,72.166500,0.280700,0.021500
13.240000,72.167200,0.283000,0.021600
13.280000,72.168100,0.286200,0.021900
13.320000,72.169000,0.289900,0.022100
13.360000,72.169600,0.292800,0.022400
13.400000,72.170200,0.295300,0.022500
13.440000,72.170700,0.297400,0.022700
13.480000,72.171300,0.299300,0.022900
13.520000,72.171900,0.301300,0.023000
13.560000,72.172700,0.304500,0.023200
13.600000,72.173600,0.308500,0.023500
13.640000,72.174400,0.311800,0.023700
13.680000,72.174900,0.314300,0.023900
13.720000,72.175500,0.316400,0.024000
13.760000,72.176000,0.318500,0.024200
13.800000,72.176600,0.320500,0.024400
13.840000,72.177200,0.322600,0.024500
13.880000,72.178000,0.325700,0.024800
13.920000,72.178900,0.329700,0.025000
13.960000,72.179600,0.333100,0.025300
14.000000,72.180200,0.335600,0.025500
14.040000,72.180800,0.337900,0.025600
14.080000,72.181300,0.339900,0.025800
14.120000,72.181900,0.341900,0.025900
14.160000,72.182700,0.344500,0.026100
14.200000,72.183600,0.348400,0.026400
14.240000,72.184300,0.352400,0.026700
14.280000,72.184900,0.354700,0.026900
14.320000,72.185500,0.356800,0.027100
14.360000,72.186000,0.359100,0.027200
14.400000,72.186600,0.361400,0.027400
14.440000,72.187200,0.363700,0.027600
14.480000,72.188000,0.366400,0.027800
14.520000,72.188800,0.370200,0.028100
14.560000,72.189600,0.374200,0.028300
14.600000,72.190200,0.377100,0.028500
14.640000,72.190800,0.379400,0.028700
14.680000,72.191300,0.381600,0.028900
14.720000,72.191900,0.383800,0.029000
14.760000,72.192600,0.386400,0.029200
14.800000,72.193500,0.389900,0.029500
14.840000,72.194200,0.393700,0.029700
14.880000,72.194900,0.396600,0.030000
14.920000,72.195500,0.399100,0.030200
14.960000,72.196100,0.401600,0.030400
15.000000,72.196600,0.404100,0.030500
15.040000,72.197200,0.406100,0.030700
15.080000,72.197900,0.408600,0.030800
15.120000,72.198800,0.412400,0.031200
15.160000,72.199600,0.416400,0.031500
15.200000,72.200300,0.419500,0.031700
15.240000,72.200900,0.422300,0.031800
15.280000,72.201400,0.424300,0.032000
15.320000,72.202000,0.426300,0.032200
15.360000,72.202500,0.428600,0.032400
15.400000,72.203400,0.431900,0.032600
15.440000,72.204300,0.436100,0.032900
15.480000,72.204900,0.439700,0.033100
15.520000,72.205500,0.442400,0.033300
15.560000,72.206100,0.445100,0.033500
15.600000,72.206700,0.447500,0.033700
15.640000,72.207300,0.449900,0.033900
15.680000,72.207900,0.452300,0.034100
15.720000,72.208800,0.456200,0.034300
15.760000,72.209700,0.460300,0.034600
15.800000,72.210300,0.463700,0.034800
15.840000,72.210900,0.466200,0.035000
15.880000,72.211400,0.468700,0.035300
15.920000,72.211900,0.470700,0.035400
15.960000,72.212500,0.473100,0.035600
16.000000,72.213300,0.476100,0.035800
16.040000,72.214200,0.480100,0.036100
16.080000,72.214900,0.484400,0.036400
16.120000,72.215600,0.487200,0.036600
16.160000,72.216200,0.489900,0.036800
16.200000,72.216700,0.492400,0.037000
16.240000,72.217300,0.494900,0.037200
16.280000,72.217900,0.497200,0.037300
16.320000,72.218800,0.500400,0.037600
16.360000,72.219600,0.505100,0.037900
16.400000,72.220300,0.508800,0.038200
16.440000,72.220900,0.511400,0.038400
16.480000,72.221500,0.514000,0.038600
16.520000,72.222000,0.516200,0.038700
16.560000,72.222500,0.518400,0.038900
16.600000,72.223200,0.521200,0.039100
16.640000,72.224200,0.525200,0.039400
16.680000,72.225000,0.530000,0.039700
16.720000,72.225600,0.533100,0.039900
16.760000,72.226200,0.535700,0.040100
16.800000,72.226800,0.538500,0.040300
16.840000,72.227300,0.540700,0.040500
16.880000,72.227900,0.543300,0.040700
16.920000,72.228600,0.546400,0.040900
16.960000,72.229500,0.550500,0.041200
17.000000,72.230200,0.554700,0.041500
17.040000,72.230900,0.557800,0.041700
17.080000,72.231500,0.560400,0.041900
17.120000,72.232000,0.563100,0.042100
17.160000,72.232500,0.565300,0.042300
17.200000,72.233200,0.567900,0.042400
17.240000,72.234000,0.571700,0.042700
17.280000,72.234900,0.576500,0.043100
17.320000,72.235600,0.580100,0.043300
17.360000,72.236200,0.582700,0.043500
17.400000,72.236800,0.585500,0.043700
17.440000,72.237400,0.587900,0.043900
17.480000,72.237900,0.590200,0.044000
17.520000,72.238600,0.592900,0.044200
17.560000,72.239400,0.596800,0.044500
17.600000,72.240300,0.601400,0.044800
17.640000,72.240900,0.605000,0.045100
17.680000,72.241500,0.607600,0.045300
17.720000,72.242100,0.610200,0.045500
17.760000,72.242600,0.612900,0.045700
17.800000,72.243200,0.615400,0.045800
17.840000,72.244000,0.618900,0.046100
17.880000,72.245000,0.623600,0.046400
17.920000,72.245700,0.628100,0.046700
17.960000,72.246300,0.631000,0.046900
18.000000,72.246800,0.633600,0.047100
18.040000,72.247400,0.636000,0.047300
18.080000,72.247900,0.638400,0.047500
18.120000,72.248500,0.641200,0.047600
18.160000,72.249400,0.644900,0.047900
18.200000,72.250300,0.649800,0.048300
18.240000,72.251000,0.653800,0.048600
18.280000,72.251600,0.656800,0.048700
18.320000,72.252100,0.659100,0.048900
18.360000,72.252600,0.661600,0.049100
18.400000,72.253200,0.664300,0.049300
18.440000,72.254000,0.667500,0.049600
18.480000,72.254900,0.672000,0.049900
18.520000,72.255700,0.676800,0.050200
18.560000,72.256300,0.679900,0.050400
18.600000,72.256900,0.682500,0.050600
18.640000,72.257400,0.685300,0.050800
18.680000,72.257900,0.687800,0.051000
18.720000,72.258500,0.690400,0.051200
18.760000,72.259300,0.693900,0.051400
18.800000,72.260200,0.698500,0.051800
18.840000,72.261000,0.703200,0.052100
18.880000,72.261600,0.706300,0.052300
18.920000,72.262200,0.709200,0.052500
18.960000,72.262700,0.711800,0.052700
19.000000,72.263200,0.714100,0.052900
19.040000,72.263900,0.716900,0.053100
19.080000,72.264800,0.721000,0.053400
19.120000,72.265600,0.725800,0.053700
19.160000,72.266200,0.729500,0.054000
19.200000,72.266800,0.732100,0.054200
19.240000,72.267400,0.735100,0.054400
19.280000,72.268000,0.738000,0.054600
19.320000,72.268500,0.740700,0.054800
19.360000,72.269200,0.743700,0.055000
19.400000,72.270100,0.748100,0.055300
19.440000,72.271000,0.753300,0.055700
19.480000,72.271600,0.757000,0.056000
19.520000,72.272200,0.760100,0.056200
19.560000,72.272800,0.763200,0.056400
19.600000,72.273300,0.765700,0.056500
19.640000,72.273800,0.768200,0.056800
19.680000,72.274700,0.772200,0.057000
19.720000,72.275600,0.777300,0.057400
19.760000,72.276300,0.782000,0.057700
19.800000,72.276800,0.785400,0.057900
19.840000,72.277500,0.788800,0.058200
19.880000,72.278000,0.791900,0.058400
19.920000,72.278600,0.795000,0.058700
19.960000,72.279200,0.798000,0.058800
20.000000,72.280100,0.802500,0.059100
20.040000,72.280900,0.808000,0.059500
20.080000,72.281600,0.812800,0.059800
20.120000,72.282200,0.816800,0.060100
20.160000,72.282800,0.820100,0.060300
20.200000,72.283300,0.823200,0.060600
20.240000,72.283800,0.826300,0.060700
20.280000,72.284600,0.829900,0.061000
20.320000,72.285500,0.835500,0.061400
20.360000,72.286300,0.841400,0.061800
20.400000,72.286900,0.845900,0.062100
20.440000,72.287500,0.849400,0.062300
20.480000,72.288100,0.852900,0.062600
20.520000,72.288600,0.856400,0.062800
20.560000,72.289200,0.859800,0.063000
20.600000,72.290000,0.864100,0.063300
20.640000,72.290900,0.869600,0.063700
20.680000,72.291600,0.875400,0.064100
20.720000,72.292200,0.879200,0.064300
20.760000,72.292800,0.882800,0.064600
20.800000,72.293300,0.886100,0.064800
20.840000,72.293900,0.889400,0.065000
20.880000,72.294500,0.893000,0.065300
20.920000,72.295400,0.897800,0.065600
20.960000,72.296300,0.904200,0.066000
21.000000,72.296900,0.909000,0.066400
21.040000,72.297600,0.912700,0.066600
21.080000,72.298200,0.916500,0.066900
21.120000,72.298700,0.920000,0.067100
21.160000,72.299200,0.923500,0.067300
21.200000,72.299900,0.927200,0.067600
21.240000,72.300800,0.932400,0.067900
21.280000,72.301600,0.938000,0.068400
21.320000,72.302200,0.942800,0.068700
21.360000,72.302900,0.946900,0.068900
21.400000,72.303400,0.950600,0.069200
21.440000,72.303900,0.953800,0.069400
21.480000,72.304500,0.957000,0.069600
21.520000,72.305400,0.961500,0.069900
21.560000,72.306300,0.967900,0.070400
21.600000,72.307000,0.973200,0.070700
21.640000,72.307600,0.976800,0.070900
21.680000,72.308200,0.980900,0.071200
21.720000,72.308700,0.984500,0.071500
21.760000,72.309300,0.987800,0.071700
21.800000,72.309800,0.991000,0.071900
21.840000,72.310700,0.995900,0.072200
21.880000,72.311600,1.002200,0.072800
21.920000,72.312200,1.007300,0.073000
21.960000,72.312900,1.011500,0.073300
22.000000,72.313500,1.015100,0.073500
22.040000,72.314000,1.018600,0.073800
22.080000,72.314500,1.021600,0.073900
22.120000,72.315300,1.025700,0.074200
22.160000,72.316300,1.031700,0.074600
22.200000,72.317000,1.037700,0.075000
22.240000,72.317600,1.041700,0.075400
22.280000,72.318200,1.045400,0.075600
22.320000,72.318700,1.049100,0.075900
22.360000,72.319200,1.052400,0.076100
22.400000,72.319800,1.055500,0.076300
22.440000,72.320600,1.059800,0.076600
22.480000,72.321500,1.065800,0.077000
22.520000,72.322300,1.072000,0.077300
22.560000,72.322900,1.076500,0.077600
22.600000,72.323500,1.080200,0.077900
22.640000,72.324000,1.083700,0.078100
22.680000,72.324500,1.086600,0.078300
22.720000,72.325300,1.090400,0.078600
22.760000,72.326200,1.096200,0.079000
22.800000,72.327000,1.102300,0.079400
22.840000,72.327600,1.106700,0.079700
22.880000,72.328200,1.110300,0.080000
22.920000,72.328800,1.114200,0.080200
22.960000,72.329300,1.117600,0.080500
23.000000,72.329800,1.121100,0.080700
23.040000,72.330600,1.124700,0.081000
23.080000,72.331400,1.130000,0.081300
23.120000,72.332300,1.136600,0.081700
23.160000,72.332900,1.141500,0.082100
23.200000,72.333500,1.145400,0.082300
23.240000,72.334100,1.149100,0.082600
23.280000,72.334600,1.152000,0.082800
23.320000,72.335200,1.155600,0.083000
23.360000,72.336100,1.160600,0.083400
23.400000,72.337000,1.166900,0.083800
23.440000,72.337600,1.172000,0.084100
23.480000,72.338200,1.176000,0.084400
23.520000,72.338800,1.179900,0.084700
23.560000,72.339400,1.183300,0.084900
23.600000,72.339900,1.187000,0.085100
23.640000,72.340500,1.190700,0.085300
23.680000,72.341400,1.196000,0.085700
23.720000,72.342300,1.202100,0.086200
23.760000,72.343000,1.207700,0.086500
23.800000,72.343600,1.211700,0.086800
23.840000,72.344100,1.215400,0.087100
23.880000,72.344700,1.218800,0.087300
23.920000,72.345200,1.222300,0.087500
23.960000,72.345900,1.226100,0.087700
24.000000,72.346900,1.232100,0.088200
24.040000,72.347600,1.238300,0.088600
24.080000,72.348300,1.242800,0.088900
24.120000,72.348800,1.246900,0.089100
24.160000,72.349400,1.250400,0.089400
24.200000,72.349900,1.254100,0.089600
24.240000,72.350600,1.258000,0.089900
24.280000,72.351400,1.262400,0.090200
24.320000,72.352300,1.268600,0.090600
24.360000,72.353000,1.274600,0.091000
24.400000,72.353600,1.278800,0.091300
24.440000,72.354100,1.282200,0.091600
24.480000,72.354600,1.285400,0.091800
24.520000,72.355200,1.288600,0.092000
24.560000,72.355900,1.292800,0.092200
24.600000,72.356800,1.298500,0.092600
24.640000,72.357600,1.305100,0.093100
24.680000,72.358300,1.310200,0.093400
24.720000,72.358900,1.314000,0.093700
24.760000,72.359400,1.317700,0.093900
24.800000,72.359900,1.321100,0.094100
24.840000,72.360500,1.324800,0.094400
24.880000,72.361300,1.328800,0.094700
24.920000,72.362200,1.334500,0.095100
24.960000,72.363000,1.340800,0.095500
25.000000,72.363600,1.345500,0.095900
25.040000,72.364200,1.349100,0.096100
25.080000,72.364700,1.352500,0.096300
25.120000,72.365200,1.356100,0.096500
25.160000,72.365800,1.359500,0.096800
25.200000,72.366700,1.364700,0.097100
25.240000,72.367600,1.371400,0.097600
25.280000,72.368300,1.376900,0.097900
25.320000,72.368900,1.381300,0.098200
25.360000,72.369500,1.385100,0.098500
25.400000,72.370000,1.388500,0.098700
25.440000,72.370500,1.392100,0.099000
25.480000,72.371200,1.395700,0.099200
25.520000,72.372100,1.401000,0.099600
25.560000,72.372900,1.407300,0.100000
25.600000,72.373600,1.412500,0.100400
25.640000,72.374200,1.416600,0.100600
25.680000,72.374700,1.420100,0.100900
25.720000,72.375300,1.423700,0.101100
25.760000,72.375800,1.427100,0.101300
25.800000,72.376600,1.431500,0.101600
25.840000,72.377600,1.438200,0.102100
25.880000,72.378300,1.444300,0.102500
25.920000,72.379000,1.448800,0.102800
25.960000,72.379500,1.452700,0.103000
26.000000,72.380100,1.456600,0.103300
26.040000,72.380600,1.459800,0.103500
26.080000,72.381200,1.463400,0.103700
26.120000,72.382000,1.468100,0.104100
26.160000,72.382900,1.474400,0.104500
26.200000,72.383600,1.480300,0.104900
26.240000,72.384200,1.484800,0.105200
26.280000,72.384800,1.488700,0.105400
26.320000,72.385300,1.492200,0.105700
26.360000,72.385900,1.495600,0.106000
26.400000,72.386600,1.499600,0.106200
26.440000,72.387500,1.505800,0.106600
26.480000,72.388300,1.512200,0.107100
26.520000,72.389000,1.517300,0.107400
26.560000,72.389600,1.521100,0.107600
26.600000,72.390100,1.524800,0.107900
26.640000,72.390600,1.528200,0.108200
26.680000,72.391200,1.531700,0.108400
26.720000,72.391900,1.536000,0.108700
26.760000,72.392800,1.542200,0.109100
26.800000,72.393600,1.548500,0.109500
26.840000,72.394200,1.553100,0.109800
26.880000,72.394900,1.557400,0.110100
26.920000,72.395300,1.561000,0.110400
26.960000,72.395900,1.564300,0.110600
27.000000,72.396600,1.568100,0.110800
27.040000,72.397500,1.573400,0.111200
27.080000,72.398300,1.580500,0.111700
27.120000,72.398900,1.585600,0.112000
27.160000,72.399500,1.589300,0.112300
27.200000,72.400100,1.593500,0.112600
27.240000,72.400600,1.596800,0.112800
27.280000,72.401200,1.600400,0.113000
27.320000,72.401900,1.604400,0.113300
27.360000,72.402700,1.610000,0.113700
27.400000,72.403600,1.616700,0.114100
27.440000,72.404300,1.622300,0.114500
27.480000,72.404900,1.626500,0.114800
27.520000,72.405400,1.630200,0.115000
27.560000,72.406000,1.633500,0.115200
27.600000,72.406500,1.637100,0.115500
27.640000,72.407300,1.641800,0.115800
27.680000,72.408200,1.647800,0.116300
27.720000,72.408900,1.653400,0.116600
27.760000,72.409500,1.657700,0.116900
27.800000,72.410100,1.661900,0.117200
27.840000,72.410700,1.665700,0.117500
27.880000,72.411200,1.669500,0.117700
27.920000,72.411800,1.673100,0.117900
27.960000,72.412700,1.678000,0.118300
28.000000,72.413600,1.684600,0.118700
28.040000,72.414300,1.690800,0.119100
28.080000,72.414900,1.695500,0.119400
28.120000,72.415500,1.699400,0.119700
28.160000,72.416000,1.702700,0.119900
28.200000,72.416600,1.706000,0.120200
28.240000,72.417300,1.710400,0.120400
28.280000,72.418200,1.716100,0.120900
28.320000,72.418900,1.722300,0.121300
28.360000,72.419600,1.727100,0.121600
28.400000,72.420200,1.731600,0.121900
28.440000,72.420700,1.735600,0.122200
28.480000,72.421300,1.739300,0.122400
28.520000,72.421900,1.742800,0.122600
28.560000,72.422700,1.747400,0.122900
28.600000,72.423600,1.753700,0.123400
28.640000,72.424300,1.760100,0.123800
28.680000,72.425000,1.765100,0.124200
28.720000,72.425500,1.769000,0.124400
28.760000,72.426000,1.772500,0.124600
28.800000,72.426600,1.775800,0.124900
28.840000,72.427200,1.779700,0.125100
28.880000,72.428100,1.784900,0.125500
28.920000,72.428900,1.791900,0.125900
28.960000,72.429600,1.797200,0.126300
29.000000,72.430200,1.801700,0.126600
29.040000,72.430800,1.805900,0.126900
29.080000,72.431300,1.809600,0.127100
29.120000,72.431900,1.813100,0.127400
29.160000,72.432700,1.817300,0.127700
29.200000,72.433500,1.823400,0.128100
29.240000,72.434300,1.829900,0.128500
29.280000,72.434900,1.834500,0.128900
29.320000,72.435500,1.839000,0.129100
29.360000,72.436000,1.842600,0.129400
29.400000,72.436600,1.846000,0.129600
29.440000,72.437200,1.849900,0.129900
29.480000,72.438000,1.854900,0.130300
29.520000,72.438900,1.861700,0.130700
29.560000,72.439600,1.867800,0.131100
29.600000,72.440200,1.872200,0.131400
29.640000,72.440800,1.876300,0.131700
29.680000,72.441400,1.880200,0.131900
29.720000,72.441900,1.883700,0.132200
29.760000,72.442600,1.887600,0.132400
29.800000,72.443500,1.893000,0.132800
29.840000,72.444300,1.899500,0.133300
29.880000,72.444900,1.904800,0.133600
29.920000,72.445500,1.909300,0.133900
29.960000,72.446100,1.913300,0.134100
30.000000,72.446600,1.916800,0.134400
30.040000,72.447200,1.920500,0.134700
30.080000,72.447900,1.924900,0.135000
30.120000,72.448900,1.931500,0.135400
30.160000,72.449600,1.938100,0.135800
30.200000,72.450200,1.942600,0.136200
30.240000,72.450900,1.947000,0.136500
30.280000,72.451400,1.950600,0.136700
30.320000,72.451900,1.954300,0.136900
30.360000,72.452500,1.957800,0.137200
30.400000,72.453300,1.962400,0.137500
30.440000,72.454200,1.968800,0.138000
30.480000,72.454900,1.975300,0.138400
30.520000,72.455600,1.979800,0.138700
30.560000,72.456100,1.983900,0.139000
30.600000,72.456600,1.987800,0.139300
30.640000,72.457200,1.991500,0.139500
30.680000,72.457900,1.995600,0.139800
30.720000,72.458900,2.001600,0.140200
30.760000,72.459700,2.008800,0.140700
30.800000,72.460300,2.013700,0.141000
30.840000,72.460900,2.017600,0.141300
30.880000,72.461400,2.021500,0.141500
30.920000,72.461900,2.025100,0.141800
30.960000,72.462500,2.028300,0.142100
31.000000,72.463300,2.032800,0.142300
31.040000,72.464200,2.039200,0.142800
31.080000,72.464900,2.046100,0.143200
31.120000,72.465600,2.051000,0.143600
31.160000,72.466200,2.055400,0.143900
31.200000,72.466700,2.059300,0.144100
31.240000,72.467200,2.062800,0.144400
31.280000,72.467900,2.066700,0.144600
31.320000,72.468800,2.072300,0.145000
31.360000,72.469600,2.079400,0.145500
31.400000,72.470200,2.084900,0.145900
31.440000,72.470900,2.088900,0.146100
31.480000,72.471500,2.093100,0.146400
31.520000,72.472000,2.096900,0.146700
31.560000,72.472500,2.100400,0.146900
31.600000,72.473200,2.104700,0.147200
31.640000,72.474100,2.110400,0.147600
31.680000,72.475000,2.117500,0.148100
31.720000,72.475600,2.123000,0.148500
31.760000,72.476200,2.127700,0.148800
31.800000,72.476800,2.131800,0.149100
31.840000,72.477300,2.135200,0.149300
31.880000,72.477900,2.138800,0.149500
31.920000,72.478700,2.143700,0.149900
31.960000,72.479600,2.150200,0.150300
32.000000,72.480300,2.156400,0.150800
32.040000,72.480900,2.160700,0.151000
32.080000,72.481500,2.165300,0.151400
32.120000,72.482100,2.169700,0.151700
32.160000,72.482600,2.173400,0.151900
32.200000,72.483200,2.177100,0.152200
32.240000,72.484100,2.182200,0.152500
32.280000,72.484900,2.189200,0.153000
32.320000,72.485700,2.195300,0.153400
32.360000,72.486300,2.200200,0.153700
32.400000,72.486800,2.204500,0.154100
32.440000,72.487300,2.208100,0.154300
32.480000,72.487900,2.211100,0.154500
32.520000,72.488600,2.215300,0.154800
32.560000,72.489500,2.221600,0.155200
32.600000,72.490300,2.228400,0.155700
32.640000,72.490900,2.233800,0.156000
32.680000,72.491500,2.238400,0.156300
32.720000,72.492100,2.242300,0.156600
32.760000,72.492600,2.246300,0.156900
32.800000,72.493200,2.250400,0.157100
32.840000,72.494000,2.254500,0.157400
32.880000,72.494900,2.260600,0.157900
32.920000,72.495600,2.267200,0.158300
32.960000,72.496300,2.272400,0.158700
33.000000,72.496900,2.276700,0.159000
33.040000,72.497300,2.280400,0.159300
33.080000,72.497900,2.283800,0.159500
33.120000,72.498500,2.287600,0.159800
33.160000,72.499400,2.293200,0.160100
33.200000,72.500200,2.300400,0.160600
33.240000,72.500900,2.306300,0.161000
33.280000,72.501500,2.310800,0.161300
33.320000,72.502100,2.315300,0.161600
33.360000,72.502700,2.319200,0.161900
33.400000,72.503200,2.323100,0.162100
33.440000,72.503900,2.327200,0.162400
33.480000,72.504800,2.332900,0.162800
33.520000,72.505600,2.339800,0.163300
33.560000,72.506200,2.345100,0.163700
33.600000,72.506800,2.349300,0.164000
33.640000,72.507400,2.353500,0.164200
33.680000,72.507900,2.357100,0.164500
33.720000,72.508500,2.361000,0.164800
33.760000,72.509300,2.365700,0.165100
33.800000,72.510300,2.372500,0.165600
33.840000,72.510900,2.379400,0.166000
33.880000,72.511600,2.384200,0.166300
33.920000,72.512200,2.388500,0.166700
33.960000,72.512700,2.392500,0.167000
34.000000,72.513300,2.396400,0.167200
34.040000,72.513900,2.400300,0.167500
34.080000,72.514700,2.405100,0.167800
34.120000,72.515600,2.411700,0.168200
34.160000,72.516300,2.417900,0.168700
34.200000,72.516900,2.422700,0.169000
34.240000,72.517400,2.427200,0.169300
34.280000,72.518000,2.431200,0.169500
34.320000,72.518500,2.434800,0.169800
34.360000,72.519300,2.439100,0.170100
34.400000,72.520200,2.445500,0.170600
34.440000,72.521000,2.452500,0.171000
34.480000,72.521600,2.457500,0.171400
34.520000,72.522300,2.462200,0.171700
34.560000,72.522800,2.466400,0.172000
34.600000,72.523300,2.470100,0.172300
34.640000,72.523900,2.473600,0.172500
34.680000,72.524600,2.478200,0.172800
34.720000,72.525500,2.484500,0.173300
34.760000,72.526200,2.491200,0.173700
34.800000,72.526900,2.496400,0.174100
34.840000,72.527500,2.501100,0.174400
34.880000,72.528000,2.505000,0.174700
34.920000,72.528500,2.508700,0.174900
34.960000,72.529200,2.512700,0.175200
35.000000,72.530100,2.518500,0.175700
35.040000,72.531000,2.525800,0.176100
35.080000,72.531700,2.531600,0.176500
35.120000,72.532300,2.536100,0.176800
35.160000,72.532800,2.540400,0.177100
35.200000,72.533300,2.544000,0.177300
35.240000,72.533900,2.547600,0.177600
35.280000,72.534600,2.551700,0.177900
35.320000,72.535400,2.557600,0.178300
35.360000,72.536200,2.564600,0.178800
35.400000,72.536900,2.570200,0.179200
35.440000,72.537500,2.574900,0.179500
35.480000,72.538100,2.579100,0.179800
35.520000,72.538600,2.582400,0.180000
35.560000,72.539200,2.586100,0.180300
35.600000,72.540100,2.591500,0.180600
35.640000,72.541000,2.598800,0.181100
35.680000,72.541600,2.605100,0.181600
35.720000,72.542200,2.609400,0.181800
35.760000,72.542800,2.613900,0.182200
35.800000,72.543300,2.617700,0.182400
35.840000,72.543900,2.621400,0.182700
35.880000,72.544500,2.625300,0.182900
35.920000,72.545300,2.630600,0.183400
35.960000,72.546200,2.637400,0.183900
36.000000,72.547000,2.644000,0.184200
36.040000,72.547600,2.648800,0.184600
36.080000,72.548100,2.653100,0.184900
36.120000,72.548600,2.656800,0.185100
36.160000,72.549200,2.660000,0.185400
36.200000,72.550000,2.664800,0.185700
36.240000,72.550900,2.671800,0.186200
36.280000,72.551600,2.678500,0.186600
36.320000,72.552200,2.683200,0.187000
36.360000,72.552800,2.687700,0.187200
36.400000,72.553400,2.692000,0.187500
36.440000,72.553900,2.695900,0.187800
36.480000,72.554500,2.699900,0.188100
36.520000,72.555300,2.704700,0.188400
36.560000,72.556200,2.711200,0.188900
36.600000,72.557000,2.718000,0.189400
36.640000,72.557600,2.723500,0.189700
36.680000,72.558200,2.727700,0.190000
36.720000,72.558700,2.731600,0.190300
36.760000,72.559300,2.735300,0.190500
36.800000,72.559900,2.739600,0.190800
36.840000,72.560800,2.745300,0.191200
36.880000,72.561600,2.752400,0.191700
36.920000,72.562200,2.758100,0.192100
36.960000,72.562900,2.762800,0.192400
37.000000,72.563400,2.767000,0.192700
37.040000,72.564000,2.771100,0.193000
37.080000,72.564500,2.774900,0.193300
37.120000,72.565300,2.779200,0.193600
37.160000,72.566200,2.785400,0.194000
37.200000,72.567000,2.792800,0.194500
37.240000,72.567600,2.798700,0.194900
37.280000,72.568200,2.802900,0.195200
37.320000,72.568700,2.806600,0.195500
37.360000,72.569200,2.810400,0.195700
37.400000,72.569800,2.814200,0.195900
37.440000,72.570700,2.819500,0.196300
37.480000,72.571600,2.826600,0.196900
37.520000,72.572300,2.833300,0.197300
37.560000,72.572900,2.838100,0.197600
37.600000,72.573500,2.842400,0.197900
37.640000,72.574000,2.846300,0.198200
37.680000,72.574600,2.850300,0.198400
37.720000,72.575200,2.854500,0.198700
37.760000,72.576100,2.860300,0.199100
37.800000,72.577000,2.867500,0.199600
37.840000,72.577600,2.873700,0.200100
37.880000,72.578200,2.877900,0.200400
37.920000,72.578800,2.881800,0.200600
37.960000,72.579300,2.885500,0.200900
38.000000,72.579800,2.889000,0.201200
38.040000,72.580600,2.893900,0.201500
38.080000,72.581600,2.900800,0.202000
38.120000,72.582300,2.907800,0.202400
38.160000,72.583000,2.913000,0.202800
38.200000,72.583500,2.917500,0.203100
38.240000,72.584100,2.921500,0.203400
38.280000,72.584600,2.925600,0.203700
38.320000,72.585200,2.929500,0.204000
38.360000,72.586000,2.934500,0.204300
38.400000,72.586900,2.941200,0.204700
38.440000,72.587600,2.947900,0.205200
38.480000,72.588200,2.952400,0.205500
38.520000,72.588800,2.956800,0.205800
38.560000,72.589300,2.960800,0.206100
38.600000,72.589800,2.964400,0.206400
38.640000,72.590600,2.968500,0.206600
38.680000,72.591500,2.974700,0.207100
38.720000,72.592300,2.982100,0.207600
38.760000,72.593000,2.988200,0.208000
38.800000,72.593600,2.992700,0.208300
38.840000,72.594100,2.996700,0.208600
38.880000,72.594600,3.000600,0.208900
38.920000,72.595200,3.004500,0.209200
38.960000,72.595900,3.008900,0.209400
39.000000,72.596800,3.014900,0.209900
39.040000,72.597600,3.021900,0.210400
39.080000,72.598200,3.027500,0.210800
39.120000,72.598800,3.032000,0.211100
39.160000,72.599400,3.036100,0.211400
39.200000,72.599900,3.039800,0.211600
39.240000,72.600500,3.043900,0.211800
39.280000,72.601400,3.049600,0.212300
39.320000,72.602300,3.057000,0.212800
39.360000,72.603000,3.063500,0.213200
39.400000,72.603600,3.068100,0.213500
39.440000,72.604100,3.072100,0.213800
39.480000,72.604700,3.076000,0.214100
39.520000,72.605200,3.080000,0.214300
39.560000,72.605900,3.084200,0.214600
39.600000,72.606700,3.089900,0.215100
39.640000,72.607600,3.096900,0.215500
39.680000,72.608300,3.103000,0.215900
39.720000,72.608900,3.108000,0.216300
39.760000,72.609400,3.112300,0.216600
39.800000,72.610000,3.116000,0.216900
39.840000,72.610500,3.120200,0.217100
39.880000,72.611300,3.125000,0.217500
39.920000,72.612300,3.132000,0.218000
39.960000,72.612900,3.138700,0.218400
40.000000,72.613600,3.143400,0.218800
40.040000,72.614100,3.147700,0.219100
40.080000,72.614700,3.151800,0.219400
40.120000,72.615200,3.155700,0.219600
40.160000,72.615800,3.159900,0.219900
40.200000,72.616700,3.165300,0.220300
40.240000,72.617600,3.172200,0.220800
40.280000,72.618300,3.179000,0.221300
40.320000,72.618900,3.184100,0.221600
40.360000,72.619500,3.188500,0.222000
40.400000,72.620000,3.192400,0.222200
40.440000,72.620600,3.196200,0.222500
40.480000,72.621300,3.200900,0.222800
40.520000,72.622200,3.206900,0.223200
40.560000,72.622900,3.213600,0.223700
40.600000,72.623600,3.219100,0.224000
40.640000,72.624200,3.224000,0.224400
40.680000,72.624700,3.228500,0.224700
40.720000,72.625300,3.232400,0.225000
40.760000,72.625900,3.236600,0.225300
40.800000,72.626600,3.241300,0.225600
40.840000,72.627500,3.248000,0.226000
40.880000,72.628300,3.254400,0.226500
40.920000,72.629000,3.260000,0.226900
40.960000,72.629600,3.264600,0.227200
41.000000,72.630000,3.268600,0.227500
41.040000,72.630600,3.272200,0.227700
41.080000,72.631200,3.276200,0.228000
41.120000,72.632100,3.281900,0.228400
41.160000,72.632900,3.289200,0.228900
41.200000,72.633500,3.294800,0.229400
41.240000,72.634200,3.299700,0.229700
41.280000,72.634800,3.304600,0.230000
41.320000,72.635300,3.308700,0.230300
41.360000,72.635900,3.312500,0.230600
41.400000,72.636600,3.317200,0.230900
41.440000,72.637500,3.323400,0.231300
41.480000,72.638300,3.330100,0.231800
41.520000,72.638900,3.336100,0.232200
41.560000,72.639500,3.340500,0.232500
41.600000,72.640100,3.344500,0.232800
41.640000,72.640600,3.348300,0.233000
41.680000,72.641200,3.352300,0.233400
41.720000,72.642000,3.357200,0.233700
41.760000,72.642900,3.364700,0.234200
41.800000,72.643600,3.371500,0.234600
41.840000,72.644200,3.376200,0.235000
41.880000,72.644800,3.380600,0.235300
41.920000,72.645400,3.385200,0.235600
41.960000,72.646000,3.389300,0.235900
42.000000,72.646600,3.393200,0.236200
42.040000,72.647500,3.398900,0.236500
42.080000,72.648300,3.406000,0.237100
42.120000,72.648900,3.411900,0.237500
42.160000,72.649500,3.416800,0.237800
42.200000,72.650100,3.421200,0.238200
42.240000,72.650600,3.425100,0.238400
42.280000,72.651200,3.429000,0.238700
42.320000,72.652000,3.433700,0.239000
42.360000,72.652900,3.440600,0.239500
42.400000,72.653700,3.447800,0.240100
42.440000,72.654300,3.453000,0.240400
42.480000,72.654800,3.457700,0.240700
42.520000,72.655400,3.462100,0.241000
42.560000,72.656000,3.466200,0.241300
42.600000,72.656600,3.470200,0.241600
42.640000,72.657400,3.475300,0.241900
42.680000,72.658200,3.481800,0.242400
42.720000,72.658900,3.488600,0.242800
42.760000,72.659600,3.493700,0.243200
42.800000,72.660100,3.498300,0.243600
42.816000,72.660400,3.500100,0.243700