File: Modulus_Steel_1.csv
Time,Displacement,Force,Strain 1
(s),(mm),(kN),(%)
0.0000,0.0000,0.0014,0.0001
0.0200,0.0000,0.0015,0.0001
0.0400,0.0002,0.0015,0.0002
0.0600,0.0004,0.0019,0.0003
0.0800,0.0006,0.0030,0.0003
0.1000,0.0010,0.0047,0.0003
0.1200,0.0015,0.0072,0.0003
0.1400,0.0020,0.0102,0.0004
0.1600,0.0024,0.0135,0.0006
0.1800,0.0028,0.0165,0.0006
0.2000,0.0032,0.0191,0.0006
0.2200,0.0035,0.0215,0.0007
0.2400,0.0038,0.0234,0.0007
0.2600,0.0041,0.0253,0.0008
0.2800,0.0044,0.0272,0.0009
0.3000,0.0047,0.0289,0.0009
0.3200,0.0050,0.0307,0.0009
0.3400,0.0054,0.0326,0.0009
0.3600,0.0058,0.0349,0.0010
0.3800,0.0063,0.0374,0.0011
0.4000,0.0067,0.0398,0.0012
0.4200,0.0071,0.0423,0.0012
0.4400,0.0075,0.0445,0.0012
0.4600,0.0078,0.0466,0.0012
0.4800,0.0081,0.0486,0.0013
0.5000,0.0084,0.0501,0.0014
0.5200,0.0087,0.0515,0.0014
0.5400,0.0089,0.0529,0.0014
0.5600,0.0092,0.0543,0.0015
0.5800,0.0095,0.0555,0.0015
0.6000,0.0098,0.0569,0.0015
0.6200,0.0101,0.0583,0.0016
0.6400,0.0106,0.0598,0.0016
0.6600,0.0110,0.0617,0.0016
0.6800,0.0114,0.0640,0.0017
0.7000,0.0118,0.0660,0.0018
0.7200,0.0122,0.0680,0.0018
0.7400,0.0125,0.0700,0.0018
0.7600,0.0128,0.0718,0.0019
0.7800,0.0131,0.0733,0.0019
0.8000,0.0134,0.0747,0.0020
0.8200,0.0137,0.0763,0.0021
0.8400,0.0140,0.0780,0.0021
0.8600,0.0142,0.0794,0.0021
0.8800,0.0145,0.0808,0.0021
0.9000,0.0148,0.0820,0.0022
0.9200,0.0151,0.0835,0.0022
0.9400,0.0154,0.0851,0.0023
0.9600,0.0159,0.0869,0.0023
0.9800,0.0163,0.0891,0.0023
1.0000,0.0167,0.0914,0.0024
1.0200,0.0171,0.0936,0.0025
1.0400,0.0175,0.0958,0.0025
1.0600,0.0179,0.0978,0.0026
1.0800,0.0182,0.0994,0.0026
1.1000,0.0185,0.1006,0.0027
1.1200,0.0187,0.1016,0.0027
1.1400,0.0190,0.1028,0.0028
1.1600,0.0193,0.1039,0.0028
1.1800,0.0196,0.1051,0.0028
1.2000,0.0198,0.1062,0.0029
1.2200,0.0201,0.1073,0.0029
1.2400,0.0205,0.1085,0.0029
1.2600,0.0209,0.1099,0.0030
1.2800,0.0213,0.1117,0.0030
1.3000,0.0217,0.1137,0.0031
1.3200,0.0221,0.1154,0.0031
1.3400,0.0225,0.1170,0.0032
1.3600,0.0228,0.1183,0.0032
1.3800,0.0231,0.1194,0.0033
1.4000,0.0235,0.1204,0.0033
1.4200,0.0237,0.1214,0.0034
1.4400,0.0241,0.1224,0.0034
1.4600,0.0243,0.1232,0.0034
1.4800,0.0246,0.1241,0.0034
1.5000,0.0249,0.1251,0.0034
1.5200,0.0251,0.1260,0.0034
1.5400,0.0254,0.1270,0.0035
1.5600,0.0258,0.1283,0.0035
1.5800,0.0263,0.1299,0.0036
1.6000,0.0267,0.1316,0.0036
1.6200,0.0272,0.1332,0.0036
1.6400,0.0275,0.1348,0.0037
1.6600,0.0279,0.1362,0.0038
1.6800,0.0282,0.1372,0.0038
1.7000,0.0285,0.1380,0.0038
1.7200,0.0288,0.1385,0.0038
1.7400,0.0290,0.1391,0.0038
1.7600,0.0294,0.1399,0.0039
1.7800,0.0296,0.1406,0.0039
1.8000,0.0298,0.1413,0.0039
1.8200,0.0301,0.1421,0.0039
1.8400,0.0304,0.1430,0.0039
1.8600,0.0308,0.1440,0.0040
1.8800,0.0312,0.1452,0.0040
1.9000,0.0317,0.1468,0.0041
1.9200,0.0321,0.1487,0.0041
1.9400,0.0325,0.1503,0.0041
1.9600,0.0328,0.1517,0.0041
1.9800,0.0332,0.1526,0.0042
2.0000,0.0335,0.1533,0.0042
2.0200,0.0338,0.1540,0.0042
2.0400,0.0341,0.1549,0.0042
2.0600,0.0343,0.1557,0.0042
2.0800,0.0346,0.1564,0.0043
2.1000,0.0349,0.1569,0.0043
2.1200,0.0352,0.1575,0.0044
2.1400,0.0355,0.1582,0.0043
2.1600,0.0358,0.1592,0.0043
2.1800,0.0362,0.1606,0.0044
2.2000,0.0367,0.1621,0.0045
2.2200,0.0371,0.1639,0.0045
2.2400,0.0375,0.1655,0.0045
2.2600,0.0379,0.1669,0.0045
2.2800,0.0382,0.1681,0.0046
2.3000,0.0385,0.1691,0.0046
2.3200,0.0388,0.1697,0.0046
2.3400,0.0391,0.1704,0.0046
2.3600,0.0393,0.1712,0.0046
2.3800,0.0396,0.1718,0.0046
2.4000,0.0399,0.1725,0.0047
2.4200,0.0401,0.1734,0.0047
2.4400,0.0404,0.1743,0.0048
2.4600,0.0408,0.1755,0.0048
2.4800,0.0412,0.1771,0.0048
2.5000,0.0416,0.1789,0.0049
2.5200,0.0421,0.1809,0.0050
2.5400,0.0425,0.1831,0.0050
2.5600,0.0429,0.1848,0.0051
2.5800,0.0432,0.1864,0.0050
2.6000,0.0435,0.1876,0.0051
2.6200,0.0438,0.1886,0.0051
2.6400,0.0441,0.1897,0.0052
2.6600,0.0444,0.1909,0.0052
2.6800,0.0447,0.1919,0.0052
2.7000,0.0449,0.1930,0.0052
2.7200,0.0452,0.1941,0.0052
2.7400,0.0455,0.1950,0.0053
2.7600,0.0458,0.1961,0.0053
2.7800,0.0462,0.1974,0.0054
2.8000,0.0466,0.1990,0.0054
2.8200,0.0470,0.2011,0.0054
2.8400,0.0474,0.2032,0.0054
2.8600,0.0478,0.2054,0.0055
2.8800,0.0482,0.2074,0.0056
2.9000,0.0485,0.2087,0.0056
2.9200,0.0488,0.2098,0.0057
2.9400,0.0491,0.2110,0.0057
2.9600,0.0493,0.2122,0.0057
2.9800,0.0496,0.2132,0.0057
3.0000,0.0499,0.2142,0.0058
3.0200,0.0501,0.2153,0.0058
3.0400,0.0504,0.2163,0.0058
3.0600,0.0508,0.2174,0.0058
3.0800,0.0511,0.2189,0.0059
3.1000,0.0515,0.2209,0.0060
3.1200,0.0520,0.2231,0.0060
3.1400,0.0524,0.2255,0.0060
3.1600,0.0528,0.2277,0.0060
3.1800,0.0532,0.2296,0.0061
3.2000,0.0535,0.2313,0.0062
3.2200,0.0538,0.2328,0.0062
3.2400,0.0542,0.2340,0.0062
3.2600,0.0544,0.2352,0.0063
3.2800,0.0547,0.2364,0.0063
3.3000,0.0550,0.2375,0.0063
3.3200,0.0552,0.2386,0.0063
3.3400,0.0555,0.2397,0.0064
3.3600,0.0558,0.2409,0.0064
3.3800,0.0561,0.2422,0.0065
3.4000,0.0565,0.2438,0.0065
3.4200,0.0569,0.2457,0.0065
3.4400,0.0573,0.2480,0.0066
3.4600,0.0577,0.2503,0.0067
3.4800,0.0581,0.2525,0.0067
3.5000,0.0585,0.2545,0.0068
3.5200,0.0588,0.2562,0.0068
3.5400,0.0591,0.2576,0.0068
3.5600,0.0594,0.2589,0.0068
3.5800,0.0597,0.2601,0.0069
3.6000,0.0599,0.2613,0.0069
3.6200,0.0602,0.2626,0.0069
3.6400,0.0605,0.2639,0.0069
3.6600,0.0608,0.2651,0.0069
3.6800,0.0611,0.2665,0.0070
3.7000,0.0616,0.2684,0.0071
3.7200,0.0620,0.2706,0.0071
3.7400,0.0624,0.2730,0.0071
3.7600,0.0628,0.2754,0.0072
3.7800,0.0632,0.2779,0.0073
3.8000,0.0636,0.2799,0.0074
3.8200,0.0639,0.2815,0.0074
3.8400,0.0642,0.2829,0.0074
3.8600,0.0644,0.2843,0.0074
3.8800,0.0648,0.2858,0.0075
3.9000,0.0650,0.2871,0.0076
3.9200,0.0652,0.2882,0.0076
3.9400,0.0655,0.2893,0.0076
3.9600,0.0658,0.2905,0.0075
3.9800,0.0661,0.2920,0.0076
4.0000,0.0665,0.2937,0.0077
4.0200,0.0669,0.2956,0.0077
4.0400,0.0673,0.2978,0.0078
4.0600,0.0677,0.3001,0.0078
4.0800,0.0681,0.3028,0.0079
4.1000,0.0685,0.3053,0.0080
4.1200,0.0688,0.3073,0.0080
4.1400,0.0692,0.3092,0.0080
4.1600,0.0695,0.3109,0.0081
4.1800,0.0697,0.3123,0.0081
4.2000,0.0700,0.3135,0.0081
4.2200,0.0703,0.3148,0.0082
4.2400,0.0706,0.3161,0.0082
4.2600,0.0708,0.3173,0.0082
4.2800,0.0711,0.3187,0.0082
4.3000,0.0715,0.3203,0.0082
4.3200,0.0719,0.3223,0.0084
4.3400,0.0724,0.3246,0.0085
4.3600,0.0729,0.3273,0.0085
4.3800,0.0732,0.3299,0.0085
4.4000,0.0736,0.3321,0.0085
4.4200,0.0739,0.3339,0.0086
4.4400,0.0741,0.3355,0.0087
4.4600,0.0745,0.3368,0.0087
4.4800,0.0747,0.3380,0.0087
4.5000,0.0750,0.3393,0.0087
4.5200,0.0753,0.3405,0.0087
4.5400,0.0756,0.3418,0.0088
4.5600,0.0759,0.3430,0.0088
4.5800,0.0761,0.3441,0.0088
4.6000,0.0764,0.3453,0.0089
4.6200,0.0768,0.3470,0.0089
4.6400,0.0772,0.3491,0.0089
4.6600,0.0777,0.3514,0.0090
4.6800,0.0781,0.3538,0.0091
4.7000,0.0785,0.3559,0.0091
4.7200,0.0789,0.3579,0.0091
4.7400,0.0792,0.3596,0.0092
4.7600,0.0795,0.3611,0.0093
4.7800,0.0798,0.3623,0.0093
4.8000,0.0801,0.3636,0.0093
4.8200,0.0804,0.3648,0.0093
4.8400,0.0806,0.3659,0.0094
4.8600,0.0808,0.3668,0.0094
4.8800,0.0812,0.3677,0.0094
4.9000,0.0815,0.3691,0.0094
4.9200,0.0819,0.3709,0.0094
4.9400,0.0823,0.3730,0.0095
4.9600,0.0827,0.3755,0.0096
4.9800,0.0831,0.3782,0.0096
5.0000,0.0835,0.3806,0.0097
5.0200,0.0838,0.3824,0.0097
5.0400,0.0842,0.3839,0.0097
5.0600,0.0845,0.3852,0.0098
5.0800,0.0847,0.3866,0.0098
5.1000,0.0851,0.3881,0.0098
5.1200,0.0853,0.3895,0.0099
5.1400,0.0856,0.3907,0.0099
5.1600,0.0859,0.3918,0.0099
5.1800,0.0861,0.3929,0.0100
5.2000,0.0865,0.3942,0.0100
5.2200,0.0868,0.3956,0.0101
5.2400,0.0872,0.3974,0.0101
5.2600,0.0876,0.3994,0.0102
5.2800,0.0881,0.4019,0.0102
5.3000,0.0885,0.4045,0.0103
5.3200,0.0889,0.4067,0.0103
5.3400,0.0892,0.4087,0.0104
5.3600,0.0895,0.4105,0.0104
5.3800,0.0898,0.4118,0.0104
5.4000,0.0901,0.4129,0.0105
5.4200,0.0904,0.4142,0.0105
5.4400,0.0906,0.4152,0.0106
5.4600,0.0909,0.4162,0.0106
5.4800,0.0911,0.4172,0.0106
5.5000,0.0914,0.4182,0.0106
5.5200,0.0918,0.4196,0.0106
5.5400,0.0922,0.4213,0.0107
5.5600,0.0926,0.4234,0.0107
5.5800,0.0930,0.4256,0.0108
5.6000,0.0934,0.4279,0.0109
5.6200,0.0938,0.4301,0.0109
5.6400,0.0941,0.4322,0.0110
5.6600,0.0944,0.4338,0.0110
5.6800,0.0948,0.4352,0.0111
5.7000,0.0951,0.4365,0.0111
5.7200,0.0954,0.4381,0.0111
5.7400,0.0957,0.4392,0.0112
5.7600,0.0959,0.4403,0.0112
5.7800,0.0962,0.4414,0.0112
5.8000,0.0965,0.4426,0.0112
5.8200,0.0968,0.4437,0.0112
5.8400,0.0971,0.4451,0.0113
5.8600,0.0976,0.4469,0.0113
5.8800,0.0980,0.4493,0.0114
5.9000,0.0984,0.4517,0.0114
5.9200,0.0988,0.4540,0.0115
5.9400,0.0992,0.4562,0.0116
5.9600,0.0995,0.4582,0.0116
5.9800,0.0999,0.4599,0.0117
6.0000,0.1001,0.4611,0.0117
6.0200,0.1004,0.4622,0.0117
6.0400,0.1007,0.4632,0.0117
6.0600,0.1009,0.4641,0.0117
6.0800,0.1012,0.4650,0.0117
6.1000,0.1015,0.4659,0.0118
6.1200,0.1018,0.4668,0.0118
6.1400,0.1021,0.4684,0.0119
6.1600,0.1025,0.4703,0.0119
6.1800,0.1030,0.4727,0.0119
6.2000,0.1034,0.4752,0.0120
6.2200,0.1038,0.4776,0.0120
6.2400,0.1041,0.4796,0.0121
6.2600,0.1045,0.4814,0.0122
6.2800,0.1048,0.4828,0.0122
6.3000,0.1051,0.4842,0.0122
6.3200,0.1054,0.4854,0.0123
6.3400,0.1057,0.4866,0.0123
6.3600,0.1060,0.4877,0.0123
6.3800,0.1062,0.4888,0.0123
6.4000,0.1065,0.4897,0.0123
6.4200,0.1068,0.4907,0.0124
6.4400,0.1071,0.4919,0.0124
6.4600,0.1075,0.4935,0.0124
6.4800,0.1079,0.4956,0.0125
6.5000,0.1084,0.4980,0.0126
6.5200,0.1088,0.5006,0.0126
6.5400,0.1092,0.5031,0.0127
6.5600,0.1096,0.5053,0.0128
6.5800,0.1099,0.5071,0.0128
6.6000,0.1101,0.5083,0.0128
6.6200,0.1104,0.5094,0.0128
6.6400,0.1107,0.5104,0.0129
6.6600,0.1109,0.5116,0.0129
6.6800,0.1112,0.5127,0.0130
6.7000,0.1115,0.5138,0.0130
6.7200,0.1117,0.5150,0.0130
6.7400,0.1121,0.5163,0.0130
6.7600,0.1125,0.5181,0.0131
6.7800,0.1129,0.5202,0.0132
6.8000,0.1134,0.5228,0.0132
6.8200,0.1138,0.5255,0.0133
6.8400,0.1142,0.5281,0.0133
6.8600,0.1145,0.5303,0.0134
6.8800,0.1149,0.5321,0.0134
6.9000,0.1152,0.5337,0.0135
6.9200,0.1155,0.5355,0.0135
6.9400,0.1158,0.5371,0.0136
6.9600,0.1160,0.5383,0.0136
6.9800,0.1163,0.5393,0.0136
7.0000,0.1166,0.5404,0.0137
7.0200,0.1168,0.5415,0.0137
7.0400,0.1172,0.5428,0.0137
7.0600,0.1175,0.5443,0.0138
7.0800,0.1179,0.5462,0.0138
7.1000,0.1183,0.5484,0.0139
7.1200,0.1187,0.5510,0.0139
7.1400,0.1191,0.5538,0.0140
7.1600,0.1195,0.5563,0.0140
7.1800,0.1198,0.5582,0.0141
7.2000,0.1202,0.5600,0.0142
7.2200,0.1205,0.5615,0.0142
7.2400,0.1207,0.5628,0.0142
7.2600,0.1210,0.5642,0.0143
7.2800,0.1213,0.5655,0.0143
7.3000,0.1216,0.5667,0.0144
7.3200,0.1218,0.5677,0.0144
7.3400,0.1221,0.5689,0.0144
7.3600,0.1225,0.5703,0.0144
7.3800,0.1229,0.5723,0.0145
7.4000,0.1233,0.5748,0.0146
7.4200,0.1237,0.5778,0.0147
7.4400,0.1242,0.5805,0.0147
7.4600,0.1246,0.5829,0.0148
7.4800,0.1249,0.5849,0.0148
7.5000,0.1252,0.5867,0.0149
7.5200,0.1255,0.5884,0.0150
7.5400,0.1258,0.5898,0.0150
7.5600,0.1261,0.5912,0.0150
7.5800,0.1263,0.5925,0.0150
7.6000,0.1266,0.5936,0.0151
7.6200,0.1269,0.5946,0.0151
7.6400,0.1271,0.5957,0.0152
7.6600,0.1274,0.5970,0.0152
7.6800,0.1278,0.5988,0.0152
7.7000,0.1282,0.6010,0.0152
7.7200,0.1286,0.6034,0.0154
7.7400,0.1291,0.6060,0.0155
7.7600,0.1295,0.6087,0.0155
7.7800,0.1299,0.6114,0.0155
7.8000,0.1302,0.6136,0.0155
7.8200,0.1305,0.6155,0.0156
7.8400,0.1308,0.6170,0.0157
7.8600,0.1311,0.6183,0.0157
7.8800,0.1314,0.6196,0.0158
7.9000,0.1316,0.6208,0.0158
7.9200,0.1318,0.6222,0.0158
7.9400,0.1322,0.6234,0.0159
7.9600,0.1325,0.6247,0.0159
7.9800,0.1329,0.6266,0.0159
8.0000,0.1333,0.6289,0.0159
8.0200,0.1337,0.6316,0.0160
8.0400,0.1341,0.6347,0.0162
8.0600,0.1346,0.6374,0.0163
8.0800,0.1349,0.6399,0.0163
8.1000,0.1352,0.6420,0.0163
8.1200,0.1355,0.6438,0.0164
8.1400,0.1359,0.6455,0.0164
8.1600,0.1361,0.6471,0.0165
8.1800,0.1363,0.6483,0.0166
8.2000,0.1366,0.6493,0.0165
8.2200,0.1369,0.6505,0.0165
8.2400,0.1371,0.6517,0.0165
8.2600,0.1374,0.6530,0.0166
8.2800,0.1377,0.6547,0.0167
8.3000,0.1381,0.6566,0.0167
8.3200,0.1385,0.6589,0.0167
8.3400,0.1390,0.6617,0.0168
8.3600,0.1394,0.6648,0.0169
8.3800,0.1398,0.6676,0.0171
8.4000,0.1402,0.6701,0.0171
8.4200,0.1405,0.6723,0.0171
8.4400,0.1408,0.6743,0.0171
8.4600,0.1411,0.6761,0.0172
8.4800,0.1414,0.6775,0.0173
8.5000,0.1416,0.6788,0.0173
8.5200,0.1419,0.6800,0.0173
8.5400,0.1422,0.6812,0.0173
8.5600,0.1424,0.6824,0.0173
8.5800,0.1428,0.6841,0.0174
8.6000,0.1432,0.6865,0.0175
8.6200,0.1436,0.6891,0.0175
8.6400,0.1441,0.6921,0.0176
8.6600,0.1445,0.6953,0.0176
8.6800,0.1449,0.6981,0.0177
8.7000,0.1452,0.7006,0.0178
8.7200,0.1455,0.7025,0.0179
8.7400,0.1458,0.7042,0.0179
8.7600,0.1461,0.7058,0.0179
8.7800,0.1464,0.7074,0.0180
8.8000,0.1466,0.7089,0.0181
8.8200,0.1469,0.7102,0.0181
8.8400,0.1472,0.7116,0.0181
8.8600,0.1474,0.7129,0.0181
8.8800,0.1477,0.7144,0.0181
8.9000,0.1481,0.7162,0.0182
8.9200,0.1485,0.7184,0.0183
8.9400,0.1489,0.7212,0.0184
8.9600,0.1494,0.7242,0.0184
8.9800,0.1498,0.7274,0.0184
9.0000,0.1502,0.7304,0.0185
9.0200,0.1505,0.7331,0.0187
9.0400,0.1509,0.7352,0.0187
9.0600,0.1511,0.7369,0.0187
9.0800,0.1514,0.7384,0.0187
9.1000,0.1517,0.7399,0.0188
9.1200,0.1520,0.7414,0.0188
9.1400,0.1522,0.7427,0.0189
9.1600,0.1525,0.7441,0.0189
9.1800,0.1528,0.7456,0.0189
9.2000,0.1532,0.7475,0.0189
9.2200,0.1536,0.7500,0.0190
9.2400,0.1540,0.7530,0.0191
9.2600,0.1544,0.7562,0.0192
9.2800,0.1548,0.7593,0.0193
9.3000,0.1552,0.7619,0.0193
9.3200,0.1555,0.7642,0.0194
9.3400,0.1558,0.7663,0.0194
9.3600,0.1561,0.7683,0.0195
9.3800,0.1564,0.7702,0.0195
9.4000,0.1567,0.7719,0.0195
9.4200,0.1570,0.7735,0.0196
9.4400,0.1572,0.7752,0.0196
9.4600,0.1575,0.7769,0.0197
9.4800,0.1578,0.7783,0.0197
9.5000,0.1581,0.7799,0.0197
9.5200,0.1585,0.7821,0.0198
9.5400,0.1589,0.7847,0.0199
9.5600,0.1593,0.7881,0.0200
9.5800,0.1598,0.7915,0.0201
9.6000,0.1602,0.7947,0.0201
9.6200,0.1606,0.7977,0.0202
9.6400,0.1609,0.8001,0.0202
9.6600,0.1612,0.8022,0.0203
9.6800,0.1615,0.8040,0.0204
9.7000,0.1617,0.8056,0.0204
9.7200,0.1620,0.8072,0.0204
9.7400,0.1623,0.8086,0.0204
9.7600,0.1625,0.8100,0.0205
9.7800,0.1629,0.8115,0.0205
9.8000,0.1631,0.8133,0.0206
9.8200,0.1635,0.8155,0.0206
9.8400,0.1639,0.8180,0.0206
9.8600,0.1644,0.8210,0.0207
9.8800,0.1648,0.8243,0.0208
9.9000,0.1652,0.8274,0.0209
9.9200,0.1655,0.8301,0.0210
9.9400,0.1658,0.8325,0.0210
9.9600,0.1661,0.8346,0.0211
9.9800,0.1664,0.8365,0.0211
10.0000,0.1667,0.8382,0.0212
10.0200,0.1670,0.8397,0.0212
10.0400,0.1672,0.8414,0.0212
10.0600,0.1675,0.8432,0.0212
10.0800,0.1678,0.8449,0.0213
10.1000,0.1681,0.8466,0.0213
10.1200,0.1685,0.8484,0.0214
10.1400,0.1689,0.8508,0.0214
10.1600,0.1693,0.8535,0.0215
10.1800,0.1698,0.8566,0.0216
10.2000,0.1702,0.8600,0.0217
10.2200,0.1706,0.8632,0.0217
10.2400,0.1709,0.8659,0.0218
10.2600,0.1712,0.8680,0.0218
10.2800,0.1715,0.8700,0.0219
10.3000,0.1718,0.8716,0.0219
10.3200,0.1720,0.8729,0.0219
10.3400,0.1723,0.8745,0.0220
10.3600,0.1726,0.8761,0.0220
10.3800,0.1728,0.8774,0.0220
10.4000,0.1731,0.8789,0.0221
10.4200,0.1735,0.8808,0.0222
10.4400,0.1738,0.8833,0.0222
10.4600,0.1743,0.8861,0.0222
10.4800,0.1747,0.8893,0.0223
10.5000,0.1751,0.8927,0.0224
10.5200,0.1755,0.8960,0.0225
10.5400,0.1758,0.8985,0.0225
10.5600,0.1761,0.9007,0.0226
10.5800,0.1765,0.9027,0.0226
10.6000,0.1768,0.9045,0.0227
10.6200,0.1771,0.9064,0.0227
10.6400,0.1773,0.9080,0.0227
10.6600,0.1776,0.9096,0.0228
10.6800,0.1779,0.9113,0.0228
10.7000,0.1781,0.9128,0.0228
10.7200,0.1784,0.9147,0.0228
10.7400,0.1788,0.9168,0.0229
10.7600,0.1792,0.9195,0.0230
10.7800,0.1797,0.9226,0.0230
10.8000,0.1801,0.9259,0.0231
10.8200,0.1805,0.9295,0.0232
10.8400,0.1809,0.9327,0.0233
10.8600,0.1812,0.9352,0.0234
10.8800,0.1815,0.9374,0.0234
10.9000,0.1818,0.9393,0.0234
10.9200,0.1820,0.9410,0.0234
10.9400,0.1823,0.9424,0.0235
10.9600,0.1826,0.9439,0.0235
10.9800,0.1828,0.9456,0.0235
11.0000,0.1831,0.9472,0.0236
11.0200,0.1834,0.9490,0.0236
11.0400,0.1838,0.9510,0.0236
11.0600,0.1842,0.9536,0.0237
11.0800,0.1847,0.9569,0.0238
11.1000,0.1851,0.9602,0.0238
11.1200,0.1855,0.9634,0.0240
11.1400,0.1858,0.9665,0.0240
11.1600,0.1862,0.9691,0.0241
11.1800,0.1865,0.9713,0.0241
11.2000,0.1868,0.9735,0.0242
11.2200,0.1871,0.9754,0.0242
11.2400,0.1874,0.9772,0.0242
11.2600,0.1877,0.9789,0.0243
11.2800,0.1879,0.9804,0.0243
11.3000,0.1882,0.9821,0.0243
11.3200,0.1885,0.9838,0.0244
11.3400,0.1888,0.9857,0.0244
11.3600,0.1892,0.9880,0.0245
11.3800,0.1896,0.9908,0.0245
11.4000,0.1901,0.9942,0.0246
11.4200,0.1904,0.9977,0.0247
11.4400,0.1908,1.0013,0.0247
11.4600,0.1912,1.0043,0.0248
11.4800,0.1915,1.0067,0.0249
11.5000,0.1918,1.0086,0.0249
11.5200,0.1921,1.0105,0.0249
11.5400,0.1924,1.0125,0.0250
11.5600,0.1926,1.0143,0.0250
11.5800,0.1929,1.0159,0.0251
11.6000,0.1931,1.0173,0.0251
11.6200,0.1934,1.0191,0.0251
11.6400,0.1938,1.0210,0.0251
11.6600,0.1941,1.0234,0.0252
11.6800,0.1946,1.0264,0.0253
11.7000,0.1951,1.0301,0.0254
11.7200,0.1955,1.0338,0.0255
11.7400,0.1959,1.0370,0.0255
11.7600,0.1962,1.0398,0.0256
11.7800,0.1966,1.0423,0.0257
11.8000,0.1968,1.0444,0.0257
11.8200,0.1971,1.0465,0.0257
11.8400,0.1974,1.0485,0.0258
11.8600,0.1977,1.0505,0.0258
11.8800,0.1979,1.0521,0.0258
11.9000,0.1983,1.0537,0.0259
11.9200,0.1985,1.0556,0.0259
11.9400,0.1988,1.0574,0.0260
11.9600,0.1991,1.0594,0.0260
11.9800,0.1996,1.0619,0.0261
12.0000,0.1999,1.0648,0.0261
12.0200,0.2004,1.0683,0.0262
12.0400,0.2008,1.0718,0.0263
12.0600,0.2012,1.0751,0.0264
12.0800,0.2015,1.0782,0.0264
12.1000,0.2018,1.0810,0.0265
12.1200,0.2021,1.0833,0.0265
12.1400,0.2024,1.0854,0.0266
12.1600,0.2027,1.0871,0.0266
12.1800,0.2029,1.0889,0.0266
12.2000,0.2032,1.0907,0.0267
12.2200,0.2035,1.0923,0.0267
12.2400,0.2038,1.0941,0.0268
12.2600,0.2042,1.0963,0.0268
12.2800,0.2046,1.0992,0.0269
12.3000,0.2050,1.1026,0.0269
12.3200,0.2054,1.1062,0.0270
12.3400,0.2059,1.1099,0.0271
12.3600,0.2062,1.1132,0.0272
12.3800,0.2066,1.1159,0.0272
12.4000,0.2068,1.1182,0.0273
12.4200,0.2072,1.1204,0.0273
12.4400,0.2074,1.1227,0.0274
12.4600,0.2077,1.1246,0.0274
12.4800,0.2080,1.1264,0.0274
12.5000,0.2082,1.1282,0.0275
12.5200,0.2085,1.1301,0.0275
12.5400,0.2088,1.1319,0.0276
12.5600,0.2091,1.1336,0.0276
12.5800,0.2095,1.1358,0.0277
12.6000,0.2099,1.1387,0.0277
12.6200,0.2103,1.1422,0.0278
12.6400,0.2107,1.1458,0.0279
12.6600,0.2111,1.1492,0.0280
12.6800,0.2115,1.1524,0.0281
12.7000,0.2118,1.1554,0.0281
12.7200,0.2121,1.1579,0.0281
12.7400,0.2125,1.1602,0.0282
12.7600,0.2127,1.1622,0.0283
12.7800,0.2130,1.1640,0.0283
12.8000,0.2133,1.1659,0.0283
12.8200,0.2135,1.1677,0.0284
12.8400,0.2138,1.1693,0.0284
12.8600,0.2141,1.1714,0.0284
12.8800,0.2145,1.1739,0.0285
12.9000,0.2149,1.1768,0.0286
12.9200,0.2154,1.1802,0.0286
12.9400,0.2158,1.1840,0.0287
12.9600,0.2162,1.1876,0.0288
12.9800,0.2165,1.1907,0.0289
13.0000,0.2169,1.1932,0.0290
13.0200,0.2172,1.1954,0.0290
13.0400,0.2174,1.1976,0.0291
13.0600,0.2177,1.1996,0.0291
13.0800,0.2180,1.2016,0.0292
13.1000,0.2182,1.2033,0.0292
13.1200,0.2185,1.2050,0.0292
13.1400,0.2188,1.2069,0.0292
13.1600,0.2191,1.2089,0.0293
13.1800,0.2194,1.2110,0.0293
13.2000,0.2199,1.2137,0.0294
13.2200,0.2203,1.2168,0.0295
13.2400,0.2207,1.2205,0.0295
13.2600,0.2211,1.2242,0.0296
13.2800,0.2215,1.2278,0.0297
13.3000,0.2218,1.2311,0.0298
13.3200,0.2222,1.2338,0.0298
13.3400,0.2225,1.2361,0.0299
13.3600,0.2227,1.2381,0.0299
13.3800,0.2230,1.2401,0.0300
13.4000,0.2233,1.2420,0.0300
13.4200,0.2236,1.2436,0.0300
13.4400,0.2238,1.2452,0.0301
13.4600,0.2241,1.2471,0.0301
13.4800,0.2245,1.2493,0.0301
13.5000,0.2249,1.2520,0.0302
13.5200,0.2253,1.2552,0.0303
13.5400,0.2257,1.2589,0.0304
13.5600,0.2261,1.2626,0.0305
13.5800,0.2265,1.2658,0.0306
13.6000,0.2268,1.2686,0.0306
13.6200,0.2271,1.2709,0.0307
13.6400,0.2275,1.2732,0.0307
13.6600,0.2277,1.2753,0.0307
13.6800,0.2280,1.2772,0.0307
13.7000,0.2283,1.2791,0.0308
13.7200,0.2285,1.2811,0.0309
13.7400,0.2288,1.2830,0.0309
13.7600,0.2291,1.2847,0.0309
13.7800,0.2294,1.2866,0.0310
13.8000,0.2298,1.2888,0.0310
13.8200,0.2302,1.2918,0.0311
13.8400,0.2306,1.2953,0.0312
13.8600,0.2311,1.2992,0.0313
13.8800,0.2315,1.3028,0.0313
13.9000,0.2319,1.3062,0.0314
13.9200,0.2322,1.3092,0.0315
13.9400,0.2325,1.3119,0.0316
13.9600,0.2328,1.3143,0.0316
13.9800,0.2331,1.3164,0.0317
14.0000,0.2334,1.3182,0.0317
14.0200,0.2336,1.3199,0.0317
14.0400,0.2339,1.3215,0.0318
14.0600,0.2342,1.3232,0.0318
14.0800,0.2345,1.3250,0.0318
14.1000,0.2348,1.3274,0.0319
14.1200,0.2352,1.3303,0.0320
14.1400,0.2357,1.3337,0.0321
14.1600,0.2361,1.3374,0.0322
14.1800,0.2365,1.3411,0.0322
14.2000,0.2368,1.3442,0.0323
14.2200,0.2372,1.3469,0.0323
14.2400,0.2375,1.3495,0.0324
14.2600,0.2378,1.3517,0.0325
14.2800,0.2381,1.3538,0.0325
14.3000,0.2383,1.3559,0.0326
14.3200,0.2387,1.3579,0.0326
14.3400,0.2389,1.3597,0.0327
14.3600,0.2392,1.3617,0.0327
14.3800,0.2395,1.3635,0.0327
14.4000,0.2398,1.3656,0.0328
14.4200,0.2402,1.3681,0.0328
14.4400,0.2406,1.3714,0.0329
14.4600,0.2411,1.3751,0.0330
14.4800,0.2415,1.3790,0.0331
14.5000,0.2419,1.3825,0.0332
14.5200,0.2422,1.3857,0.0332
14.5400,0.2426,1.3887,0.0333
14.5600,0.2428,1.3912,0.0334
14.5800,0.2431,1.3934,0.0334
14.6000,0.2434,1.3953,0.0334
14.6200,0.2436,1.3970,0.0335
14.6400,0.2439,1.3987,0.0335
14.6600,0.2442,1.4005,0.0336
14.6800,0.2444,1.4026,0.0336
14.7000,0.2448,1.4047,0.0337
14.7200,0.2451,1.4073,0.0337
14.7400,0.2456,1.4104,0.0338
14.7600,0.2461,1.4142,0.0339
14.7800,0.2465,1.4181,0.0340
14.8000,0.2469,1.4218,0.0341
14.8200,0.2472,1.4249,0.0341
14.8400,0.2475,1.4277,0.0342
14.8600,0.2478,1.4300,0.0343
14.8800,0.2481,1.4323,0.0344
14.9000,0.2484,1.4346,0.0344
14.9200,0.2487,1.4368,0.0344
14.9400,0.2489,1.4388,0.0345
14.9600,0.2492,1.4406,0.0346
14.9800,0.2495,1.4427,0.0346
15.0000,0.2498,1.4446,0.0346
15.0200,0.2502,1.4470,0.0346
15.0400,0.2506,1.4499,0.0347
15.0600,0.2510,1.4534,0.0348
15.0800,0.2515,1.4570,0.0349
15.1000,0.2518,1.4609,0.0350
15.1200,0.2522,1.4644,0.0351
15.1400,0.2525,1.4676,0.0351
15.1600,0.2529,1.4703,0.0352
15.1800,0.2531,1.4725,0.0353
15.2000,0.2534,1.4745,0.0353
15.2200,0.2537,1.4764,0.0353
15.2400,0.2539,1.4783,0.0354
15.2600,0.2542,1.4803,0.0354
15.2800,0.2545,1.4822,0.0354
15.3000,0.2548,1.4843,0.0355
15.3200,0.2551,1.4867,0.0356
15.3400,0.2555,1.4897,0.0356
15.3600,0.2560,1.4931,0.0357
15.3800,0.2564,1.4970,0.0358
15.4000,0.2568,1.5010,0.0359
15.4200,0.2572,1.5046,0.0360
15.4400,0.2575,1.5077,0.0361
15.4600,0.2578,1.5104,0.0361
15.4800,0.2582,1.5128,0.0362
15.5000,0.2584,1.5153,0.0363
15.5200,0.2587,1.5176,0.0363
15.5400,0.2590,1.5196,0.0363
15.5600,0.2593,1.5215,0.0364
15.5800,0.2595,1.5234,0.0364
15.6000,0.2598,1.5254,0.0365
15.6200,0.2601,1.5275,0.0365
15.6400,0.2605,1.5302,0.0366
15.6600,0.2609,1.5335,0.0367
15.6800,0.2614,1.5374,0.0368
15.7000,0.2617,1.5415,0.0369
15.7200,0.2622,1.5452,0.0370
15.7400,0.2625,1.5485,0.0371
15.7600,0.2628,1.5514,0.0371
15.7800,0.2631,1.5539,0.0371
15.8000,0.2634,1.5562,0.0372
15.8200,0.2637,1.5585,0.0372
15.8400,0.2640,1.5604,0.0373
15.8600,0.2642,1.5625,0.0373
15.8800,0.2645,1.5646,0.0374
15.9000,0.2648,1.5667,0.0374
15.9200,0.2651,1.5689,0.0375
15.9400,0.2655,1.5715,0.0376
15.9600,0.2659,1.5746,0.0376
15.9800,0.2664,1.5784,0.0377
16.0000,0.2668,1.5826,0.0378
16.0200,0.2672,1.5863,0.0379
16.0400,0.2675,1.5897,0.0380
16.0600,0.2679,1.5926,0.0381
16.0800,0.2682,1.5952,0.0381
16.1000,0.2684,1.5977,0.0381
16.1200,0.2688,1.6001,0.0382
16.1400,0.2690,1.6023,0.0383
16.1600,0.2693,1.6043,0.0384
16.1800,0.2696,1.6063,0.0384
16.2000,0.2698,1.6084,0.0384
16.2200,0.2701,1.6106,0.0384
16.2400,0.2705,1.6130,0.0385
16.2600,0.2709,1.6159,0.0386
16.2800,0.2712,1.6193,0.0387
16.3000,0.2717,1.6232,0.0387
16.3200,0.2721,1.6274,0.0388
16.3400,0.2725,1.6312,0.0389
16.3600,0.2728,1.6347,0.0390
16.3800,0.2731,1.6376,0.0391
16.4000,0.2734,1.6399,0.0391
16.4200,0.2737,1.6422,0.0392
16.4400,0.2740,1.6445,0.0392
16.4600,0.2743,1.6469,0.0393
16.4800,0.2746,1.6490,0.0394
16.5000,0.2748,1.6507,0.0394
16.5200,0.2751,1.6528,0.0394
16.5400,0.2755,1.6553,0.0395
16.5600,0.2758,1.6582,0.0396
16.5800,0.2763,1.6618,0.0397
16.6000,0.2767,1.6658,0.0398
16.6200,0.2772,1.6700,0.0399
16.6400,0.2776,1.6737,0.0399
16.6600,0.2779,1.6770,0.0400
16.6800,0.2782,1.6798,0.0401
16.7000,0.2785,1.6821,0.0402
16.7200,0.2788,1.6844,0.0402
16.7400,0.2790,1.6868,0.0402
16.7600,0.2793,1.6889,0.0403
16.7800,0.2795,1.6909,0.0403
16.8000,0.2799,1.6930,0.0404
16.8200,0.2801,1.6952,0.0404
16.8400,0.2804,1.6975,0.0405
16.8600,0.2808,1.7001,0.0405
16.8800,0.2812,1.7034,0.0406
16.9000,0.2816,1.7071,0.0408
16.9200,0.2821,1.7112,0.0408
16.9400,0.2825,1.7154,0.0409
16.9600,0.2829,1.7193,0.0410
16.9800,0.2832,1.7226,0.0411
17.0000,0.2835,1.7255,0.0412
17.0200,0.2838,1.7282,0.0412
17.0400,0.2841,1.7303,0.0412
17.0600,0.2844,1.7326,0.0413
17.0800,0.2846,1.7346,0.0414
17.1000,0.2848,1.7366,0.0414
17.1200,0.2852,1.7386,0.0415
17.1400,0.2855,1.7407,0.0415
17.1600,0.2859,1.7435,0.0416
17.1800,0.2863,1.7471,0.0417
17.2000,0.2867,1.7510,0.0418
17.2200,0.2872,1.7553,0.0419
17.2400,0.2876,1.7595,0.0420
17.2600,0.2879,1.7629,0.0420
17.2800,0.2882,1.7659,0.0421
17.3000,0.2885,1.7685,0.0421
17.3200,0.2888,1.7710,0.0422
17.3400,0.2891,1.7733,0.0423
17.3600,0.2893,1.7755,0.0423
17.3800,0.2896,1.7778,0.0424
17.4000,0.2899,1.7800,0.0424
17.4200,0.2901,1.7823,0.0425
17.4400,0.2905,1.7848,0.0425
17.4600,0.2908,1.7872,0.0426
17.4800,0.2912,1.7900,0.0427
17.5000,0.2916,1.7934,0.0428
17.5200,0.2920,1.7974,0.0428
17.5400,0.2924,1.8017,0.0429
17.5600,0.2929,1.8058,0.0430
17.5800,0.2932,1.8094,0.0431
17.6000,0.2936,1.8128,0.0432
17.6200,0.2938,1.8156,0.0433
17.6400,0.2942,1.8180,0.0434
17.6600,0.2944,1.8202,0.0434
17.6800,0.2947,1.8225,0.0434
17.7000,0.2949,1.8247,0.0435
17.7200,0.2952,1.8267,0.0435
17.7400,0.2955,1.8287,0.0436
17.7600,0.2958,1.8311,0.0436
17.7800,0.2962,1.8342,0.0437
17.8000,0.2966,1.8380,0.0438
17.8200,0.2971,1.8421,0.0439
17.8400,0.2975,1.8462,0.0440
17.8600,0.2978,1.8501,0.0441
17.8800,0.2982,1.8535,0.0441
17.9000,0.2985,1.8565,0.0442
17.9200,0.2988,1.8592,0.0443
17.9400,0.2991,1.8618,0.0443
17.9600,0.2994,1.8641,0.0444
17.9800,0.2997,1.8667,0.0445
18.0000,0.2999,1.8691,0.0445
18.0200,0.3002,1.8713,0.0445
18.0400,0.3005,1.8735,0.0446
18.0600,0.3008,1.8757,0.0447
18.0800,0.3011,1.8785,0.0448
18.1000,0.3016,1.8815,0.0448
18.1200,0.3020,1.8852,0.0449
18.1400,0.3024,1.8894,0.0450
18.1600,0.3028,1.8935,0.0451
18.1800,0.3032,1.8972,0.0452
18.2000,0.3036,1.9007,0.0452
18.2200,0.3039,1.9039,0.0453
18.2400,0.3042,1.9067,0.0454
18.2600,0.3044,1.9091,0.0454
18.2800,0.3047,1.9113,0.0455
18.3000,0.3050,1.9135,0.0456
18.3200,0.3052,1.9155,0.0456
18.3400,0.3055,1.9173,0.0456
18.3600,0.3058,1.9195,0.0456
18.3800,0.3061,1.9221,0.0457
18.4000,0.3065,1.9255,0.0458
18.4200,0.3070,1.9294,0.0459
18.4400,0.3074,1.9336,0.0460
18.4600,0.3078,1.9380,0.0461
18.4800,0.3081,1.9419,0.0462
18.5000,0.3085,1.9452,0.0463
18.5200,0.3088,1.9483,0.0463
18.5400,0.3091,1.9510,0.0464
18.5600,0.3094,1.9535,0.0464
18.5800,0.3097,1.9562,0.0465
18.6000,0.3100,1.9586,0.0466
18.6200,0.3103,1.9609,0.0467
18.6400,0.3105,1.9632,0.0467
18.6600,0.3108,1.9653,0.0468
18.6800,0.3111,1.9676,0.0468
18.7000,0.3115,1.9701,0.0469
18.7200,0.3119,1.9736,0.0469
18.7400,0.3124,1.9777,0.0470
18.7600,0.3128,1.9819,0.0471
18.7800,0.3132,1.9861,0.0473
18.8000,0.3136,1.9899,0.0474
18.8200,0.3139,1.9935,0.0474
18.8400,0.3142,1.9965,0.0475
18.8600,0.3145,1.9992,0.0476
18.8800,0.3147,2.0015,0.0476
18.9000,0.3150,2.0037,0.0477
18.9200,0.3152,2.0057,0.0477
18.9400,0.3155,2.0077,0.0477
18.9600,0.3157,2.0099,0.0477
18.9800,0.3161,2.0125,0.0478
19.0000,0.3164,2.0152,0.0479
19.0200,0.3169,2.0185,0.0480
19.0400,0.3173,2.0225,0.0480
19.0600,0.3177,2.0269,0.0482
19.0800,0.3181,2.0311,0.0483
19.1000,0.3185,2.0349,0.0484
19.1200,0.3188,2.0381,0.0484
19.1400,0.3191,2.0410,0.0485
19.1600,0.3194,2.0440,0.0486
19.1800,0.3197,2.0468,0.0486
19.2000,0.3200,2.0493,0.0487
19.2200,0.3203,2.0516,0.0487
19.2400,0.3206,2.0539,0.0488
19.2600,0.3208,2.0561,0.0488
19.2800,0.3211,2.0583,0.0489
19.3000,0.3215,2.0608,0.0490
19.3200,0.3219,2.0639,0.0490
19.3400,0.3223,2.0675,0.0491
19.3600,0.3227,2.0717,0.0492
19.3800,0.3231,2.0760,0.0493
19.4000,0.3235,2.0803,0.0494
19.4200,0.3238,2.0840,0.0495
19.4400,0.3242,2.0870,0.0496
19.4600,0.3244,2.0897,0.0496
19.4800,0.3247,2.0921,0.0497
19.5000,0.3250,2.0943,0.0498
19.5200,0.3253,2.0968,0.0498
19.5400,0.3256,2.0991,0.0499
19.5600,0.3258,2.1014,0.0499
19.5800,0.3261,2.1039,0.0499
19.6000,0.3264,2.1063,0.0500
19.6200,0.3268,2.1093,0.0500
19.6400,0.3273,2.1130,0.0501
19.6600,0.3277,2.1173,0.0502
19.6800,0.3281,2.1218,0.0503
19.7000,0.3285,2.1261,0.0505
19.7200,0.3289,2.1298,0.0506
19.7400,0.3292,2.1328,0.0506
19.7600,0.3295,2.1358,0.0507
19.7800,0.3298,2.1387,0.0508
19.8000,0.3301,2.1416,0.0508
19.8200,0.3304,2.1438,0.0509
19.8400,0.3306,2.1458,0.0509
19.8600,0.3309,2.1481,0.0510
19.8800,0.3312,2.1505,0.0510
19.9000,0.3315,2.1528,0.0511
19.9200,0.3318,2.1556,0.0511
19.9400,0.3322,2.1592,0.0512
19.9600,0.3326,2.1632,0.0513
19.9800,0.3331,2.1674,0.0514
20.0000,0.3335,2.1716,0.0515
20.0200,0.3338,2.1756,0.0516
20.0400,0.3342,2.1791,0.0517
20.0600,0.3345,2.1822,0.0517
20.0800,0.3348,2.1851,0.0518
20.1000,0.3351,2.1879,0.0519
20.1200,0.3353,2.1903,0.0519
20.1400,0.3356,2.1925,0.0519
20.1600,0.3359,2.1947,0.0520
20.1800,0.3362,2.1971,0.0521
20.2000,0.3364,2.1993,0.0522
20.2200,0.3368,2.2020,0.0522
20.2400,0.3372,2.2052,0.0523
20.2600,0.3377,2.2094,0.0524
20.2800,0.3381,2.2141,0.0525
20.3000,0.3385,2.2187,0.0526
20.3200,0.3389,2.2228,0.0526
20.3400,0.3392,2.2263,0.0527
20.3600,0.3395,2.2295,0.0528
20.3800,0.3399,2.2324,0.0529
20.4000,0.3401,2.2349,0.0529
20.4200,0.3404,2.2374,0.0530
20.4400,0.3407,2.2398,0.0531
20.4600,0.3409,2.2422,0.0531
20.4800,0.3412,2.2446,0.0531
20.5000,0.3415,2.2468,0.0532
20.5200,0.3418,2.2493,0.0532
20.5400,0.3422,2.2523,0.0533
20.5600,0.3425,2.2558,0.0534
20.5800,0.3430,2.2599,0.0535
20.6000,0.3434,2.2644,0.0536
20.6200,0.3438,2.2687,0.0537
20.6400,0.3441,2.2727,0.0538
20.6600,0.3445,2.2761,0.0539
20.6800,0.3448,2.2792,0.0540
20.7000,0.3451,2.2820,0.0540
20.7200,0.3454,2.2846,0.0541
20.7400,0.3457,2.2872,0.0542
20.7600,0.3459,2.2895,0.0542
20.7800,0.3462,2.2917,0.0542
20.8000,0.3465,2.2938,0.0543
20.8200,0.3468,2.2963,0.0543
20.8400,0.3472,2.2993,0.0544
20.8600,0.3476,2.3030,0.0545
20.8800,0.3481,2.3075,0.0546
20.9000,0.3485,2.3124,0.0547
20.9200,0.3489,2.3169,0.0548
20.9400,0.3492,2.3207,0.0549
20.9600,0.3496,2.3238,0.0550
20.9800,0.3499,2.3268,0.0550
21.0000,0.3502,2.3297,0.0550
21.0200,0.3505,2.3323,0.0551
21.0400,0.3507,2.3347,0.0552
21.0600,0.3509,2.3370,0.0552
21.0800,0.3512,2.3391,0.0553
21.1000,0.3515,2.3413,0.0553
21.1200,0.3517,2.3438,0.0554
21.1400,0.3521,2.3465,0.0554
21.1600,0.3525,2.3495,0.0555
21.1800,0.3529,2.3532,0.0556
21.2000,0.3534,2.3576,0.0557
21.2200,0.3538,2.3622,0.0558
21.2400,0.3542,2.3665,0.0559
21.2600,0.3545,2.3704,0.0560
21.2800,0.3549,2.3737,0.0561
21.3000,0.3552,2.3768,0.0561
21.3200,0.3554,2.3797,0.0562
21.3400,0.3557,2.3822,0.0563
21.3600,0.3560,2.3845,0.0564
21.3800,0.3562,2.3868,0.0564
21.4000,0.3565,2.3890,0.0564
21.4200,0.3568,2.3914,0.0564
21.4400,0.3572,2.3942,0.0565
21.4600,0.3575,2.3976,0.0566
21.4800,0.3580,2.4016,0.0567
21.5000,0.3584,2.4061,0.0568
21.5200,0.3589,2.4107,0.0569
21.5400,0.3592,2.4149,0.0570
21.5600,0.3595,2.4183,0.0571
21.5800,0.3598,2.4211,0.0572
21.6000,0.3602,2.4237,0.0572
21.6200,0.3604,2.4265,0.0573
21.6400,0.3607,2.4291,0.0573
21.6600,0.3610,2.4317,0.0574
21.6800,0.3612,2.4340,0.0575
21.7000,0.3615,2.4364,0.0575
21.7200,0.3618,2.4389,0.0575
21.7400,0.3621,2.4415,0.0576
21.7600,0.3624,2.4443,0.0576
21.7800,0.3628,2.4477,0.0577
21.8000,0.3633,2.4517,0.0579
21.8200,0.3637,2.4562,0.0579
21.8400,0.3641,2.4606,0.0580
21.8600,0.3645,2.4650,0.0581
21.8800,0.3649,2.4691,0.0582
21.9000,0.3652,2.4723,0.0583
21.9200,0.3655,2.4751,0.0584
21.9400,0.3657,2.4778,0.0584
21.9600,0.3660,2.4804,0.0585
21.9800,0.3663,2.4828,0.0585
22.0000,0.3665,2.4849,0.0585
22.0200,0.3668,2.4870,0.0586
22.0400,0.3671,2.4894,0.0587
22.0600,0.3675,2.4923,0.0587
22.0800,0.3679,2.4961,0.0588
22.1000,0.3684,2.5005,0.0589
22.1200,0.3688,2.5052,0.0591
22.1400,0.3692,2.5093,0.0592
22.1600,0.3695,2.5131,0.0592
22.1800,0.3698,2.5163,0.0593
22.2000,0.3701,2.5194,0.0593
22.2200,0.3704,2.5223,0.0594
22.2400,0.3707,2.5249,0.0594
22.2600,0.3710,2.5275,0.0595
22.2800,0.3713,2.5300,0.0596
22.3000,0.3716,2.5325,0.0596
22.3200,0.3718,2.5351,0.0597
22.3400,0.3721,2.5376,0.0597
22.3600,0.3724,2.5404,0.0598
22.3800,0.3728,2.5436,0.0599
22.4000,0.3732,2.5474,0.0599
22.4200,0.3737,2.5519,0.0600
22.4400,0.3741,2.5567,0.0601
22.4600,0.3745,2.5613,0.0603
22.4800,0.3749,2.5656,0.0604
22.5000,0.3752,2.5691,0.0605
22.5200,0.3755,2.5721,0.0605
22.5400,0.3758,2.5748,0.0606
22.5600,0.3761,2.5773,0.0606
22.5800,0.3763,2.5795,0.0607
22.6000,0.3766,2.5819,0.0607
22.6200,0.3769,2.5843,0.0607
22.6400,0.3771,2.5865,0.0608
22.6600,0.3775,2.5890,0.0609
22.6800,0.3778,2.5921,0.0609
22.7000,0.3783,2.5959,0.0611
22.7200,0.3787,2.6004,0.0611
22.7400,0.3791,2.6050,0.0612
22.7600,0.3795,2.6092,0.0614
22.7800,0.3798,2.6129,0.0614
22.8000,0.3801,2.6163,0.0615
22.8200,0.3805,2.6195,0.0616
22.8400,0.3808,2.6225,0.0616
22.8600,0.3811,2.6254,0.0617
22.8800,0.3813,2.6283,0.0617
22.9000,0.3816,2.6308,0.0618
22.9200,0.3819,2.6331,0.0618
22.9400,0.3821,2.6354,0.0619
22.9600,0.3824,2.6381,0.0619
22.9800,0.3828,2.6411,0.0620
23.0000,0.3832,2.6446,0.0621
23.0200,0.3837,2.6486,0.0622
23.0400,0.3841,2.6532,0.0623
23.0600,0.3845,2.6580,0.0624
23.0800,0.3849,2.6626,0.0625
23.1000,0.3852,2.6667,0.0626
23.1200,0.3856,2.6701,0.0627
23.1400,0.3858,2.6729,0.0627
23.1600,0.3861,2.6752,0.0628
23.1800,0.3864,2.6776,0.0628
23.2000,0.3866,2.6799,0.0629
23.2200,0.3869,2.6822,0.0630
23.2400,0.3872,2.6846,0.0630
23.2600,0.3874,2.6872,0.0631
23.2800,0.3878,2.6901,0.0631
23.3000,0.3882,2.6935,0.0632
23.3200,0.3887,2.6976,0.0633
23.3400,0.3891,2.7022,0.0634
23.3600,0.3895,2.7071,0.0635
23.3800,0.3898,2.7115,0.0636
23.4000,0.3902,2.7150,0.0637
23.4200,0.3905,2.7181,0.0638
23.4400,0.3908,2.7210,0.0638
23.4600,0.3911,2.7239,0.0639
23.4800,0.3914,2.7269,0.0639
23.5000,0.3917,2.7294,0.0640
23.5200,0.3919,2.7318,0.0640
23.5400,0.3922,2.7342,0.0641
23.5600,0.3925,2.7365,0.0641
23.5800,0.3928,2.7390,0.0642
23.6000,0.3932,2.7422,0.0643
23.6200,0.3936,2.7460,0.0644
23.6400,0.3940,2.7504,0.0644
23.6600,0.3944,2.7552,0.0645
23.6800,0.3949,2.7598,0.0647
23.7000,0.3952,2.7640,0.0648
23.7200,0.3955,2.7674,0.0649
23.7400,0.3958,2.7704,0.0649
23.7600,0.3961,2.7733,0.0649
23.7800,0.3964,2.7758,0.0650
23.8000,0.3966,2.7782,0.0650
23.8200,0.3969,2.7806,0.0651
23.8400,0.3972,2.7833,0.0651
23.8600,0.3974,2.7857,0.0652
23.8800,0.3978,2.7883,0.0652
23.9000,0.3981,2.7915,0.0653
23.9200,0.3986,2.7951,0.0654
23.9400,0.3991,2.7994,0.0655
23.9600,0.3994,2.8042,0.0656
23.9800,0.3999,2.8088,0.0657
24.0000,0.4002,2.8129,0.0658
24.0200,0.4005,2.8163,0.0659
24.0400,0.4008,2.8194,0.0659
24.0600,0.4011,2.8223,0.0660
24.0800,0.4014,2.8250,0.0661
24.1000,0.4017,2.8275,0.0661
24.1200,0.4019,2.8300,0.0662
24.1400,0.4022,2.8326,0.0662
24.1600,0.4025,2.8351,0.0663
24.1800,0.4028,2.8375,0.0663
24.2000,0.4031,2.8401,0.0664
24.2200,0.4036,2.8435,0.0665
24.2400,0.4039,2.8475,0.0665
24.2600,0.4044,2.8521,0.0666
24.2800,0.4048,2.8570,0.0668
24.3000,0.4052,2.8614,0.0669
24.3200,0.4055,2.8653,0.0670
24.3400,0.4058,2.8686,0.0670
24.3600,0.4061,2.8715,0.0671
24.3800,0.4064,2.8743,0.0671
24.4000,0.4067,2.8768,0.0672
24.4200,0.4069,2.8793,0.0672
24.4400,0.4072,2.8818,0.0673
24.4600,0.4075,2.8843,0.0674
24.4800,0.4077,2.8867,0.0674
24.5000,0.4081,2.8893,0.0675
24.5200,0.4085,2.8926,0.0675
24.5400,0.4089,2.8965,0.0676
24.5600,0.4094,2.9011,0.0677
24.5800,0.4098,2.9057,0.0678
24.6000,0.4102,2.9102,0.0680
24.6200,0.4105,2.9143,0.0680
24.6400,0.4108,2.9178,0.0681
24.6600,0.4112,2.9206,0.0682
24.6800,0.4115,2.9233,0.0682
24.7000,0.4117,2.9262,0.0683
24.7200,0.4120,2.9290,0.0683
24.7400,0.4123,2.9317,0.0684
24.7600,0.4126,2.9343,0.0685
24.7800,0.4128,2.9367,0.0685
24.8000,0.4131,2.9391,0.0686
24.8200,0.4135,2.9418,0.0686
24.8400,0.4138,2.9450,0.0687
24.8600,0.4143,2.9493,0.0688
24.8800,0.4147,2.9538,0.0689
24.9000,0.4151,2.9583,0.0690
24.9200,0.4155,2.9626,0.0691
24.9400,0.4158,2.9666,0.0692
24.9600,0.4161,2.9700,0.0692
24.9800,0.4165,2.9729,0.0693
25.0000,0.4167,2.9757,0.0694
25.0200,0.4170,2.9785,0.0694
25.0400,0.4173,2.9812,0.0695
25.0600,0.4175,2.9834,0.0696
25.0800,0.4178,2.9858,0.0696
25.1000,0.4181,2.9885,0.0697
25.1200,0.4185,2.9917,0.0697
25.1400,0.4189,2.9955,0.0698
25.1600,0.4194,2.9997,0.0699
25.1800,0.4198,3.0044,0.0700
25.2000,0.4202,3.0090,0.0701
25.2200,0.4205,3.0134,0.0702
25.2400,0.4209,3.0171,0.0703
25.2600,0.4212,3.0203,0.0704
25.2800,0.4215,3.0232,0.0705
25.3000,0.4218,3.0259,0.0705
25.3200,0.4220,3.0286,0.0705
25.3400,0.4223,3.0311,0.0706
25.3600,0.4226,3.0336,0.0707
25.3800,0.4228,3.0360,0.0707
25.4000,0.4231,3.0385,0.0707
25.4200,0.4234,3.0413,0.0708
25.4400,0.4238,3.0446,0.0709
25.4600,0.4242,3.0483,0.0710
25.4800,0.4247,3.0528,0.0711
25.5000,0.4251,3.0575,0.0712
25.5200,0.4255,3.0622,0.0713
25.5400,0.4258,3.0662,0.0713
25.5600,0.4262,3.0696,0.0715
25.5800,0.4265,3.0731,0.0715
25.6000,0.4268,3.0761,0.0716
25.6200,0.4271,3.0789,0.0717
25.6400,0.4273,3.0814,0.0717
25.6600,0.4276,3.0839,0.0718
25.6800,0.4279,3.0863,0.0718
25.7000,0.4281,3.0887,0.0719
25.7200,0.4285,3.0913,0.0719
25.7400,0.4289,3.0947,0.0719
25.7600,0.4293,3.0988,0.0720
25.7800,0.4297,3.1033,0.0722
25.8000,0.4302,3.1084,0.0723
25.8200,0.4306,3.1130,0.0724
25.8400,0.4309,3.1170,0.0725
25.8600,0.4312,3.1202,0.0725
25.8800,0.4315,3.1230,0.0726
25.9000,0.4317,3.1256,0.0727
25.9200,0.4321,3.1283,0.0727
25.9400,0.4323,3.1309,0.0728
25.9600,0.4326,3.1334,0.0728
25.9800,0.4329,3.1359,0.0729
26.0000,0.4331,3.1385,0.0729
26.0200,0.4334,3.1411,0.0730
26.0400,0.4338,3.1441,0.0731
26.0600,0.4342,3.1476,0.0732
26.0800,0.4346,3.1517,0.0732
26.1000,0.4351,3.1564,0.0734
26.1200,0.4355,3.1614,0.0735
26.1400,0.4359,3.1661,0.0735
26.1600,0.4362,3.1702,0.0736
26.1800,0.4366,3.1738,0.0737
26.2000,0.4368,3.1770,0.0738
26.2200,0.4371,3.1798,0.0738
26.2400,0.4374,3.1824,0.0739
26.2600,0.4376,3.1848,0.0739
26.2800,0.4379,3.1872,0.0740
26.3000,0.4382,3.1896,0.0740
26.3200,0.4385,3.1922,0.0741
26.3400,0.4389,3.1951,0.0742
26.3600,0.4392,3.1986,0.0743
26.3800,0.4397,3.2026,0.0743
26.4000,0.4401,3.2072,0.0745
26.4200,0.4405,3.2118,0.0746
26.4400,0.4408,3.2158,0.0747
26.4600,0.4412,3.2194,0.0747
26.4800,0.4415,3.2226,0.0747
26.5000,0.4418,3.2258,0.0748
26.5200,0.4421,3.2288,0.0749
26.5400,0.4423,3.2315,0.0750
26.5600,0.4426,3.2341,0.0750
26.5800,0.4429,3.2367,0.0750
26.6000,0.4432,3.2392,0.0751
26.6200,0.4435,3.2418,0.0752
26.6400,0.4438,3.2445,0.0753
26.6600,0.4442,3.2476,0.0753
26.6800,0.4446,3.2516,0.0754
26.7000,0.4450,3.2561,0.0755
26.7200,0.4454,3.2610,0.0756
26.7400,0.4458,3.2655,0.0757
26.7600,0.4462,3.2696,0.0758
26.7800,0.4465,3.2734,0.0759
26.8000,0.4468,3.2767,0.0760
26.8200,0.4471,3.2798,0.0761
26.8400,0.4474,3.2824,0.0761
26.8600,0.4476,3.2849,0.0761
26.8800,0.4479,3.2871,0.0762
26.9000,0.4482,3.2894,0.0762
26.9200,0.4484,3.2918,0.0763
26.9400,0.4488,3.2945,0.0764
26.9600,0.4491,3.2974,0.0764
26.9800,0.4496,3.3012,0.0765
27.0000,0.4500,3.3056,0.0765
27.0200,0.4504,3.3104,0.0767
27.0400,0.4508,3.3151,0.0768
27.0600,0.4511,3.3191,0.0769
27.0800,0.4514,3.3228,0.0770
27.1000,0.4518,3.3260,0.0770
27.1200,0.4521,3.3287,0.0771
27.1400,0.4524,3.3316,0.0771
27.1600,0.4527,3.3345,0.0772
27.1800,0.4529,3.3372,0.0773
27.2000,0.4532,3.3398,0.0773
27.2200,0.4535,3.3422,0.0773
27.2400,0.4538,3.3447,0.0774
27.2600,0.4541,3.3475,0.0775
27.2800,0.4545,3.3508,0.0776
27.3000,0.4550,3.3548,0.0776
27.3200,0.4554,3.3594,0.0777
27.3400,0.4558,3.3641,0.0778
27.3600,0.4562,3.3684,0.0779
27.3800,0.4565,3.3725,0.0780
27.4000,0.4569,3.3762,0.0781
27.4200,0.4572,3.3793,0.0782
27.4400,0.4574,3.3821,0.0782
27.4600,0.4577,3.3845,0.0783
27.4800,0.4579,3.3867,0.0784
27.5000,0.4582,3.3890,0.0784
27.5200,0.4585,3.3915,0.0784
27.5400,0.4588,3.3939,0.0785
27.5600,0.4591,3.3969,0.0785
27.5800,0.4595,3.4003,0.0786
27.6000,0.4599,3.4041,0.0787
27.6200,0.4604,3.4086,0.0788
27.6400,0.4608,3.4135,0.0789
27.6600,0.4611,3.4181,0.0790
27.6800,0.4615,3.4220,0.0791
27.7000,0.4618,3.4255,0.0792
27.7200,0.4622,3.4286,0.0792
27.7400,0.4624,3.4314,0.0793
27.7600,0.4627,3.4343,0.0794
27.7800,0.4630,3.4370,0.0794
27.8000,0.4633,3.4395,0.0795
27.8200,0.4636,3.4420,0.0795
27.8400,0.4638,3.4445,0.0796
27.8600,0.4641,3.4470,0.0796
27.8800,0.4645,3.4501,0.0797
27.9000,0.4649,3.4538,0.0798
27.9200,0.4654,3.4582,0.0799
27.9400,0.4658,3.4629,0.0799
27.9600,0.4662,3.4675,0.0801
27.9800,0.4665,3.4717,0.0802
28.0000,0.4669,3.4756,0.0803
28.0200,0.4671,3.4790,0.0803
28.0400,0.4674,3.4819,0.0804
28.0600,0.4677,3.4845,0.0804
28.0800,0.4680,3.4871,0.0805
28.1000,0.4682,3.4895,0.0806
28.1200,0.4685,3.4919,0.0806
28.1400,0.4688,3.4946,0.0807
28.1600,0.4691,3.4973,0.0807
28.1780,0.4694,3.5001,0.0808