File: Modulus_Al_3.csv
Time,Displacement,Force,Strain 1
(s),(mm),(kN),(%)
0.0000,0.0000,0.0000,0.0001
0.0400,0.0001,0.0000,0.0001
0.0800,0.0007,0.0002,0.0001
0.1200,0.0015,0.0002,0.0002
0.1600,0.0022,0.0003,0.0003
0.2000,0.0032,0.0005,0.0004
0.2400,0.0041,0.0007,0.0005
0.2800,0.0049,0.0009,0.0006
0.3200,0.0055,0.0013,0.0008
0.3600,0.0060,0.0019,0.0010
0.4000,0.0065,0.0022,0.0011
0.4400,0.0072,0.0026,0.0012
0.4800,0.0080,0.0028,0.0014
0.5200,0.0088,0.0032,0.0015
0.5600,0.0096,0.0034,0.0016
0.6000,0.0102,0.0037,0.0017
0.6400,0.0108,0.0037,0.0018
0.6800,0.0113,0.0040,0.0019
0.7200,0.0118,0.0041,0.0020
0.7600,0.0125,0.0047,0.0020
0.8000,0.0133,0.0056,0.0020
0.8400,0.0142,0.0069,0.0021
0.8800,0.0149,0.0081,0.0021
0.9200,0.0155,0.0094,0.0022
0.9600,0.0161,0.0104,0.0022
1.0000,0.0166,0.0116,0.0023
1.0400,0.0172,0.0126,0.0023
1.0800,0.0179,0.0142,0.0024
1.1200,0.0189,0.0161,0.0025
1.1600,0.0196,0.0180,0.0026
1.2000,0.0202,0.0192,0.0027
1.2400,0.0208,0.0207,0.0029
1.2800,0.0213,0.0221,0.0030
1.3200,0.0219,0.0231,0.0032
1.3600,0.0225,0.0246,0.0034
1.4000,0.0233,0.0263,0.0036
1.4400,0.0242,0.0286,0.0039
1.4800,0.0249,0.0308,0.0042
1.5200,0.0256,0.0325,0.0044
1.5600,0.0261,0.0337,0.0046
1.6000,0.0266,0.0353,0.0047
1.6400,0.0272,0.0367,0.0049
1.6800,0.0279,0.0384,0.0051
1.7200,0.0288,0.0407,0.0054
1.7600,0.0296,0.0431,0.0057
1.8000,0.0303,0.0452,0.0060
1.8400,0.0309,0.0470,0.0062
1.8800,0.0314,0.0486,0.0064
1.9200,0.0319,0.0499,0.0065
1.9600,0.0325,0.0516,0.0067
2.0000,0.0333,0.0538,0.0069
2.0400,0.0341,0.0565,0.0072
2.0800,0.0349,0.0590,0.0074
2.1200,0.0356,0.0614,0.0076
2.1600,0.0361,0.0630,0.0078
2.2000,0.0366,0.0649,0.0080
2.2400,0.0372,0.0666,0.0081
2.2800,0.0379,0.0685,0.0082
2.3200,0.0387,0.0710,0.0084
2.3600,0.0395,0.0740,0.0087
2.4000,0.0403,0.0765,0.0088
2.4400,0.0409,0.0787,0.0090
2.4800,0.0415,0.0805,0.0091
2.5200,0.0420,0.0819,0.0091
2.5600,0.0425,0.0835,0.0093
2.6000,0.0432,0.0851,0.0094
2.6400,0.0440,0.0873,0.0095
2.6800,0.0448,0.0897,0.0097
2.7200,0.0456,0.0916,0.0098
2.7600,0.0462,0.0929,0.0098
2.8000,0.0467,0.0938,0.0099
2.8400,0.0472,0.0948,0.0100
2.8800,0.0478,0.0960,0.0100
2.9200,0.0486,0.0979,0.0101
2.9600,0.0495,0.1005,0.0103
3.0000,0.0502,0.1027,0.0104
3.0400,0.0509,0.1046,0.0104
3.0800,0.0515,0.1061,0.0105
3.1200,0.0520,0.1073,0.0105
3.1600,0.0526,0.1087,0.0106
3.2000,0.0532,0.1099,0.0107
3.2400,0.0540,0.1118,0.0107
3.2800,0.0548,0.1144,0.0108
3.3200,0.0556,0.1163,0.0109
3.3600,0.0562,0.1176,0.0109
3.4000,0.0567,0.1184,0.0109
3.4400,0.0573,0.1192,0.0108
3.4800,0.0579,0.1202,0.0108
3.5200,0.0586,0.1215,0.0109
3.5600,0.0595,0.1234,0.0109
3.6000,0.0603,0.1256,0.0110
3.6400,0.0609,0.1269,0.0111
3.6800,0.0615,0.1280,0.0111
3.7200,0.0620,0.1287,0.0111
3.7600,0.0626,0.1297,0.0112
3.8000,0.0632,0.1306,0.0112
3.8400,0.0639,0.1321,0.0113
3.8800,0.0648,0.1343,0.0114
3.9200,0.0656,0.1362,0.0115
3.9600,0.0663,0.1377,0.0116
4.0000,0.0668,0.1384,0.0116
4.0400,0.0673,0.1392,0.0117
4.0800,0.0679,0.1404,0.0117
4.1200,0.0686,0.1420,0.0118
4.1600,0.0694,0.1443,0.0120
4.2000,0.0702,0.1469,0.0122
4.2400,0.0709,0.1487,0.0123
4.2800,0.0715,0.1501,0.0123
4.3200,0.0721,0.1509,0.0124
4.3600,0.0726,0.1518,0.0124
4.4000,0.0732,0.1528,0.0125
4.4400,0.0739,0.1540,0.0126
4.4800,0.0747,0.1558,0.0127
4.5200,0.0756,0.1583,0.0129
4.5600,0.0763,0.1599,0.0130
4.6000,0.0768,0.1608,0.0130
4.6400,0.0774,0.1615,0.0131
4.6800,0.0779,0.1627,0.0132
4.7200,0.0785,0.1648,0.0134
4.7600,0.0793,0.1677,0.0135
4.8000,0.0802,0.1713,0.0138
4.8400,0.0809,0.1744,0.0140
4.8800,0.0815,0.1768,0.0142
4.9200,0.0821,0.1792,0.0144
4.9600,0.0827,0.1810,0.0145
5.0000,0.0832,0.1828,0.0146
5.0400,0.0838,0.1853,0.0148
5.0800,0.0847,0.1882,0.0150
5.1200,0.0856,0.1917,0.0153
5.1600,0.0863,0.1950,0.0155
5.2000,0.0869,0.1975,0.0157
5.2400,0.0874,0.1996,0.0158
5.2800,0.0879,0.2014,0.0159
5.3200,0.0885,0.2031,0.0160
5.3600,0.0892,0.2056,0.0162
5.4000,0.0902,0.2090,0.0164
5.4400,0.0909,0.2124,0.0166
5.4800,0.0916,0.2151,0.0168
5.5200,0.0921,0.2172,0.0170
5.5600,0.0927,0.2191,0.0171
5.6000,0.0933,0.2211,0.0172
5.6400,0.0939,0.2232,0.0174
5.6800,0.0947,0.2257,0.0176
5.7200,0.0955,0.2293,0.0178
5.7600,0.0963,0.2328,0.0181
5.8000,0.0969,0.2353,0.0183
5.8400,0.0974,0.2373,0.0184
5.8800,0.0980,0.2390,0.0185
5.9200,0.0985,0.2408,0.0187
5.9600,0.0992,0.2432,0.0188
6.0000,0.1001,0.2464,0.0191
6.0400,0.1009,0.2502,0.0194
6.0800,0.1016,0.2530,0.0196
6.1200,0.1022,0.2553,0.0198
6.1600,0.1027,0.2574,0.0199
6.2000,0.1033,0.2591,0.0200
6.2400,0.1038,0.2610,0.0201
6.2800,0.1046,0.2634,0.0203
6.3200,0.1054,0.2670,0.0206
6.3600,0.1062,0.2705,0.0209
6.4000,0.1069,0.2734,0.0211
6.4400,0.1075,0.2755,0.0212
6.4800,0.1080,0.2775,0.0214
6.5200,0.1085,0.2792,0.0215
6.5600,0.1092,0.2815,0.0217
6.6000,0.1100,0.2845,0.0219
6.6400,0.1109,0.2884,0.0222
6.6800,0.1116,0.2916,0.0225
6.7200,0.1122,0.2941,0.0226
6.7600,0.1128,0.2963,0.0227
6.8000,0.1134,0.2982,0.0230
6.8400,0.1139,0.3004,0.0231
6.8800,0.1145,0.3026,0.0233
6.9200,0.1154,0.3058,0.0235
6.9600,0.1162,0.3097,0.0238
7.0000,0.1169,0.3130,0.0241
7.0400,0.1175,0.3156,0.0242
7.0800,0.1180,0.3177,0.0244
7.1200,0.1186,0.3198,0.0245
7.1600,0.1191,0.3217,0.0247
7.2000,0.1199,0.3248,0.0249
7.2400,0.1209,0.3287,0.0252
7.2800,0.1216,0.3330,0.0255
7.3200,0.1222,0.3355,0.0257
7.3600,0.1228,0.3378,0.0259
7.4000,0.1234,0.3401,0.0260
7.4400,0.1239,0.3420,0.0262
7.4800,0.1245,0.3442,0.0264
7.5200,0.1253,0.3474,0.0266
7.5600,0.1262,0.3512,0.0269
7.6000,0.1269,0.3551,0.0272
7.6400,0.1276,0.3583,0.0274
7.6800,0.1281,0.3604,0.0276
7.7200,0.1286,0.3625,0.0278
7.7600,0.1292,0.3646,0.0279
7.8000,0.1299,0.3674,0.0281
7.8400,0.1308,0.3713,0.0284
7.8800,0.1316,0.3755,0.0288
7.9200,0.1323,0.3790,0.0290
7.9600,0.1329,0.3815,0.0292
8.0000,0.1334,0.3838,0.0294
8.0400,0.1339,0.3862,0.0296
8.0800,0.1345,0.3886,0.0298
8.1200,0.1352,0.3914,0.0300
8.1600,0.1361,0.3957,0.0303
8.2000,0.1369,0.4002,0.0306
8.2400,0.1376,0.4039,0.0309
8.2800,0.1382,0.4065,0.0311
8.3200,0.1387,0.4088,0.0313
8.3600,0.1392,0.4110,0.0315
8.4000,0.1399,0.4138,0.0316
8.4400,0.1407,0.4176,0.0319
8.4800,0.1416,0.4221,0.0323
8.5200,0.1422,0.4260,0.0326
8.5600,0.1429,0.4290,0.0328
8.6000,0.1434,0.4315,0.0330
8.6400,0.1439,0.4342,0.0331
8.6800,0.1445,0.4366,0.0333
8.7200,0.1452,0.4395,0.0335
8.7600,0.1460,0.4437,0.0339
8.8000,0.1469,0.4482,0.0342
8.8400,0.1476,0.4524,0.0345
8.8800,0.1482,0.4556,0.0347
8.9200,0.1487,0.4583,0.0350
8.9600,0.1492,0.4607,0.0352
9.0000,0.1498,0.4634,0.0353
9.0400,0.1506,0.4667,0.0356
9.0800,0.1515,0.4711,0.0359
9.1200,0.1522,0.4758,0.0363
9.1600,0.1529,0.4795,0.0365
9.2000,0.1535,0.4824,0.0367
9.2400,0.1540,0.4851,0.0370
9.2800,0.1546,0.4878,0.0371
9.3200,0.1552,0.4905,0.0373
9.3600,0.1560,0.4941,0.0376
9.4000,0.1569,0.4989,0.0380
9.4400,0.1576,0.5035,0.0383
9.4800,0.1582,0.5070,0.0386
9.5200,0.1588,0.5099,0.0388
9.5600,0.1593,0.5122,0.0390
9.6000,0.1599,0.5147,0.0392
9.6400,0.1606,0.5181,0.0394
9.6800,0.1614,0.5226,0.0397
9.7200,0.1622,0.5275,0.0401
9.7600,0.1629,0.5314,0.0404
9.8000,0.1635,0.5349,0.0407
9.8400,0.1640,0.5378,0.0409
9.8800,0.1646,0.5405,0.0410
9.9200,0.1652,0.5434,0.0412
9.9600,0.1659,0.5468,0.0415
10.0000,0.1668,0.5515,0.0419
10.0400,0.1676,0.5567,0.0422
10.0800,0.1682,0.5606,0.0425
10.1200,0.1688,0.5635,0.0427
10.1600,0.1693,0.5662,0.0429
10.2000,0.1699,0.5688,0.0431
10.2400,0.1705,0.5719,0.0433
10.2800,0.1714,0.5760,0.0437
10.3200,0.1722,0.5811,0.0441
10.3600,0.1729,0.5858,0.0444
10.4000,0.1736,0.5893,0.0446
10.4400,0.1741,0.5925,0.0449
10.4800,0.1746,0.5953,0.0451
10.5200,0.1752,0.5978,0.0453
10.5600,0.1759,0.6011,0.0455
10.6000,0.1767,0.6056,0.0458
10.6400,0.1775,0.6107,0.0462
10.6800,0.1782,0.6151,0.0465
10.7200,0.1788,0.6185,0.0468
10.7600,0.1794,0.6214,0.0470
10.8000,0.1799,0.6242,0.0472
10.8400,0.1805,0.6272,0.0474
10.8800,0.1813,0.6311,0.0477
10.9200,0.1822,0.6361,0.0481
10.9600,0.1829,0.6410,0.0485
11.0000,0.1836,0.6451,0.0488
11.0400,0.1842,0.6485,0.0490
11.0800,0.1847,0.6512,0.0492
11.1200,0.1852,0.6538,0.0494
11.1600,0.1858,0.6568,0.0496
11.2000,0.1866,0.6607,0.0499
11.2400,0.1875,0.6656,0.0503
11.2800,0.1882,0.6702,0.0507
11.3200,0.1888,0.6739,0.0509
11.3600,0.1894,0.6769,0.0511
11.4000,0.1900,0.6794,0.0514
11.4400,0.1905,0.6820,0.0516
11.4800,0.1912,0.6854,0.0518
11.5200,0.1922,0.6898,0.0521
11.5600,0.1930,0.6951,0.0526
11.6000,0.1936,0.6990,0.0529
11.6400,0.1942,0.7023,0.0531
11.6800,0.1947,0.7052,0.0534
11.7200,0.1952,0.7074,0.0535
11.7600,0.1958,0.7102,0.0537
11.8000,0.1966,0.7137,0.0540
11.8400,0.1974,0.7184,0.0543
11.8800,0.1982,0.7235,0.0547
11.9200,0.1989,0.7276,0.0551
11.9600,0.1994,0.7307,0.0553
12.0000,0.2000,0.7334,0.0555
12.0400,0.2005,0.7358,0.0557
12.0800,0.2012,0.7389,0.0559
12.1200,0.2021,0.7433,0.0563
12.1600,0.2029,0.7484,0.0567
12.2000,0.2036,0.7526,0.0570
12.2400,0.2042,0.7560,0.0572
12.2800,0.2047,0.7589,0.0575
12.3200,0.2052,0.7614,0.0576
12.3600,0.2058,0.7642,0.0579
12.4000,0.2065,0.7676,0.0581
12.4400,0.2074,0.7720,0.0585
12.4800,0.2082,0.7772,0.0589
12.5200,0.2089,0.7820,0.0592
12.5600,0.2095,0.7853,0.0595
12.6000,0.2101,0.7880,0.0597
12.6400,0.2105,0.7904,0.0599
12.6800,0.2112,0.7935,0.0601
12.7200,0.2120,0.7971,0.0604
12.7600,0.2129,0.8025,0.0608
12.8000,0.2136,0.8071,0.0612
12.8400,0.2142,0.8105,0.0614
12.8800,0.2148,0.8136,0.0616
12.9200,0.2153,0.8165,0.0619
12.9600,0.2158,0.8191,0.0621
13.0000,0.2165,0.8222,0.0624
13.0400,0.2173,0.8265,0.0627
13.0800,0.2182,0.8316,0.0631
13.1200,0.2189,0.8365,0.0634
13.1600,0.2195,0.8401,0.0637
13.2000,0.2201,0.8432,0.0640
13.2400,0.2206,0.8457,0.0641
13.2800,0.2212,0.8485,0.0643
13.3200,0.2219,0.8519,0.0646
13.3600,0.2228,0.8571,0.0650
13.4000,0.2236,0.8620,0.0654
13.4400,0.2242,0.8659,0.0657
13.4800,0.2248,0.8694,0.0660
13.5200,0.2254,0.8721,0.0662
13.5600,0.2259,0.8748,0.0664
13.6000,0.2265,0.8778,0.0666
13.6400,0.2273,0.8818,0.0669
13.6800,0.2282,0.8869,0.0673
13.7200,0.2290,0.8920,0.0677
13.7600,0.2296,0.8960,0.0680
13.8000,0.2301,0.8990,0.0683
13.8400,0.2306,0.9016,0.0684
13.8800,0.2312,0.9042,0.0686
13.9200,0.2319,0.9076,0.0688
13.9600,0.2327,0.9120,0.0692
14.0000,0.2336,0.9173,0.0696
14.0400,0.2342,0.9219,0.0700
14.0800,0.2349,0.9255,0.0702
14.1200,0.2354,0.9285,0.0704
14.1600,0.2359,0.9316,0.0707
14.2000,0.2365,0.9342,0.0709
14.2400,0.2372,0.9377,0.0712
14.2800,0.2381,0.9426,0.0715
14.3200,0.2389,0.9479,0.0719
14.3600,0.2396,0.9524,0.0722
14.4000,0.2402,0.9555,0.0724
14.4400,0.2406,0.9581,0.0726
14.4800,0.2412,0.9609,0.0729
14.5200,0.2418,0.9637,0.0731
14.5600,0.2427,0.9681,0.0734
14.6000,0.2435,0.9735,0.0738
14.6400,0.2443,0.9785,0.0742
14.6800,0.2449,0.9822,0.0745
14.7200,0.2455,0.9856,0.0747
14.7600,0.2460,0.9884,0.0749
14.8000,0.2465,0.9914,0.0752
14.8400,0.2472,0.9945,0.0754
14.8800,0.2480,0.9989,0.0757
14.9200,0.2489,1.0044,0.0761
14.9600,0.2496,1.0089,0.0765
15.0000,0.2502,1.0124,0.0767
15.0400,0.2507,1.0155,0.0770
15.0800,0.2512,1.0181,0.0772
15.1200,0.2518,1.0210,0.0774
15.1600,0.2526,1.0249,0.0777
15.2000,0.2535,1.0301,0.0781
15.2400,0.2542,1.0354,0.0785
15.2800,0.2549,1.0394,0.0788
15.3200,0.2555,1.0429,0.0791
15.3600,0.2560,1.0459,0.0792
15.4000,0.2566,1.0486,0.0795
15.4400,0.2572,1.0515,0.0797
15.4800,0.2579,1.0555,0.0801
15.5200,0.2588,1.0607,0.0804
15.5600,0.2596,1.0659,0.0808
15.6000,0.2602,1.0700,0.0811
15.6400,0.2607,1.0733,0.0814
15.6800,0.2613,1.0761,0.0816
15.7200,0.2619,1.0792,0.0818
15.7600,0.2626,1.0826,0.0820
15.8000,0.2635,1.0875,0.0824
15.8400,0.2643,1.0929,0.0828
15.8800,0.2649,1.0975,0.0832
15.9200,0.2656,1.1011,0.0835
15.9600,0.2661,1.1044,0.0837
16.0000,0.2666,1.1071,0.0839
16.0400,0.2672,1.1097,0.0841
16.0800,0.2679,1.1133,0.0844
16.1200,0.2688,1.1184,0.0848
16.1600,0.2695,1.1236,0.0852
16.2000,0.2702,1.1281,0.0855
16.2400,0.2708,1.1319,0.0858
16.2800,0.2713,1.1347,0.0860
16.3200,0.2719,1.1375,0.0862
16.3600,0.2725,1.1408,0.0865
16.4000,0.2734,1.1453,0.0868
16.4400,0.2742,1.1510,0.0872
16.4800,0.2749,1.1557,0.0876
16.5200,0.2756,1.1595,0.0879
16.5600,0.2761,1.1628,0.0881
16.6000,0.2766,1.1657,0.0883
16.6400,0.2772,1.1686,0.0885
16.6800,0.2778,1.1720,0.0888
16.7200,0.2787,1.1767,0.0892
16.7600,0.2795,1.1822,0.0896
16.8000,0.2802,1.1872,0.0899
16.8400,0.2809,1.1909,0.0902
16.8800,0.2814,1.1940,0.0904
16.9200,0.2819,1.1966,0.0907
16.9600,0.2825,1.1998,0.0909
17.0000,0.2833,1.2041,0.0912
17.0400,0.2842,1.2093,0.0916
17.0800,0.2849,1.2145,0.0920
17.1200,0.2855,1.2185,0.0923
17.1600,0.2861,1.2217,0.0926
17.2000,0.2867,1.2250,0.0928
17.2400,0.2872,1.2277,0.0930
17.2800,0.2878,1.2311,0.0932
17.3200,0.2886,1.2355,0.0935
17.3600,0.2895,1.2410,0.0939
17.4000,0.2903,1.2461,0.0943
17.4400,0.2909,1.2504,0.0946
17.4800,0.2914,1.2534,0.0948
17.5200,0.2920,1.2564,0.0951
17.5600,0.2926,1.2593,0.0953
17.6000,0.2932,1.2629,0.0956
17.6400,0.2941,1.2677,0.0959
17.6800,0.2949,1.2729,0.0963
17.7200,0.2956,1.2777,0.0967
17.7600,0.2961,1.2813,0.0970
17.8000,0.2967,1.2845,0.0972
17.8400,0.2973,1.2874,0.0974
17.8800,0.2979,1.2907,0.0977
17.9200,0.2986,1.2945,0.0980
17.9600,0.2995,1.2996,0.0984
18.0000,0.3003,1.3052,0.0988
18.0400,0.3010,1.3099,0.0991
18.0800,0.3015,1.3134,0.0994
18.1200,0.3020,1.3163,0.0996
18.1600,0.3025,1.3191,0.0998
18.2000,0.3032,1.3222,0.1000
18.2400,0.3040,1.3268,0.1003
18.2800,0.3049,1.3325,0.1008
18.3200,0.3056,1.3376,0.1012
18.3600,0.3062,1.3416,0.1015
18.4000,0.3067,1.3447,0.1017
18.4400,0.3073,1.3478,0.1019
18.4800,0.3079,1.3509,0.1022
18.5200,0.3086,1.3544,0.1025
18.5600,0.3094,1.3594,0.1028
18.6000,0.3102,1.3648,0.1033
18.6400,0.3109,1.3696,0.1036
18.6800,0.3115,1.3735,0.1039
18.7200,0.3120,1.3762,0.1041
18.7600,0.3125,1.3792,0.1043
18.8000,0.3132,1.3825,0.1045
18.8400,0.3140,1.3868,0.1049
18.8800,0.3148,1.3925,0.1053
18.9200,0.3156,1.3982,0.1057
18.9600,0.3162,1.4021,0.1060
19.0000,0.3168,1.4057,0.1063
19.0400,0.3174,1.4088,0.1065
19.0800,0.3179,1.4119,0.1068
19.1200,0.3185,1.4148,0.1070
19.1600,0.3194,1.4195,0.1073
19.2000,0.3202,1.4252,0.1078
19.2400,0.3209,1.4300,0.1082
19.2800,0.3215,1.4340,0.1084
19.3200,0.3221,1.4373,0.1087
19.3600,0.3226,1.4401,0.1089
19.4000,0.3231,1.4432,0.1091
19.4400,0.3239,1.4471,0.1094
19.4800,0.3248,1.4526,0.1099
19.5200,0.3256,1.4584,0.1103
19.5600,0.3262,1.4627,0.1106
19.6000,0.3268,1.4663,0.1109
19.6400,0.3274,1.4696,0.1111
19.6800,0.3279,1.4727,0.1113
19.7200,0.3285,1.4758,0.1116
19.7600,0.3292,1.4798,0.1119
19.8000,0.3301,1.4853,0.1123
19.8400,0.3309,1.4908,0.1127
19.8800,0.3315,1.4952,0.1130
19.9200,0.3321,1.4986,0.1133
19.9600,0.3326,1.5017,0.1135
20.0000,0.3332,1.5047,0.1138
20.0400,0.3339,1.5085,0.1140
20.0800,0.3348,1.5134,0.1144
20.1200,0.3356,1.5193,0.1149
20.1600,0.3363,1.5245,0.1152
20.2000,0.3369,1.5281,0.1155
20.2400,0.3374,1.5312,0.1157
20.2800,0.3379,1.5343,0.1159
20.3200,0.3385,1.5374,0.1162
20.3600,0.3392,1.5411,0.1165
20.4000,0.3401,1.5463,0.1168
20.4400,0.3409,1.5522,0.1173
20.4800,0.3416,1.5573,0.1176
20.5200,0.3422,1.5610,0.1180
20.5600,0.3427,1.5642,0.1182
20.6000,0.3432,1.5673,0.1184
20.6400,0.3439,1.5707,0.1186
20.6800,0.3447,1.5752,0.1190
20.7200,0.3456,1.5813,0.1195
20.7600,0.3463,1.5866,0.1199
20.8000,0.3469,1.5906,0.1202
20.8400,0.3475,1.5940,0.1204
20.8800,0.3479,1.5972,0.1207
20.9200,0.3485,1.6005,0.1209
20.9600,0.3492,1.6039,0.1211
21.0000,0.3500,1.6088,0.1215
21.0400,0.3509,1.6146,0.1220
21.0800,0.3516,1.6202,0.1224
21.1200,0.3522,1.6245,0.1227
21.1600,0.3528,1.6279,0.1229
21.2000,0.3533,1.6309,0.1231
21.2400,0.3538,1.6339,0.1234
21.2800,0.3546,1.6381,0.1237
21.3200,0.3555,1.6438,0.1241
21.3600,0.3562,1.6494,0.1245
21.4000,0.3569,1.6537,0.1249
21.4400,0.3575,1.6576,0.1251
21.4800,0.3580,1.6610,0.1254
21.5200,0.3586,1.6644,0.1256
21.5600,0.3592,1.6677,0.1258
21.6000,0.3600,1.6722,0.1262
21.6400,0.3609,1.6778,0.1266
21.6800,0.3617,1.6837,0.1271
21.7200,0.3622,1.6883,0.1274
21.7600,0.3628,1.6921,0.1277
21.8000,0.3633,1.6952,0.1279
21.8400,0.3639,1.6982,0.1281
21.8800,0.3646,1.7017,0.1284
21.9200,0.3654,1.7068,0.1288
21.9600,0.3662,1.7127,0.1293
22.0000,0.3669,1.7179,0.1296
22.0400,0.3675,1.7220,0.1299
22.0800,0.3681,1.7258,0.1302
22.1200,0.3686,1.7288,0.1304
22.1600,0.3692,1.7319,0.1307
22.2000,0.3699,1.7361,0.1310
22.2400,0.3708,1.7415,0.1314
22.2800,0.3716,1.7471,0.1318
22.3200,0.3723,1.7525,0.1322
22.3600,0.3729,1.7563,0.1325
22.4000,0.3733,1.7597,0.1327
22.4400,0.3739,1.7625,0.1330
22.4800,0.3745,1.7657,0.1332
22.5200,0.3753,1.7705,0.1335
22.5600,0.3762,1.7767,0.1340
22.6000,0.3769,1.7820,0.1345
22.6400,0.3775,1.7863,0.1347
22.6800,0.3781,1.7903,0.1350
22.7200,0.3786,1.7937,0.1353
22.7600,0.3792,1.7968,0.1355
22.8000,0.3799,1.8006,0.1358
22.8400,0.3807,1.8055,0.1361
22.8800,0.3816,1.8113,0.1366
22.9200,0.3822,1.8167,0.1370
22.9600,0.3828,1.8208,0.1373
23.0000,0.3834,1.8243,0.1375
23.0400,0.3839,1.8276,0.1378
23.0800,0.3845,1.8307,0.1380
23.1200,0.3852,1.8351,0.1384
23.1600,0.3861,1.8409,0.1388
23.2000,0.3869,1.8470,0.1392
23.2400,0.3876,1.8516,0.1395
23.2800,0.3882,1.8558,0.1399
23.3200,0.3887,1.8592,0.1401
23.3600,0.3892,1.8624,0.1404
23.4000,0.3898,1.8659,0.1406
23.4400,0.3906,1.8703,0.1410
23.4800,0.3915,1.8761,0.1414
23.5200,0.3922,1.8817,0.1418
23.5600,0.3929,1.8864,0.1422
23.6000,0.3934,1.8901,0.1425
23.6400,0.3940,1.8936,0.1427
23.6800,0.3945,1.8970,0.1430
23.7200,0.3952,1.9007,0.1433
23.7600,0.3961,1.9063,0.1436
23.8000,0.3969,1.9126,0.1441
23.8400,0.3976,1.9178,0.1445
23.8800,0.3982,1.9220,0.1448
23.9200,0.3987,1.9255,0.1451
23.9600,0.3993,1.9287,0.1453
24.0000,0.3999,1.9320,0.1456
24.0400,0.4006,1.9363,0.1459
24.0800,0.4014,1.9417,0.1463
24.1200,0.4022,1.9475,0.1467
24.1600,0.4029,1.9529,0.1471
24.2000,0.4035,1.9571,0.1474
24.2400,0.4040,1.9604,0.1477
24.2800,0.4045,1.9636,0.1479
24.3200,0.4052,1.9671,0.1482
24.3600,0.4061,1.9723,0.1486
24.4000,0.4069,1.9786,0.1490
24.4400,0.4076,1.9841,0.1494
24.4800,0.4083,1.9884,0.1498
24.5200,0.4088,1.9925,0.1501
24.5600,0.4093,1.9957,0.1503
24.6000,0.4099,1.9987,0.1505
24.6400,0.4105,2.0026,0.1508
24.6800,0.4113,2.0079,0.1512
24.7200,0.4122,2.0139,0.1516
24.7600,0.4129,2.0195,0.1520
24.8000,0.4135,2.0240,0.1524
24.8400,0.4141,2.0277,0.1527
24.8800,0.4146,2.0309,0.1529
24.9200,0.4152,2.0342,0.1531
24.9600,0.4160,2.0388,0.1535
25.0000,0.4168,2.0448,0.1539
25.0400,0.4176,2.0509,0.1544
25.0800,0.4182,2.0553,0.1547
25.1200,0.4188,2.0593,0.1550
25.1600,0.4193,2.0625,0.1553
25.2000,0.4198,2.0659,0.1555
25.2400,0.4205,2.0693,0.1557
25.2800,0.4213,2.0739,0.1561
25.3200,0.4221,2.0800,0.1565
25.3600,0.4229,2.0861,0.1570
25.4000,0.4235,2.0909,0.1573
25.4400,0.4241,2.0948,0.1575
25.4800,0.4246,2.0980,0.1578
25.5200,0.4252,2.1012,0.1580
25.5600,0.4259,2.1054,0.1583
25.6000,0.4268,2.1110,0.1588
25.6400,0.4276,2.1175,0.1592
25.6800,0.4282,2.1221,0.1595
25.7200,0.4288,2.1261,0.1598
25.7600,0.4294,2.1297,0.1601
25.8000,0.4299,2.1330,0.1604
25.8400,0.4305,2.1368,0.1606
25.8800,0.4312,2.1409,0.1609
25.9200,0.4321,2.1466,0.1614
25.9600,0.4329,2.1531,0.1618
26.0000,0.4336,2.1583,0.1623
26.0400,0.4341,2.1623,0.1625
26.0800,0.4347,2.1657,0.1628
26.1200,0.4352,2.1688,0.1630
26.1600,0.4359,2.1727,0.1633
26.2000,0.4367,2.1777,0.1637
26.2400,0.4375,2.1840,0.1642
26.2800,0.4382,2.1896,0.1646
26.3200,0.4389,2.1940,0.1649
26.3600,0.4394,2.1979,0.1652
26.4000,0.4399,2.2012,0.1654
26.4400,0.4405,2.2047,0.1657
26.4800,0.4412,2.2087,0.1660
26.5200,0.4421,2.2143,0.1664
26.5600,0.4430,2.2208,0.1669
26.6000,0.4436,2.2265,0.1673
26.6400,0.4442,2.2307,0.1676
26.6800,0.4447,2.2342,0.1678
26.7200,0.4452,2.2374,0.1681
26.7600,0.4458,2.2409,0.1683
26.8000,0.4466,2.2457,0.1687
26.8400,0.4475,2.2520,0.1692
26.8800,0.4482,2.2580,0.1696
26.9200,0.4489,2.2628,0.1699
26.9600,0.4495,2.2667,0.1703
27.0000,0.4501,2.2703,0.1705
27.0400,0.4505,2.2736,0.1708
27.0800,0.4512,2.2773,0.1711
27.1200,0.4520,2.2823,0.1714
27.1600,0.4529,2.2887,0.1719
27.2000,0.4536,2.2947,0.1723
27.2400,0.4542,2.2992,0.1727
27.2800,0.4548,2.3028,0.1729
27.3200,0.4552,2.3062,0.1732
27.3600,0.4558,2.3095,0.1734
27.4000,0.4566,2.3138,0.1737
27.4400,0.4574,2.3199,0.1742
27.4800,0.4582,2.3264,0.1747
27.5200,0.4589,2.3315,0.1750
27.5600,0.4595,2.3357,0.1754
27.6000,0.4601,2.3393,0.1756
27.6400,0.4606,2.3427,0.1759
27.6800,0.4612,2.3461,0.1762
27.7200,0.4619,2.3508,0.1765
27.7600,0.4628,2.3566,0.1770
27.8000,0.4636,2.3628,0.1774
27.8400,0.4642,2.3675,0.1777
27.8800,0.4648,2.3711,0.1780
27.9200,0.4653,2.3750,0.1783
27.9600,0.4659,2.3785,0.1785
28.0000,0.4665,2.3824,0.1788
28.0400,0.4674,2.3877,0.1792
28.0800,0.4682,2.3943,0.1797
28.1200,0.4689,2.3999,0.1801
28.1600,0.4696,2.4044,0.1805
28.2000,0.4701,2.4081,0.1807
28.2400,0.4706,2.4118,0.1810
28.2800,0.4712,2.4149,0.1812
28.3200,0.4719,2.4189,0.1815
28.3600,0.4727,2.4244,0.1819
28.4000,0.4735,2.4307,0.1824
28.4400,0.4742,2.4362,0.1828
28.4800,0.4748,2.4406,0.1831
28.5200,0.4753,2.4444,0.1834
28.5600,0.4759,2.4479,0.1836
28.6000,0.4765,2.4515,0.1839
28.6400,0.4773,2.4565,0.1843
28.6800,0.4782,2.4628,0.1847
28.7200,0.4789,2.4688,0.1852
28.7600,0.4796,2.4737,0.1855
28.8000,0.4801,2.4777,0.1858
28.8400,0.4806,2.4811,0.1861
28.8800,0.4812,2.4847,0.1864
28.9200,0.4818,2.4883,0.1866
28.9600,0.4827,2.4935,0.1870
29.0000,0.4835,2.4997,0.1875
29.0400,0.4842,2.5057,0.1879
29.0800,0.4849,2.5103,0.1883
29.1200,0.4854,2.5142,0.1885
29.1600,0.4859,2.5178,0.1888
29.2000,0.4865,2.5211,0.1891
29.2400,0.4873,2.5256,0.1894
29.2800,0.4882,2.5320,0.1898
29.3200,0.4889,2.5384,0.1903
29.3600,0.4896,2.5433,0.1907
29.4000,0.4901,2.5474,0.1910
29.4400,0.4907,2.5512,0.1912
29.4800,0.4912,2.5547,0.1915
29.5200,0.4918,2.5581,0.1917
29.5600,0.4926,2.5629,0.1921
29.6000,0.4935,2.5692,0.1926
29.6400,0.4942,2.5754,0.1930
29.6800,0.4949,2.5804,0.1934
29.7200,0.4955,2.5846,0.1937
29.7600,0.4960,2.5882,0.1940
29.8000,0.4966,2.5915,0.1942
29.8400,0.4972,2.5955,0.1946
29.8800,0.4982,2.6014,0.1949
29.9200,0.4989,2.6078,0.1954
29.9600,0.4996,2.6130,0.1958
30.0000,0.5002,2.6173,0.1961
30.0400,0.5007,2.6213,0.1964
30.0800,0.5013,2.6249,0.1967
30.1200,0.5018,2.6286,0.1970
30.1600,0.5026,2.6328,0.1973
30.2000,0.5035,2.6388,0.1977
30.2400,0.5043,2.6452,0.1982
30.2800,0.5050,2.6509,0.1986
30.3200,0.5055,2.6551,0.1989
30.3600,0.5060,2.6587,0.1991
30.4000,0.5066,2.6619,0.1994
30.4400,0.5072,2.6656,0.1997
30.4800,0.5080,2.6707,0.2000
30.5200,0.5088,2.6771,0.2005
30.5600,0.5096,2.6830,0.2010
30.6000,0.5102,2.6877,0.2013
30.6400,0.5107,2.6920,0.2016
30.6800,0.5113,2.6958,0.2019
30.7200,0.5119,2.6995,0.2022
30.7600,0.5125,2.7032,0.2025
30.8000,0.5134,2.7087,0.2029
30.8400,0.5142,2.7154,0.2034
30.8800,0.5149,2.7215,0.2038
30.9200,0.5155,2.7263,0.2041
30.9600,0.5161,2.7298,0.2044
31.0000,0.5165,2.7331,0.2046
31.0400,0.5172,2.7368,0.2049
31.0800,0.5179,2.7414,0.2052
31.1200,0.5188,2.7475,0.2057
31.1600,0.5196,2.7540,0.2062
31.2000,0.5202,2.7594,0.2066
31.2400,0.5208,2.7636,0.2069
31.2800,0.5214,2.7675,0.2072
31.3200,0.5219,2.7713,0.2074
31.3600,0.5225,2.7749,0.2077
31.4000,0.5233,2.7800,0.2081
31.4400,0.5242,2.7865,0.2086
31.4800,0.5249,2.7924,0.2090
31.5200,0.5255,2.7974,0.2094
31.5600,0.5261,2.8015,0.2096
31.6000,0.5266,2.8050,0.2099
31.6400,0.5271,2.8085,0.2102
31.6800,0.5279,2.8127,0.2105
31.7200,0.5287,2.8187,0.2109
31.7600,0.5296,2.8254,0.2114
31.8000,0.5302,2.8312,0.2118
31.8400,0.5308,2.8359,0.2122
31.8800,0.5314,2.8397,0.2125
31.9200,0.5320,2.8434,0.2128
31.9600,0.5326,2.8471,0.2130
32.0000,0.5333,2.8519,0.2134
32.0400,0.5341,2.8581,0.2138
32.0800,0.5349,2.8641,0.2143
32.1200,0.5356,2.8694,0.2146
32.1600,0.5361,2.8740,0.2150
32.2000,0.5366,2.8777,0.2152
32.2400,0.5372,2.8811,0.2155
32.2800,0.5379,2.8851,0.2158
32.3200,0.5387,2.8905,0.2162
32.3600,0.5396,2.8974,0.2167
32.4000,0.5403,2.9032,0.2172
32.4400,0.5409,2.9080,0.2175
32.4800,0.5414,2.9120,0.2178
32.5200,0.5420,2.9156,0.2181
32.5600,0.5425,2.9192,0.2184
32.6000,0.5432,2.9233,0.2186
32.6400,0.5441,2.9291,0.2190
32.6800,0.5449,2.9355,0.2195
32.7200,0.5456,2.9414,0.2199
32.7600,0.5462,2.9461,0.2203
32.8000,0.5467,2.9500,0.2205
32.8400,0.5472,2.9536,0.2208
32.8800,0.5478,2.9573,0.2211
32.9200,0.5487,2.9624,0.2215
32.9600,0.5496,2.9691,0.2220
33.0000,0.5503,2.9754,0.2224
33.0400,0.5509,2.9801,0.2228
33.0800,0.5515,2.9842,0.2231
33.1200,0.5520,2.9878,0.2233
33.1600,0.5525,2.9911,0.2236
33.2000,0.5531,2.9951,0.2239
33.2400,0.5540,3.0001,0.2243
33.2800,0.5548,3.0068,0.2248
33.3200,0.5555,3.0131,0.2252
33.3600,0.5562,3.0182,0.2255
33.4000,0.5567,3.0222,0.2259
33.4400,0.5572,3.0259,0.2261
33.4800,0.5578,3.0295,0.2264
33.5200,0.5586,3.0339,0.2267
33.5600,0.5595,3.0400,0.2272
33.6000,0.5602,3.0468,0.2277
33.6400,0.5609,3.0519,0.2281
33.6800,0.5615,3.0560,0.2283
33.7200,0.5620,3.0599,0.2286
33.7600,0.5626,3.0636,0.2289
33.8000,0.5631,3.0675,0.2292
33.8400,0.5639,3.0720,0.2295
33.8800,0.5648,3.0785,0.2300
33.9200,0.5656,3.0851,0.2305
33.9600,0.5662,3.0907,0.2309
34.0000,0.5668,3.0950,0.2312
34.0400,0.5673,3.0986,0.2315
34.0800,0.5679,3.1021,0.2317
34.1200,0.5686,3.1061,0.2320
34.1600,0.5694,3.1116,0.2325
34.2000,0.5702,3.1183,0.2329
34.2400,0.5709,3.1238,0.2333
34.2800,0.5715,3.1285,0.2337
34.3200,0.5721,3.1327,0.2340
34.3600,0.5726,3.1365,0.2343
34.4000,0.5732,3.1404,0.2346
34.4400,0.5739,3.1449,0.2349
34.4800,0.5748,3.1506,0.2353
34.5200,0.5756,3.1571,0.2358
34.5600,0.5763,3.1633,0.2362
34.6000,0.5769,3.1679,0.2366
34.6400,0.5774,3.1716,0.2368
34.6800,0.5779,3.1752,0.2371
34.7200,0.5785,3.1787,0.2374
34.7600,0.5793,3.1837,0.2377
34.8000,0.5802,3.1900,0.2382
34.8400,0.5809,3.1961,0.2387
34.8800,0.5816,3.2013,0.2391
34.9200,0.5821,3.2057,0.2393
34.9600,0.5826,3.2095,0.2397
35.0000,0.5832,3.2132,0.2399
35.0400,0.5839,3.2172,0.2402
35.0800,0.5847,3.2225,0.2406
35.1200,0.5855,3.2292,0.2411
35.1600,0.5863,3.2355,0.2415
35.2000,0.5869,3.2408,0.2419
35.2400,0.5874,3.2445,0.2422
35.2800,0.5879,3.2481,0.2425
35.3200,0.5885,3.2515,0.2427
35.3600,0.5892,3.2559,0.2430
35.4000,0.5901,3.2621,0.2435
35.4400,0.5909,3.2688,0.2440
35.4800,0.5916,3.2742,0.2444
35.5200,0.5922,3.2786,0.2447
35.5600,0.5927,3.2826,0.2450
35.6000,0.5932,3.2861,0.2452
35.6400,0.5938,3.2899,0.2456
35.6800,0.5946,3.2945,0.2459
35.7200,0.5955,3.3008,0.2464
35.7600,0.5962,3.3076,0.2469
35.8000,0.5968,3.3125,0.2472
35.8400,0.5974,3.3165,0.2475
35.8800,0.5980,3.3204,0.2478
35.9200,0.5985,3.3237,0.2481
35.9600,0.5991,3.3279,0.2483
36.0000,0.6000,3.3335,0.2488
36.0400,0.6009,3.3402,0.2493
36.0800,0.6016,3.3462,0.2497
36.1200,0.6022,3.3510,0.2501
36.1600,0.6028,3.3554,0.2504
36.2000,0.6033,3.3586,0.2506
36.2400,0.6039,3.3621,0.2509
36.2800,0.6046,3.3665,0.2512
36.3200,0.6054,3.3725,0.2517
36.3600,0.6062,3.3788,0.2521
36.4000,0.6069,3.3843,0.2525
36.4400,0.6074,3.3890,0.2529
36.4800,0.6080,3.3929,0.2532
36.5200,0.6085,3.3965,0.2534
36.5600,0.6092,3.4002,0.2537
36.6000,0.6100,3.4053,0.2540
36.6400,0.6109,3.4121,0.2545
36.6800,0.6116,3.4183,0.2551
36.7200,0.6123,3.4234,0.2554
36.7600,0.6128,3.4275,0.2557
36.8000,0.6133,3.4312,0.2560
36.8400,0.6139,3.4346,0.2562
36.8800,0.6145,3.4385,0.2565
36.9200,0.6153,3.4436,0.2569
36.9600,0.6162,3.4503,0.2574
37.0000,0.6169,3.4568,0.2579
37.0400,0.6175,3.4617,0.2582
37.0800,0.6181,3.4661,0.2585
37.1200,0.6186,3.4697,0.2588
37.1600,0.6192,3.4731,0.2591
37.2000,0.6200,3.4776,0.2594
37.2400,0.6208,3.4842,0.2599
37.2800,0.6216,3.4910,0.2604
37.3200,0.6223,3.4963,0.2608
37.3540,0.6228,3.5001,0.2611