File: Modulus_Al_2.csv
Time,Displacement,Force,Strain 1
(s),(mm),(kN),(%)
0.0000,0.0000,0.0001,-0.0001
0.0400,0.0001,0.0000,-0.0001
0.0800,0.0007,0.0003,-0.0002
0.1200,0.0016,0.0004,-0.0001
0.1600,0.0023,0.0006,-0.0002
0.2000,0.0031,0.0006,-0.0002
0.2400,0.0040,0.0008,-0.0002
0.2800,0.0049,0.0009,-0.0002
0.3200,0.0055,0.0009,-0.0001
0.3600,0.0061,0.0008,-0.0002
0.4000,0.0066,0.0009,-0.0002
0.4400,0.0072,0.0010,-0.0001
0.4800,0.0079,0.0009,-0.0001
0.5200,0.0088,0.0009,-0.0001
0.5600,0.0096,0.0011,-0.0001
0.6000,0.0102,0.0012,-0.0001
0.6400,0.0109,0.0014,-0.0001
0.6800,0.0114,0.0014,-0.0001
0.7200,0.0119,0.0014,-0.0001
0.7600,0.0125,0.0017,0.0000
0.8000,0.0132,0.0017,-0.0001
0.8400,0.0141,0.0019,-0.0001
0.8800,0.0149,0.0021,0.0000
0.9200,0.0156,0.0020,0.0000
0.9600,0.0162,0.0018,-0.0001
1.0000,0.0167,0.0022,0.0000
1.0400,0.0172,0.0020,-0.0001
1.0800,0.0179,0.0022,-0.0001
1.1200,0.0187,0.0026,0.0000
1.1600,0.0196,0.0029,-0.0001
1.2000,0.0203,0.0029,-0.0001
1.2400,0.0209,0.0030,0.0000
1.2800,0.0215,0.0032,0.0000
1.3200,0.0220,0.0034,0.0000
1.3600,0.0226,0.0035,0.0001
1.4000,0.0232,0.0038,0.0000
1.4400,0.0241,0.0039,0.0000
1.4800,0.0249,0.0043,0.0001
1.5200,0.0256,0.0044,0.0001
1.5600,0.0262,0.0047,0.0000
1.6000,0.0267,0.0047,0.0001
1.6400,0.0273,0.0047,0.0001
1.6800,0.0279,0.0050,0.0001
1.7200,0.0287,0.0052,0.0001
1.7600,0.0295,0.0055,0.0001
1.8000,0.0303,0.0059,0.0002
1.8400,0.0309,0.0062,0.0002
1.8800,0.0315,0.0069,0.0002
1.9200,0.0320,0.0077,0.0004
1.9600,0.0326,0.0085,0.0004
2.0000,0.0332,0.0094,0.0005
2.0400,0.0340,0.0109,0.0006
2.0800,0.0349,0.0127,0.0008
2.1200,0.0356,0.0149,0.0009
2.1600,0.0363,0.0168,0.0011
2.2000,0.0368,0.0182,0.0012
2.2400,0.0373,0.0196,0.0013
2.2800,0.0379,0.0210,0.0015
2.3200,0.0386,0.0229,0.0016
2.3600,0.0394,0.0252,0.0018
2.4000,0.0402,0.0277,0.0021
2.4400,0.0409,0.0300,0.0022
2.4800,0.0415,0.0319,0.0024
2.5200,0.0421,0.0339,0.0025
2.5600,0.0426,0.0355,0.0027
2.6000,0.0432,0.0371,0.0029
2.6400,0.0440,0.0392,0.0031
2.6800,0.0448,0.0421,0.0033
2.7200,0.0456,0.0448,0.0035
2.7600,0.0462,0.0473,0.0037
2.8000,0.0468,0.0493,0.0039
2.8400,0.0473,0.0511,0.0041
2.8800,0.0479,0.0528,0.0042
2.9200,0.0485,0.0546,0.0044
2.9600,0.0494,0.0574,0.0046
3.0000,0.0502,0.0607,0.0048
3.0400,0.0509,0.0635,0.0051
3.0800,0.0515,0.0658,0.0052
3.1200,0.0521,0.0677,0.0054
3.1600,0.0527,0.0698,0.0056
3.2000,0.0532,0.0717,0.0057
3.2400,0.0539,0.0739,0.0059
3.2800,0.0547,0.0768,0.0061
3.3200,0.0556,0.0802,0.0064
3.3600,0.0562,0.0831,0.0066
3.4000,0.0568,0.0856,0.0068
3.4400,0.0574,0.0877,0.0070
3.4800,0.0579,0.0897,0.0071
3.5200,0.0585,0.0917,0.0073
3.5600,0.0593,0.0944,0.0075
3.6000,0.0602,0.0980,0.0077
3.6400,0.0610,0.1015,0.0080
3.6800,0.0616,0.1043,0.0082
3.7200,0.0621,0.1066,0.0083
3.7600,0.0627,0.1086,0.0085
3.8000,0.0633,0.1109,0.0087
3.8400,0.0639,0.1131,0.0088
3.8800,0.0647,0.1159,0.0090
3.9200,0.0655,0.1195,0.0093
3.9600,0.0662,0.1231,0.0095
4.0000,0.0669,0.1256,0.0096
4.0400,0.0674,0.1281,0.0099
4.0800,0.0679,0.1303,0.0100
4.1200,0.0685,0.1325,0.0101
4.1600,0.0693,0.1351,0.0103
4.2000,0.0702,0.1386,0.0105
4.2400,0.0710,0.1425,0.0108
4.2800,0.0716,0.1460,0.0111
4.3200,0.0722,0.1486,0.0112
4.3600,0.0727,0.1510,0.0114
4.4000,0.0733,0.1533,0.0116
4.4400,0.0739,0.1556,0.0117
4.4800,0.0746,0.1584,0.0119
4.5200,0.0755,0.1625,0.0122
4.5600,0.0763,0.1664,0.0124
4.6000,0.0769,0.1697,0.0127
4.6400,0.0775,0.1724,0.0128
4.6800,0.0780,0.1747,0.0130
4.7200,0.0785,0.1771,0.0132
4.7600,0.0792,0.1798,0.0134
4.8000,0.0801,0.1833,0.0136
4.8400,0.0809,0.1875,0.0140
4.8800,0.0816,0.1911,0.0142
4.9200,0.0822,0.1937,0.0144
4.9600,0.0828,0.1965,0.0146
5.0000,0.0833,0.1990,0.0148
5.0400,0.0838,0.2013,0.0149
5.0800,0.0845,0.2040,0.0151
5.1200,0.0854,0.2078,0.0154
5.1600,0.0862,0.2121,0.0157
5.2000,0.0869,0.2159,0.0160
5.2400,0.0875,0.2191,0.0162
5.2800,0.0881,0.2218,0.0164
5.3200,0.0886,0.2243,0.0166
5.3600,0.0892,0.2269,0.0168
5.4000,0.0901,0.2306,0.0170
5.4400,0.0909,0.2350,0.0174
5.4800,0.0916,0.2389,0.0176
5.5200,0.0922,0.2420,0.0178
5.5600,0.0928,0.2449,0.0180
5.6000,0.0933,0.2476,0.0182
5.6400,0.0939,0.2501,0.0184
5.6800,0.0945,0.2530,0.0186
5.7200,0.0954,0.2565,0.0188
5.7600,0.0962,0.2610,0.0192
5.8000,0.0970,0.2651,0.0195
5.8400,0.0976,0.2686,0.0197
5.8800,0.0981,0.2712,0.0199
5.9200,0.0986,0.2738,0.0201
5.9600,0.0992,0.2762,0.0203
6.0000,0.0999,0.2794,0.0206
6.0400,0.1008,0.2837,0.0209
6.0800,0.1016,0.2881,0.0212
6.1200,0.1022,0.2918,0.0214
6.1600,0.1029,0.2949,0.0216
6.2000,0.1034,0.2977,0.0218
6.2400,0.1039,0.3006,0.0221
6.2800,0.1045,0.3031,0.0222
6.3200,0.1053,0.3064,0.0225
6.3600,0.1062,0.3112,0.0228
6.4000,0.1070,0.3157,0.0231
6.4400,0.1076,0.3193,0.0233
6.4800,0.1082,0.3224,0.0236
6.5200,0.1087,0.3246,0.0238
6.5600,0.1092,0.3276,0.0240
6.6000,0.1099,0.3306,0.0242
6.6400,0.1107,0.3347,0.0245
6.6800,0.1115,0.3394,0.0248
6.7200,0.1122,0.3434,0.0251
6.7600,0.1129,0.3468,0.0254
6.8000,0.1134,0.3500,0.0256
6.8400,0.1139,0.3529,0.0258
6.8800,0.1145,0.3558,0.0260
6.9200,0.1152,0.3590,0.0262
6.9600,0.1161,0.3632,0.0265
7.0000,0.1169,0.3681,0.0269
7.0400,0.1176,0.3718,0.0272
7.0800,0.1182,0.3751,0.0274
7.1200,0.1187,0.3780,0.0276
7.1600,0.1192,0.3806,0.0278
7.2000,0.1198,0.3836,0.0280
7.2400,0.1206,0.3874,0.0283
7.2800,0.1216,0.3924,0.0286
7.3200,0.1222,0.3970,0.0289
7.3600,0.1229,0.4008,0.0293
7.4000,0.1235,0.4041,0.0294
7.4400,0.1240,0.4070,0.0297
7.4800,0.1246,0.4097,0.0299
7.5200,0.1252,0.4128,0.0301
7.5600,0.1261,0.4170,0.0304
7.6000,0.1269,0.4218,0.0308
7.6400,0.1276,0.4264,0.0311
7.6800,0.1282,0.4299,0.0314
7.7200,0.1287,0.4328,0.0316
7.7600,0.1293,0.4358,0.0317
7.8000,0.1299,0.4387,0.0320
7.8400,0.1306,0.4423,0.0323
7.8800,0.1315,0.4470,0.0326
7.9200,0.1323,0.4521,0.0330
7.9600,0.1329,0.4562,0.0332
8.0000,0.1336,0.4597,0.0335
8.0400,0.1340,0.4629,0.0338
8.0800,0.1346,0.4658,0.0339
8.1200,0.1352,0.4689,0.0342
8.1600,0.1360,0.4727,0.0344
8.2000,0.1368,0.4775,0.0348
8.2400,0.1376,0.4822,0.0352
8.2800,0.1382,0.4866,0.0354
8.3200,0.1388,0.4896,0.0356
8.3600,0.1393,0.4926,0.0359
8.4000,0.1399,0.4955,0.0361
8.4400,0.1406,0.4988,0.0364
8.4800,0.1415,0.5034,0.0367
8.5200,0.1423,0.5087,0.0371
8.5600,0.1429,0.5129,0.0374
8.6000,0.1436,0.5163,0.0377
8.6400,0.1441,0.5197,0.0379
8.6800,0.1446,0.5226,0.0381
8.7200,0.1452,0.5254,0.0383
8.7600,0.1459,0.5292,0.0386
8.8000,0.1467,0.5339,0.0389
8.8400,0.1476,0.5390,0.0393
8.8800,0.1482,0.5438,0.0396
8.9200,0.1488,0.5475,0.0399
8.9600,0.1494,0.5507,0.0402
9.0000,0.1499,0.5536,0.0403
9.0400,0.1505,0.5568,0.0406
9.0800,0.1514,0.5611,0.0409
9.1200,0.1522,0.5662,0.0412
9.1600,0.1529,0.5709,0.0416
9.2000,0.1536,0.5745,0.0419
9.2400,0.1541,0.5779,0.0421
9.2800,0.1547,0.5810,0.0424
9.3200,0.1552,0.5842,0.0426
9.3600,0.1558,0.5874,0.0429
9.4000,0.1567,0.5918,0.0432
9.4400,0.1576,0.5973,0.0436
9.4800,0.1583,0.6026,0.0440
9.5200,0.1589,0.6064,0.0442
9.5600,0.1594,0.6096,0.0445
9.6000,0.1599,0.6127,0.0447
9.6400,0.1606,0.6157,0.0449
9.6800,0.1613,0.6199,0.0452
9.7200,0.1622,0.6253,0.0456
9.7600,0.1629,0.6304,0.0460
9.8000,0.1636,0.6344,0.0463
9.8400,0.1641,0.6380,0.0465
9.8800,0.1647,0.6415,0.0468
9.9200,0.1652,0.6446,0.0471
9.9600,0.1659,0.6481,0.0473
10.0000,0.1666,0.6522,0.0476
10.0400,0.1675,0.6576,0.0480
10.0800,0.1683,0.6631,0.0483
10.1200,0.1689,0.6674,0.0487
10.1600,0.1695,0.6710,0.0489
10.2000,0.1700,0.6743,0.0492
10.2400,0.1706,0.6774,0.0494
10.2800,0.1713,0.6812,0.0497
10.3200,0.1721,0.6861,0.0500
10.3600,0.1729,0.6913,0.0505
10.4000,0.1736,0.6958,0.0507
10.4400,0.1742,0.6996,0.0511
10.4800,0.1747,0.7033,0.0513
10.5200,0.1753,0.7066,0.0516
10.5600,0.1759,0.7099,0.0518
10.6000,0.1766,0.7140,0.0522
10.6400,0.1775,0.7192,0.0525
10.6800,0.1783,0.7249,0.0529
10.7200,0.1789,0.7297,0.0533
10.7600,0.1795,0.7334,0.0535
10.8000,0.1800,0.7365,0.0538
10.8400,0.1805,0.7397,0.0540
10.8800,0.1812,0.7431,0.0542
10.9200,0.1820,0.7477,0.0546
10.9600,0.1829,0.7534,0.0550
11.0000,0.1836,0.7584,0.0553
11.0400,0.1842,0.7625,0.0557
11.0800,0.1848,0.7663,0.0559
11.1200,0.1853,0.7699,0.0562
11.1600,0.1858,0.7731,0.0564
11.2000,0.1865,0.7770,0.0567
11.2400,0.1874,0.7817,0.0571
11.2800,0.1882,0.7875,0.0575
11.3200,0.1889,0.7925,0.0578
11.3600,0.1895,0.7964,0.0581
11.4000,0.1901,0.7998,0.0583
11.4400,0.1906,0.8029,0.0586
11.4800,0.1911,0.8062,0.0589
11.5200,0.1920,0.8105,0.0591
11.5600,0.1929,0.8160,0.0596
11.6000,0.1936,0.8213,0.0600
11.6400,0.1942,0.8258,0.0603
11.6800,0.1948,0.8297,0.0606
11.7200,0.1954,0.8331,0.0608
11.7600,0.1959,0.8365,0.0610
11.8000,0.1966,0.8401,0.0613
11.8400,0.1974,0.8447,0.0616
11.8800,0.1982,0.8507,0.0621
11.9200,0.1989,0.8562,0.0625
11.9600,0.1996,0.8604,0.0628
12.0000,0.2001,0.8639,0.0631
12.0400,0.2006,0.8673,0.0633
12.0800,0.2012,0.8709,0.0635
12.1200,0.2019,0.8749,0.0638
12.1600,0.2028,0.8800,0.0642
12.2000,0.2036,0.8857,0.0646
12.2400,0.2043,0.8907,0.0651
12.2800,0.2049,0.8949,0.0653
12.3200,0.2054,0.8985,0.0656
12.3600,0.2060,0.9019,0.0658
12.4000,0.2065,0.9053,0.0661
12.4400,0.2073,0.9094,0.0664
12.4800,0.2081,0.9148,0.0668
12.5200,0.2089,0.9208,0.0672
12.5600,0.2096,0.9253,0.0676
12.6000,0.2102,0.9294,0.0679
12.6400,0.2107,0.9330,0.0680
12.6800,0.2112,0.9363,0.0683
12.7200,0.2119,0.9401,0.0686
12.7600,0.2127,0.9452,0.0689
12.8000,0.2136,0.9509,0.0694
12.8400,0.2143,0.9562,0.0698
12.8800,0.2149,0.9604,0.0701
12.9200,0.2155,0.9642,0.0704
12.9600,0.2160,0.9677,0.0706
13.0000,0.2165,0.9712,0.0709
13.0400,0.2172,0.9750,0.0712
13.0800,0.2181,0.9802,0.0715
13.1200,0.2189,0.9862,0.0719
13.1600,0.2196,0.9912,0.0724
13.2000,0.2202,0.9956,0.0726
13.2400,0.2207,0.9993,0.0730
13.2800,0.2212,1.0026,0.0732
13.3200,0.2219,1.0060,0.0734
13.3600,0.2227,1.0108,0.0738
13.4000,0.2236,1.0168,0.0742
13.4400,0.2243,1.0222,0.0746
13.4800,0.2249,1.0267,0.0750
13.5200,0.2255,1.0305,0.0752
13.5600,0.2260,1.0340,0.0755
13.6000,0.2265,1.0375,0.0757
13.6400,0.2272,1.0410,0.0760
13.6800,0.2280,1.0459,0.0763
13.7200,0.2289,1.0519,0.0768
13.7600,0.2296,1.0573,0.0772
13.8000,0.2302,1.0618,0.0775
13.8400,0.2308,1.0657,0.0778
13.8800,0.2313,1.0692,0.0780
13.9200,0.2319,1.0727,0.0783
13.9600,0.2326,1.0772,0.0786
14.0000,0.2335,1.0828,0.0790
14.0400,0.2343,1.0887,0.0794
14.0800,0.2349,1.0935,0.0798
14.1200,0.2355,1.0975,0.0801
14.1600,0.2360,1.1013,0.0803
14.2000,0.2366,1.1046,0.0806
14.2400,0.2372,1.1082,0.0808
14.2800,0.2380,1.1128,0.0812
14.3200,0.2388,1.1185,0.0816
14.3600,0.2396,1.1244,0.0820
14.4000,0.2403,1.1289,0.0824
14.4400,0.2408,1.1327,0.0826
14.4800,0.2413,1.1362,0.0829
14.5200,0.2419,1.1397,0.0832
14.5600,0.2426,1.1437,0.0834
14.6000,0.2434,1.1491,0.0838
14.6400,0.2442,1.1551,0.0843
14.6800,0.2449,1.1602,0.0846
14.7200,0.2455,1.1646,0.0850
14.7600,0.2461,1.1684,0.0852
14.8000,0.2466,1.1722,0.0856
14.8400,0.2472,1.1758,0.0858
14.8800,0.2479,1.1799,0.0860
14.9200,0.2488,1.1853,0.0865
14.9600,0.2496,1.1914,0.0870
15.0000,0.2503,1.1965,0.0873
15.0400,0.2509,1.2008,0.0876
15.0800,0.2514,1.2043,0.0879
15.1200,0.2519,1.2077,0.0882
15.1600,0.2525,1.2115,0.0884
15.2000,0.2533,1.2162,0.0887
15.2400,0.2542,1.2223,0.0892
15.2800,0.2549,1.2283,0.0896
15.3200,0.2556,1.2327,0.0899
15.3600,0.2562,1.2369,0.0902
15.4000,0.2567,1.2408,0.0905
15.4400,0.2572,1.2443,0.0908
15.4800,0.2579,1.2481,0.0911
15.5200,0.2587,1.2533,0.0915
15.5600,0.2596,1.2594,0.0919
15.6000,0.2603,1.2649,0.0923
15.6400,0.2608,1.2693,0.0926
15.6800,0.2614,1.2730,0.0929
15.7200,0.2619,1.2765,0.0931
15.7600,0.2625,1.2800,0.0934
15.8000,0.2632,1.2847,0.0938
15.8400,0.2642,1.2906,0.0942
15.8800,0.2650,1.2968,0.0946
15.9200,0.2656,1.3016,0.0950
15.9600,0.2662,1.3059,0.0953
16.0000,0.2667,1.3096,0.0956
16.0400,0.2673,1.3131,0.0959
16.0800,0.2679,1.3169,0.0961
16.1200,0.2687,1.3217,0.0965
16.1600,0.2695,1.3274,0.0969
16.2000,0.2703,1.3334,0.0974
16.2400,0.2709,1.3381,0.0977
16.2800,0.2714,1.3419,0.0979
16.3200,0.2720,1.3455,0.0982
16.3600,0.2725,1.3490,0.0985
16.4000,0.2732,1.3533,0.0988
16.4400,0.2741,1.3591,0.0991
16.4800,0.2749,1.3653,0.0996
16.5200,0.2756,1.3704,0.1000
16.5600,0.2762,1.3748,0.1003
16.6000,0.2767,1.3787,0.1007
16.6400,0.2773,1.3824,0.1009
16.6800,0.2779,1.3859,0.1012
16.7200,0.2786,1.3905,0.1015
16.7600,0.2794,1.3962,0.1019
16.8000,0.2802,1.4022,0.1023
16.8400,0.2809,1.4074,0.1027
16.8800,0.2815,1.4115,0.1030
16.9200,0.2820,1.4154,0.1033
16.9600,0.2825,1.4189,0.1035
17.0000,0.2832,1.4228,0.1038
17.0400,0.2841,1.4279,0.1042
17.0800,0.2849,1.4343,0.1047
17.1200,0.2856,1.4397,0.1051
17.1600,0.2862,1.4441,0.1054
17.2000,0.2868,1.4480,0.1057
17.2400,0.2873,1.4516,0.1059
17.2800,0.2878,1.4551,0.1063
17.3200,0.2885,1.4593,0.1065
17.3600,0.2894,1.4646,0.1069
17.4000,0.2902,1.4710,0.1074
17.4400,0.2909,1.4770,0.1078
17.4800,0.2915,1.4817,0.1081
17.5200,0.2921,1.4854,0.1084
17.5600,0.2926,1.4888,0.1087
17.6000,0.2932,1.4925,0.1089
17.6400,0.2940,1.4972,0.1093
17.6800,0.2949,1.5033,0.1098
17.7200,0.2957,1.5095,0.1102
17.7600,0.2962,1.5141,0.1106
17.8000,0.2968,1.5181,0.1109
17.8400,0.2974,1.5220,0.1111
17.8800,0.2979,1.5254,0.1114
17.9200,0.2985,1.5294,0.1117
17.9600,0.2994,1.5345,0.1120
18.0000,0.3002,1.5407,0.1125
18.0400,0.3010,1.5470,0.1130
18.0800,0.3016,1.5521,0.1133
18.1200,0.3021,1.5559,0.1136
18.1600,0.3027,1.5596,0.1138
18.2000,0.3032,1.5630,0.1142
18.2400,0.3040,1.5673,0.1145
18.2800,0.3048,1.5733,0.1149
18.3200,0.3056,1.5795,0.1154
18.3600,0.3063,1.5848,0.1157
18.4000,0.3069,1.5892,0.1160
18.4400,0.3074,1.5932,0.1163
18.4800,0.3079,1.5970,0.1166
18.5200,0.3085,1.6007,0.1169
18.5600,0.3093,1.6056,0.1172
18.6000,0.3102,1.6118,0.1177
18.6400,0.3110,1.6179,0.1182
18.6800,0.3116,1.6232,0.1185
18.7200,0.3122,1.6275,0.1189
18.7600,0.3127,1.6312,0.1191
18.8000,0.3132,1.6347,0.1194
18.8400,0.3139,1.6384,0.1197
18.8800,0.3147,1.6436,0.1200
18.9200,0.3155,1.6500,0.1205
18.9600,0.3162,1.6555,0.1209
19.0000,0.3169,1.6604,0.1213
19.0400,0.3174,1.6647,0.1216
19.0800,0.3180,1.6684,0.1219
19.1200,0.3185,1.6721,0.1221
19.1600,0.3192,1.6763,0.1224
19.2000,0.3201,1.6819,0.1228
19.2400,0.3209,1.6882,0.1233
19.2800,0.3216,1.6942,0.1237
19.3200,0.3222,1.6987,0.1241
19.3600,0.3227,1.7025,0.1243
19.4000,0.3232,1.7061,0.1246
19.4400,0.3238,1.7098,0.1248
19.4800,0.3246,1.7146,0.1252
19.5200,0.3255,1.7208,0.1257
19.5600,0.3262,1.7271,0.1262
19.6000,0.3269,1.7318,0.1265
19.6400,0.3275,1.7364,0.1269
19.6800,0.3280,1.7402,0.1271
19.7200,0.3286,1.7437,0.1274
19.7600,0.3292,1.7476,0.1277
19.8000,0.3300,1.7528,0.1280
19.8400,0.3309,1.7589,0.1285
19.8800,0.3316,1.7652,0.1289
19.9200,0.3322,1.7698,0.1293
19.9600,0.3327,1.7738,0.1296
20.0000,0.3333,1.7775,0.1298
20.0400,0.3339,1.7812,0.1301
20.0800,0.3346,1.7856,0.1305
20.1200,0.3355,1.7919,0.1309
20.1600,0.3363,1.7986,0.1314
20.2000,0.3369,1.8038,0.1318
20.2400,0.3376,1.8083,0.1321
20.2800,0.3381,1.8124,0.1324
20.3200,0.3386,1.8161,0.1327
20.3600,0.3392,1.8196,0.1329
20.4000,0.3400,1.8242,0.1333
20.4400,0.3408,1.8305,0.1338
20.4800,0.3416,1.8365,0.1342
20.5200,0.3422,1.8418,0.1346
20.5600,0.3428,1.8463,0.1349
20.6000,0.3433,1.8501,0.1352
20.6400,0.3439,1.8538,0.1354
20.6800,0.3446,1.8583,0.1357
20.7200,0.3454,1.8637,0.1361
20.7600,0.3463,1.8703,0.1367
20.8000,0.3470,1.8760,0.1371
20.8400,0.3476,1.8805,0.1374
20.8800,0.3482,1.8849,0.1377
20.9200,0.3486,1.8885,0.1380
20.9600,0.3492,1.8922,0.1383
21.0000,0.3499,1.8967,0.1386
21.0400,0.3507,1.9023,0.1390
21.0800,0.3515,1.9087,0.1395
21.1200,0.3522,1.9144,0.1400
21.1600,0.3529,1.9192,0.1402
21.2000,0.3534,1.9232,0.1405
21.2400,0.3539,1.9270,0.1408
21.2800,0.3545,1.9307,0.1411
21.3200,0.3553,1.9357,0.1415
21.3600,0.3562,1.9423,0.1420
21.4000,0.3570,1.9485,0.1424
21.4400,0.3576,1.9533,0.1428
21.4800,0.3582,1.9576,0.1431
21.5200,0.3587,1.9615,0.1434
21.5600,0.3592,1.9650,0.1437
21.6000,0.3598,1.9690,0.1439
21.6400,0.3606,1.9741,0.1443
21.6800,0.3615,1.9805,0.1448
21.7200,0.3622,1.9867,0.1452
21.7600,0.3629,1.9918,0.1456
21.8000,0.3634,1.9959,0.1459
21.8400,0.3640,1.9997,0.1462
21.8800,0.3646,2.0034,0.1464
21.9200,0.3653,2.0082,0.1468
21.9600,0.3662,2.0146,0.1473
22.0000,0.3670,2.0211,0.1477
22.0400,0.3676,2.0261,0.1481
22.0800,0.3681,2.0303,0.1485
22.1200,0.3687,2.0344,0.1488
22.1600,0.3692,2.0380,0.1490
22.2000,0.3698,2.0418,0.1493
22.2400,0.3706,2.0466,0.1496
22.2800,0.3715,2.0528,0.1501
22.3200,0.3723,2.0591,0.1506
22.3600,0.3729,2.0646,0.1509
22.4000,0.3735,2.0688,0.1513
22.4400,0.3740,2.0727,0.1516
22.4800,0.3745,2.0763,0.1518
22.5200,0.3753,2.0805,0.1521
22.5600,0.3761,2.0864,0.1526
22.6000,0.3769,2.0934,0.1531
22.6400,0.3776,2.0990,0.1535
22.6800,0.3782,2.1036,0.1538
22.7200,0.3787,2.1080,0.1541
22.7600,0.3793,2.1115,0.1544
22.8000,0.3798,2.1153,0.1547
22.8400,0.3806,2.1197,0.1550
22.8800,0.3814,2.1257,0.1554
22.9200,0.3823,2.1324,0.1560
22.9600,0.3829,2.1381,0.1564
23.0000,0.3835,2.1429,0.1567
23.0400,0.3841,2.1466,0.1570
23.0800,0.3846,2.1503,0.1573
23.1200,0.3852,2.1546,0.1575
23.1600,0.3860,2.1596,0.1580
23.2000,0.3869,2.1663,0.1584
23.2400,0.3876,2.1725,0.1589
23.2800,0.3882,2.1771,0.1592
23.3200,0.3888,2.1816,0.1595
23.3600,0.3893,2.1855,0.1598
23.4000,0.3899,2.1893,0.1601
23.4400,0.3905,2.1934,0.1604
23.4800,0.3914,2.1987,0.1609
23.5200,0.3922,2.2059,0.1614
23.5600,0.3930,2.2123,0.1618
23.6000,0.3936,2.2170,0.1622
23.6400,0.3941,2.2210,0.1625
23.6800,0.3946,2.2248,0.1627
23.7200,0.3952,2.2287,0.1630
23.7600,0.3959,2.2336,0.1633
23.8000,0.3969,2.2400,0.1638
23.8400,0.3976,2.2465,0.1643
23.8800,0.3982,2.2518,0.1647
23.9200,0.3988,2.2562,0.1651
23.9600,0.3994,2.2602,0.1654
24.0000,0.3999,2.2641,0.1656
24.0400,0.4006,2.2679,0.1659
24.0800,0.4014,2.2731,0.1663
24.1200,0.4022,2.2797,0.1668
24.1600,0.4030,2.2860,0.1673
24.2000,0.4036,2.2911,0.1676
24.2400,0.4041,2.2951,0.1679
24.2800,0.4046,2.2990,0.1682
24.3200,0.4052,2.3027,0.1685
24.3600,0.4059,2.3071,0.1688
24.4000,0.4068,2.3132,0.1692
24.4400,0.4076,2.3202,0.1697
24.4800,0.4083,2.3258,0.1702
24.5200,0.4089,2.3307,0.1705
24.5600,0.4094,2.3349,0.1708
24.6000,0.4100,2.3388,0.1711
24.6400,0.4105,2.3425,0.1714
24.6800,0.4113,2.3472,0.1717
24.7200,0.4121,2.3534,0.1722
24.7600,0.4129,2.3600,0.1727
24.8000,0.4136,2.3652,0.1731
24.8400,0.4142,2.3694,0.1734
24.8800,0.4146,2.3735,0.1737
24.9200,0.4152,2.3773,0.1740
24.9600,0.4159,2.3812,0.1742
25.0000,0.4167,2.3867,0.1747
25.0400,0.4176,2.3937,0.1752
25.0800,0.4183,2.3999,0.1756
25.1200,0.4189,2.4049,0.1760
25.1600,0.4195,2.4093,0.1763
25.2000,0.4200,2.4132,0.1766
25.2400,0.4205,2.4172,0.1769
25.2800,0.4212,2.4214,0.1772
25.3200,0.4220,2.4269,0.1775
25.3600,0.4228,2.4333,0.1781
25.4000,0.4236,2.4394,0.1785
25.4400,0.4242,2.4441,0.1789
25.4800,0.4247,2.4482,0.1792
25.5200,0.4252,2.4523,0.1795
25.5600,0.4258,2.4561,0.1798
25.6000,0.4266,2.4610,0.1801
25.6400,0.4276,2.4678,0.1806
25.6800,0.4283,2.4743,0.1811
25.7200,0.4289,2.4797,0.1815
25.7600,0.4295,2.4842,0.1818
25.8000,0.4300,2.4883,0.1821
25.8400,0.4306,2.4920,0.1824
25.8800,0.4312,2.4959,0.1827
25.9200,0.4320,2.5009,0.1831
25.9600,0.4329,2.5075,0.1836
26.0000,0.4336,2.5138,0.1840
26.0400,0.4342,2.5194,0.1845
26.0800,0.4348,2.5239,0.1848
26.1200,0.4353,2.5278,0.1850
26.1600,0.4359,2.5317,0.1853
26.2000,0.4366,2.5363,0.1857
26.2400,0.4375,2.5427,0.1861
26.2800,0.4383,2.5495,0.1867
26.3200,0.4390,2.5549,0.1870
26.3600,0.4395,2.5594,0.1874
26.4000,0.4400,2.5635,0.1877
26.4400,0.4406,2.5674,0.1879
26.4800,0.4412,2.5712,0.1883
26.5200,0.4419,2.5760,0.1887
26.5600,0.4428,2.5823,0.1891
26.6000,0.4436,2.5891,0.1896
26.6400,0.4443,2.5946,0.1900
26.6800,0.4449,2.5995,0.1903
26.7200,0.4453,2.6033,0.1906
26.7600,0.4459,2.6070,0.1909
26.8000,0.4466,2.6115,0.1912
26.8400,0.4474,2.6173,0.1916
26.8800,0.4482,2.6244,0.1922
26.9200,0.4489,2.6302,0.1927
26.9600,0.4495,2.6348,0.1929
27.0000,0.4501,2.6395,0.1933
27.0400,0.4506,2.6434,0.1936
27.0800,0.4512,2.6473,0.1938
27.1200,0.4519,2.6518,0.1942
27.1600,0.4527,2.6575,0.1946
27.2000,0.4536,2.6646,0.1951
27.2400,0.4543,2.6707,0.1956
27.2800,0.4549,2.6754,0.1960
27.3200,0.4554,2.6793,0.1963
27.3600,0.4559,2.6829,0.1965
27.4000,0.4565,2.6871,0.1968
27.4400,0.4573,2.6922,0.1972
27.4800,0.4582,2.6987,0.1977
27.5200,0.4589,2.7054,0.1981
27.5600,0.4595,2.7103,0.1985
27.6000,0.4601,2.7151,0.1989
27.6400,0.4607,2.7193,0.1992
27.6800,0.4612,2.7233,0.1995
27.7200,0.4618,2.7274,0.1998
27.7600,0.4627,2.7331,0.2002
27.8000,0.4636,2.7399,0.2007
27.8400,0.4643,2.7462,0.2012
27.8800,0.4649,2.7514,0.2016
27.9200,0.4654,2.7554,0.2019
27.9600,0.4660,2.7591,0.2021
28.0000,0.4665,2.7629,0.2025
28.0400,0.4672,2.7676,0.2028
28.0800,0.4681,2.7739,0.2032
28.1200,0.4689,2.7807,0.2038
28.1600,0.4696,2.7864,0.2042
28.2000,0.4702,2.7912,0.2045
28.2400,0.4707,2.7955,0.2049
28.2800,0.4713,2.7996,0.2051
28.3200,0.4719,2.8036,0.2054
28.3600,0.4727,2.8085,0.2058
28.4000,0.4735,2.8151,0.2062
28.4400,0.4743,2.8213,0.2067
28.4800,0.4749,2.8268,0.2072
28.5200,0.4754,2.8314,0.2075
28.5600,0.4760,2.8352,0.2078
28.6000,0.4765,2.8392,0.2080
28.6400,0.4772,2.8435,0.2083
28.6800,0.4781,2.8495,0.2088
28.7200,0.4789,2.8570,0.2094
28.7600,0.4796,2.8630,0.2098
28.8000,0.4802,2.8678,0.2102
28.8400,0.4808,2.8724,0.2105
28.8800,0.4813,2.8762,0.2108
28.9200,0.4819,2.8801,0.2111
28.9600,0.4826,2.8846,0.2114
29.0000,0.4835,2.8910,0.2119
29.0400,0.4842,2.8974,0.2123
29.0800,0.4849,2.9031,0.2128
29.1200,0.4855,2.9077,0.2132
29.1600,0.4860,2.9119,0.2134
29.2000,0.4865,2.9157,0.2137
29.2400,0.4872,2.9199,0.2140
29.2800,0.4880,2.9257,0.2144
29.3200,0.4889,2.9328,0.2150
29.3600,0.4896,2.9393,0.2154
29.4000,0.4902,2.9442,0.2158
29.4400,0.4908,2.9488,0.2161
29.4800,0.4914,2.9528,0.2165
29.5200,0.4919,2.9566,0.2167
29.5600,0.4925,2.9608,0.2170
29.6000,0.4934,2.9665,0.2174
29.6400,0.4942,2.9730,0.2180
29.6800,0.4949,2.9792,0.2184
29.7200,0.4955,2.9842,0.2188
29.7600,0.4961,2.9883,0.2191
29.8000,0.4966,2.9922,0.2194
29.8400,0.4972,2.9962,0.2197
29.8800,0.4979,3.0012,0.2201
29.9200,0.4989,3.0080,0.2206
29.9600,0.4997,3.0149,0.2211
30.0000,0.5003,3.0204,0.2215
30.0400,0.5008,3.0246,0.2218
30.0800,0.5014,3.0288,0.2220
30.1200,0.5019,3.0326,0.2223
30.1600,0.5025,3.0365,0.2227
30.2000,0.5033,3.0416,0.2230
30.2400,0.5042,3.0485,0.2235
30.2800,0.5049,3.0551,0.2240
30.3200,0.5056,3.0604,0.2245
30.3600,0.5061,3.0649,0.2248
30.4000,0.5066,3.0687,0.2251
30.4400,0.5072,3.0726,0.2254
30.4800,0.5079,3.0772,0.2257
30.5200,0.5088,3.0837,0.2262
30.5600,0.5096,3.0908,0.2267
30.6000,0.5103,3.0963,0.2271
30.6400,0.5109,3.1008,0.2275
30.6800,0.5114,3.1051,0.2278
30.7200,0.5119,3.1092,0.2281
30.7600,0.5125,3.1129,0.2283
30.8000,0.5132,3.1177,0.2287
30.8400,0.5141,3.1239,0.2292
30.8800,0.5149,3.1308,0.2297
30.9200,0.5156,3.1369,0.2302
30.9600,0.5162,3.1415,0.2305
31.0000,0.5167,3.1457,0.2308
31.0400,0.5172,3.1496,0.2311
31.0800,0.5179,3.1536,0.2314
31.1200,0.5187,3.1592,0.2318
31.1600,0.5196,3.1661,0.2323
31.2000,0.5202,3.1722,0.2328
31.2400,0.5209,3.1773,0.2332
31.2800,0.5215,3.1818,0.2335
31.3200,0.5220,3.1859,0.2338
31.3600,0.5225,3.1898,0.2341
31.4000,0.5232,3.1940,0.2344
31.4400,0.5241,3.2000,0.2349
31.4800,0.5249,3.2068,0.2354
31.5200,0.5256,3.2131,0.2359
31.5600,0.5262,3.2182,0.2363
31.6000,0.5268,3.2225,0.2366
31.6400,0.5273,3.2261,0.2369
31.6800,0.5279,3.2301,0.2372
31.7200,0.5286,3.2351,0.2375
31.7600,0.5295,3.2418,0.2380
31.8000,0.5302,3.2486,0.2385
31.8400,0.5309,3.2540,0.2389
31.8800,0.5315,3.2587,0.2393
31.9200,0.5320,3.2629,0.2396
31.9600,0.5326,3.2670,0.2399
32.0000,0.5332,3.2710,0.2402
32.0400,0.5340,3.2763,0.2406
32.0800,0.5349,3.2830,0.2411
32.1200,0.5357,3.2895,0.2416
32.1600,0.5362,3.2952,0.2420
32.2000,0.5368,3.2992,0.2424
32.2400,0.5373,3.3030,0.2427
32.2800,0.5379,3.3066,0.2429
32.3200,0.5386,3.3110,0.2433
32.3600,0.5394,3.3174,0.2437
32.4000,0.5402,3.3242,0.2443
32.4400,0.5409,3.3302,0.2447
32.4800,0.5416,3.3353,0.2450
32.5200,0.5421,3.3397,0.2454
32.5600,0.5426,3.3437,0.2457
32.6000,0.5432,3.3475,0.2460
32.6400,0.5440,3.3523,0.2464
32.6800,0.5448,3.3588,0.2468
32.7200,0.5456,3.3658,0.2473
32.7600,0.5462,3.3711,0.2477
32.8000,0.5468,3.3756,0.2481
32.8400,0.5473,3.3795,0.2484
32.8800,0.5479,3.3833,0.2487
32.9200,0.5485,3.3876,0.2490
32.9600,0.5493,3.3931,0.2494
33.0000,0.5502,3.4003,0.2500
33.0400,0.5509,3.4065,0.2504
33.0800,0.5516,3.4119,0.2508
33.1200,0.5522,3.4164,0.2512
33.1600,0.5526,3.4201,0.2515
33.2000,0.5532,3.4239,0.2517
33.2400,0.5539,3.4282,0.2521
33.2800,0.5547,3.4341,0.2525
33.3200,0.5555,3.4409,0.2530
33.3600,0.5562,3.4467,0.2535
33.4000,0.5569,3.4516,0.2539
33.4400,0.5574,3.4559,0.2542
33.4800,0.5579,3.4598,0.2545
33.5200,0.5585,3.4638,0.2548
33.5600,0.5593,3.4688,0.2552
33.6000,0.5602,3.4758,0.2557
33.6400,0.5609,3.4828,0.2562
33.6800,0.5616,3.4881,0.2566
33.7200,0.5622,3.4927,0.2570
33.7600,0.5627,3.4967,0.2573
33.8000,0.5632,3.5001,0.2576